Workbook
Name ____________PH1: '[1]SW-TEO'!#REF!

Sheet 说明
B2: 参数输入表中：
C3: 标黄项为相对固定模块
C4: 标绿项为对成本类、收入类数据进行分类，成本参数按照：“生产成本/销售费用/管理费用/研发费用”划分；收入参数按照：“营业收入/其他收入/营业外收入”划分
C5: 标橙项为固定的分类原则
C6: 标紫项为在参数表中不需要手动输入、勾选的内容，根据其他输入参数自动计算得出，可不在参数输入界面呈现。
C7: 标红项为引用同样红色sheet中相关数据
C8: 标蓝项为可不展示内容，大部分为中间过程计算表/中间计算过程
C10: 【成本费用表】、【收入税金表】、【利润表】体现的是会计报表相关数据，涉及到的收入及成本数据均为不含增值税金额，不含税金额计算公式为： 【含税金额/（1+增值税税率）】；增值税计算公式为：【不含税金额*增值税税率】或【含税金额/（1+增值税税率）*增值税税率】
C12: 【成本费用表】中各项成本按照：一、营业总成本：（1）生产成本；（2）销售费用；（3）管理费用；（4）研发费用；（5）财务费用；二、营业外支出，进行划分，其中需重点关注长期待摊费用成本项，在成本费用表中以逐年摊销的形式出现。
C14: 【成本费用表】中标蓝的内容为不展示内容，为中间计算表，其中数据均还原成含税金额，用于后续的【现金流量表】引用
C16: 【收入表】中各项收入按照：一、营业收入；二、其他收入；三、营业外收入，营业收入及营业外收入需展示二级目录（具体的收入项）
C18: 【现金流量表】体现的是公司账上实际收到或支付的现金流，因此涉及到的收入及成本数据均为含增值税金额，数据需引用成本费用表中还原后的含税金额或参数输入表中的含税金额。同时，收入数据需关注付款比例及回款期限的应用。原理为当年的部分比例收入的滞后支付，第一年的某项收入现金流为预测现金流*首年支付比例，第二年的某项收入现金流为：当年预测现金流*当年支付比例+上一年预测现金流*（1-上一年支付比例）
C20: 【现金流量表-财务计划】增加IF判定条件，当某年的累计盈余资金<“流动资金（本项目为960万元）”+次年的“生产经营现金支出合计（成本费用表标蓝表第一行）”，给出明显提示（允许用户在参数输入界面填写各年度短期借款当期借款金额及还本金额，再重新生成新的结果）

Sheet 可抵扣进项税
B2: 投资概算 | C2: 序号 | D2: 科目 | E2: 计取基数 | F2: 进项税率 | G2: 进项税
C3: 1 | D3: 设备购置费 | F3: =参数输入表!H709 -> 0.13 | G3: =E3/(1+F3)*F3 -> 0
C4: 2 | D4: 建安工程费 | F4: =参数输入表!H710 -> 0.09 | G4: =E4/(1+F4)*F4 -> 0
C5: 3 | D5: 其他费用 | F5: =参数输入表!H711 -> 0.06 | G5: =E5/(1+F5)*F5 -> 0
C6: 4 | D6: 预备费 | F6: =参数输入表!H712 -> 0 | G6: =E6/(1+F6)*F6 -> 0
C7: 5 | D7: 送出线路投资 | F7: =参数输入表!H714 -> 0.09 | G7: =E7/(1+F7)*F7 -> 0
C8: 6 | D8: 配套支持资金 | F8: =参数输入表!H715 -> 0 | G8: =E8/(1+F8)*F8 -> 0
C9: 7 | D9: 静态总投资
C10: 8 | D10: 建设期利息
C11: 9 | D11: 动态总投资
C12: 10 | D12: 流动资金
C13: 11 | D13: 可抵扣进项税 | E13: =SUM(G3:G8) -> 0
C17: 可抵扣进项税为后台计算，不需要作为成果展示

Sheet 参数输入表
G1: 【风储】财务评价计算模型边界条件输入参数表
B3: 类别 | C3: 序号 | D3: 参数 | E3: 操作类型 | F3: 收入/成本归类 | G3: 参数释义/计算公式 | H3: 数值 | I3: 单位 | J3: 取值说明 | K3: 备注
C4: 1 | D4: 项目规模 | E4: 手动输入 | G4: 按照算力规模 | H4: 1000 | I4: p
C5: 2 | D5: 项目变电容量 | E5: 手动输入 | H5: 5 | I5: MVa
C6: 3 | D6: 机柜总功率 | E6: 手动输入 | H6: 4000 | I6: kW
C7: 4 | D7: 全年用电量 | J7: 全年用电量大于风（光）储全年发电量，风（光）储上网电量为0，如果全年用电量小于风（光）储全年发电量，上网电量=风（光）储全年发电量-全年用电量；
D8: 运营期第1年 | E8: 手动输入 | H8: 120000 | I8: MWh
D9: 运营期第2年 | E9: 手动输入 | H9: 120000 | I9: MWh
D10: 运营期第3年 | E10: 手动输入 | H10: 120000 | I10: MWh
D11: 运营期第4年 | E11: 手动输入 | H11: 120000 | I11: MWh
D12: 运营期第5年 | E12: 手动输入 | H12: 120000 | I12: MWh
D13: 运营期第6年 | E13: 手动输入 | H13: 120000 | I13: MWh
D14: 运营期第7年 | E14: 手动输入 | H14: 120000 | I14: MWh
D15: 运营期第8年 | E15: 手动输入 | H15: 120000 | I15: MWh
D16: 运营期第9年 | E16: 手动输入 | H16: 120000 | I16: MWh
D17: 运营期第10年 | E17: 手动输入 | H17: 120000 | I17: MWh
D18: 运营期第11年 | E18: 手动输入 | H18: 120000 | I18: MWh
D19: 运营期第12年 | E19: 手动输入 | H19: 120000 | I19: MWh
... D27: 运营期第20年 | E27: 手动输入 | H27: 120000 | I27: MWh
C28: 5 | D28: PUE | E28: 手动输入 | H28: 1.25
C29: 5 | D29: 是否有新能源接入 | E29: 手动输入 | G29: 直连式新能源 源网核储一体化 | H29: 否
C30: 6 | D30: 新能源类型 | E30: 下拉菜单选择 | G30: 风储、光储、风光储
D31: 风电接入比例 | E31: 手动输入 | H31: 0.5
D32: 光伏接入比例 | E32: 手动输入 | H32: 0.4
C33: 7 | D33: 新能源接入电量 | J33: 还未设置链接
D34: 光伏接入电量
D35: 运营期第1年 | G35: 取值于风光储发电量 | H35: =[2]参数输入表!$H21*[2]参数输入表!$H77 -> 47520 | I35: MWh
D36: 运营期第2年 | G36: 取值于风光储发电量 | H36: =[2]参数输入表!$H22*[2]参数输入表!$H78 -> 47306.16 | I36: MWh
D37: 运营期第3年 | G37: 取值于风光储发电量 | H37: =[2]参数输入表!$H23*[2]参数输入表!$H79 -> 47093.282 | I37: MWh
D38: 运营期第4年 | G38: 取值于风光储发电量 | H38: =[2]参数输入表!$H24*[2]参数输入表!$H80 -> 46881.363 | I38: MWh
D39: 运营期第5年 | G39: 取值于风光储发电量 | H39: =[2]参数输入表!$H25*[2]参数输入表!$H81 -> 46670.396 | I39: MWh
D40: 运营期第6年 | G40: 取值于风光储发电量 | H40: =[2]参数输入表!$H26*[2]参数输入表!$H82 -> 65044.531 | I40: MWh
D41: 运营期第7年 | G41: 取值于风光储发电量 | H41: =[2]参数输入表!$H27*[2]参数输入表!$H83 -> 64751.831 | I41: MWh
D42: 运营期第8年 | G42: 取值于风光储发电量 | H42: =[2]参数输入表!$H28*[2]参数输入表!$H84 -> 64460.448 | I42: MWh
D43: 运营期第9年 | G43: 取值于风光储发电量 | H43: =[2]参数输入表!$H29*[2]参数输入表!$H85 -> 64170.376 | I43: MWh
D44: 运营期第10年 | G44: 取值于风光储发电量 | H44: =[2]参数输入表!$H30*[2]参数输入表!$H86 -> 63881.609 | I44: MWh
D45: 运营期第11年 | G45: 取值于风光储发电量 | H45: =[2]参数输入表!$H31*[2]参数输入表!$H87 -> 63594.142 | I45: MWh
D46: 运营期第12年 | G46: 取值于风光储发电量 | H46: =[2]参数输入表!$H32*[2]参数输入表!$H88 -> 63307.968 | I46: MWh
... D54: 运营期第20年 | G54: 取值于风光储发电量 | H54: =[2]参数输入表!$H40*[2]参数输入表!$H96 -> 61064.456 | I54: MWh
D55: 风电接入电量
...

Sheet 表1-资金筹措及还本付息表
B2: 资金筹措表
B3: 序号 | C3: 建设期 | D3: 合计 | E3: 单位 | F3: 建设期 | H3: 运营期
F4: 1 | G4: 2 | H4: 1 | I4: 2 | J4: 3 | K4: 4 | L4: 5 | M4: 6 | N4: 7 | O4: 8 | P4: 9 | Q4: 10 | R4: 11 | S4: 12 | T4: 13 | U4: 14 | V4: 15 | W4: 16 | X4: 17 | Y4: 18 | Z4: 19 | AA4: 20
C5: 施工进度安排 | D5: =SUM(F5:M5) -> 1 | F5: =参数输入表!H102 -> 0.6 | G5: =参数输入表!H103 -> 0.4
B6: 1 | C6: 动态总投资（自主投资） | D6: =D7+D8+D9 -> 67671.182 | E6: 万元 | F6: =SUM(F7:F9) -> 39711.143 | G6: =SUM(G7:G9) -> 27579.04 | H6: =SUM(H7:H9) -> 381
B7: 1.1 | C7: 静态总投资（自主投资） | D7: =SUM(F7:AA7) -> 65278.39 | E7: 万元 | F7: =参数输入表!H348*F5 -> 39167.034 | G7: =参数输入表!$H$348*G5 -> 26111.356 | H7: 0
B8: 1.2 | C8: 建设期利息 | D8: =SUM(F8:AA8) -> 2011.7923 | E8: 万元 | F8: =F17 -> 544.10881 | G8: =G17 -> 1467.6835 | H8: =H17 -> 0
B9: 1.3 | C9: 流动资金 | D9: =SUM(F9:AA9) -> 381 | E9: 万元 | F9: 0 | G9: 0 | H9: =参数输入表!H351 -> 381
B10: 2 | C10: 资金来源
B11: 2.1 | C11: 资本金 | D11: =SUM(F11:AA11) -> 13705.21 | E11: 万元 | F11: =F6*(参数输入表!$H$355+0.3346%) -> 8075.102 | G11: =G6*参数输入表!$H$355 -> 5515.8079 | H11: =H6*参数输入表!$H$363 -> 114.3
B12: 2.1.1 | C12: 用于建设投资 | D12: =SUM(F12:AA12) -> 13590.91 | E12: 万元 | F12: =F11-F13-F14 -> 8075.102 | G12: =G11-G13-G14 -> 5515.8079 | H12: 0
B13: 2.1.2 | C13: 用于建设期利息 | D13: =SUM(F13:AA13) -> 0 | E13: 万元 | F13: 0 | G13: 0 | H13: 0
B14: 2.1.3 | C14: 用于流动资金 | D14: =SUM(F14:AA14) -> 114.3 | F14: 0 | G14: 0 | H14: =H9*参数输入表!H363 -> 114.3
B15: 2.2 | C15: 债务资金 | D15: =SUM(F15:M15) -> 53965.972 | E15: 万元 | F15: =SUM(F16:F18) -> 31636.041 | G15: =SUM(G16:G18) -> 22063.232 | H15: =SUM(H16:H18) -> 266.7
B16: 2.2.1 | C16: 用于建设投资 | D16: =SUM(F16:AA16) -> 51687.48 | E16: 万元 | F16: =F7-F12 -> 31091.932 | G16: =G7-G12 -> 20595.548 | H16: =H7-H12 -> 0
B17: 2.1.2 | C17: 用于建设期利息 | D17: =SUM(F17:AA17) -> 2011.7923 | E17: 万元 | F17: =F16/2*参数输入表!$H$358*(12/12) -> 544.10881 | G17: =IF(G5>0,((G16/2+F15)*参数输入表!$H$358)*(12/12),0) -> 1467.6835 | H17: 0
B18: 2.1.3 | C18: 用于流动资金 | D18: =SUM(F18:AA18) -> 266.7 | E18: 万元 | F18: 0 | G18: 0 | H18: =H9-H14 -> 266.7
B20: 营运资本变动
B21: 序号 | C21: 项目 | D21: 合计 | E21: 单位 | F21: 建设期 | H21: 运营期
F22: 1 | G22: 2 | H22: 1 | I22: 2 | J22: 3 | K22: 4 | L22: 5 | M22: 6 | N22: 7 | O22: 8 | P22: 9 | Q22: 10 | R22: 11 | S22: 12 | T22: 13 | U22: 14 | V22: 15 | W22: 16 | X22: 17 | Y22: 18 | Z22: 19 | AA22: 20
B23: 1 | C23: 流动资产 | D23: =SUM(F23:AA23) -> 217051.74 | E23: 万元 | F23: =SUM(F24:F27) -> 2674.206 | G23: =SUM(G24:G27) -> 4457.01 | H23: =SUM(H24:H27) -> 9309.1267 | I23: =SUM(I24:I27) -> 8550.2024 | J23: =SUM(J24:J27) -> 7998.4677 | K23: =SUM(K24:K27) -> 7634.4897 | L23: =SUM(L24:L27) -> 7440.7785 | M23: =SUM(M24:M27) -> 6648.9004 | ... AA23: =SUM(AA24:AA27) -> 22623.45
C24: 货币资金 | D24: =SUM(F24:AA24) -> 198161.49 | E24: 万元 | F24: ='表9-现金流量表-财务计划'!F34 -> 0 | G24: ='表9-现金流量表-财务计划'!G34 -> 0 | H24: ='表9-现金流量表-财务计划'!H34 -> 5894.3293 | I24: ='表9-现金流量表-财务计划'!I34 -> 5725.3675 | J24: ='表9-现金流量表-财务计划'!J34 -> 5764.1741 | K24: ='表9-现金流量表-财务计划'!K34 -> 5991.3142 | L24: ='表9-现金流量表-财务计划'!L34 -> 6389.2964 | M24: ='表9-现金流量表-财务计划'!M34 -> 6082.1577 | ... AA24: ='表9-现金流量表-财务计划'!AA34 -> 22623.45
C25: 应收账款 | D25: =SUM(F25:AA25) -> 0 | E25: 万元 | H25: ='表4-收入税金表'!H54 -> 0 | I25: ='表4-收入税金表'!I54 -> 0 | J25: ='表4-收入税金表'!J54 -> 0 | K25: ='表4-收入税金表'!K54 -> 0 | L25: ='表4-收入税金表'!L54 -> 0 | M25: ='表4-收入税金表'!M54 -> 0 | N25: ='表4-收入税金表'!N54 -> 0 | O25: ='表4-收入税金表'!O54 -> 0 | ... AA25: ='表4-收入税金表'!AA54 -> 0
C26: 存货 | D26: =SUM(F26:AA26) -> 0 | E26: 万元
C27: 其他流动资产（留抵税额） | D27: =SUM(F27:AA27) -> 18890.252 | E27: 万元 | F27: ='表4-收入税金表'!F39 -> 2674.206 | G27: ='表4-收入税金表'!G39 -> 4457.01 | H27: ='表4-收入税金表'!H39 -> 3414.7974 | I27: ='表4-收入税金表'!I39 -> 2824.8348 | J27: ='表4-收入税金表'!J39 -> 2234.2936 | K27: ='表4-收入税金表'!K39 -> 1643.1755 | L27: ='表4-收入税金表'!L39 -> 1051.4822 | M27: ='表4-收入税金表'!M39 -> 566.74268 | ... AA27: ='表4-收入税金表'!AA39 -> 0
B28: 2 | C28: 流动负债 | D28: =SUM(F28:AA28) -> 43563.636 | E28: 万元 | F28: =SUM(F29:F34) -> 0 | G28: =SUM(G29:G34) -> 0 | H28: =SUM(H29:H34) -> 3203.0305 | I28: =SUM(I29:I34) -> 1129.9634 | J28: =SUM(J29:J34) -> 1052.5226 | K28: =SUM(K29:K34) -> 994.50217 | L28: =SUM(L29:L34) -> 953.95887 | M28: =SUM(M29:M34) -> 854.70173 | ... AA28: =SUM(AA29:AA34) -> 4148.7008
C29: 短期借款 | D29: =SUM(F29:AA29) -> 266.7 | E29: 万元 | F29: =F64+F74 -> 0 | G29: =G60+G70 -> 0 | H29: =H60+H70 -> 266.7 | I29: =I60+I70 -> 0 | J29: =J60+J70 -> 0 | K29: =K60+K70 -> 0 | L29: =L60+L70 -> 0 | M29: =M60+M70 -> 0 | N29: =N60+N70 -> 0 | ... AA29: =AA60+AA70 -> 0
C30: 预收款项 | D30: =SUM(F30:AA30) -> 0 | E30: 万元
C31: 应付职工薪酬 | D31: =SUM(F31:AA31) -> 15360 | E31: 万元 | H31: ='表3-成本费用表'!H52 -> 768 | I31: ='表3-成本费用表'!I52 -> 768 | J31: ='表3-成本费用表'!J52 -> 768 | K31: ='表3-成本费用表'!K52 -> 768 | L31: ='表3-成本费用表'!L52 -> 768 | M31: ='表3-成本费用表'!M52 -> 768 | N31: ='表3-成本费用表'!N52 -> 768 | O31: ='表3-成本费用表'!O52 -> 768 | ... AA31: ='表3-成本费用表'!AA52 -> 768
C32: 应交税费 | D32: =SUM(F32:AA32) -> 17278.058 | E32: 万元 | H32: ='表6-现金流量表-资本金'!H24+'表6-现金流量表-资本金'!H25+'表6-现金流量表-资本金'!H29 -> 1707.3469 | I32: ='表6-现金流量表-资本金'!I24+'表6-现金流量表-资本金'!I25+'表6-现金流量表-资本金'!I29 -> 0 | J32: ='表6-现金流量表-资本金'!J24+'表6-现金流量表-资本金'!J25+'表6-现金流量表-资本金'!J29 -> 0 | K32: ='表6-现金流量表-资本金'!K24+'表6-现金流量表-资本金'!K25+'表6-现金流量表-资本金'!K29 -> 0 | L32: ='表6-现金流量表-资本金'!L24+'表6-现金流量表-资本金'!L25+'表6-现金流量表-资本金'!L29 -> 0 | M32: ='表6-现金流量表-资本金'!M24+'表6-现金流量表-资本金'!M25+'表6-现金流量表-资本金'!M29 -> 0 | N32: ='表6-现金流量表-资本金'!N24+'表6-现金流量表-资本金'!N25+'表6-现金流量表-资本金'!N29 -> 0 | O32: ='表6-现金流量表-资本金'!O24+'表6-现金流量表-资本金'!O25+'表6-现金流量表-资本金'!O29 -> 573.1091 | ... AA32: ='表6-现金流量表-资本金'!AA24+'表6-现金流量表-资本金'!AA25+'表6-现金流量表-资本金'!AA29 -> 1760.9675
C33: 应付股利 | D33: =SUM(F33:AA33) -> 10658.879 | E33: 万元 | H33: ='表5-利润表-资本金'!H31 -> 460.98366 | I33: ='表5-利润表-资本金'!I31 -> 361.96344 | J33: ='表5-利润表-资本金'!J31 -> 284.52264 | K33: ='表5-利润表-资本金'!K31 -> 226.50217 | L33: ='表5-利润表-资本金'!L31 -> 185.95887 | M33: ='表5-利润表-资本金'!M31 -> 86.701732 | N33: ='表5-利润表-资本金'!N31 -> 96.577532 | O33: ='表5-利润表-资本金'!O31 -> 114.08097 | ... AA33: ='表5-利润表-资本金'!AA31 -> 1619.7333
C34: 其他流动负债 | D34: =SUM(F34:AA34) -> 0 | E34: 万元
B36: 借款还本付息表（长期借款）
B37: 序号 | C37: 项目 | D37: 合计 | E37: 单位 | F37: 建设期 | H37: 运营期
F38: 1 | G38: 2 | H38: 1 | I38: 2 | J38: 3 | K38: 4 | L38: 5 | M38: 6 | N38: 7 | O38: 8 | P38: 9 | Q38: 10 | R38: 11 | S38: 12 | T38: 13 | U38: 14 | V38: 15 | W38: 16 | X38: 17 | Y38: 18 | Z38: 19 | AA38: 20
B39: 1 | C39: 期初借款累计 | E39: 万元 | F39: 0 | G39: =F44 -> 31636.041 | H39: =G44 -> 53699.272 | I39: =H44 -> 50916.304 | J39: =I44 -> 48035.931 | K39: =J44 -> 45054.746 | L39: =K44 -> 41969.219 | M39: =L44 -> 38775.699 | N39: =M44 -> 35470.405 | ... AA39: =Z44 -> 0
B40: 2 | C40: 当期借款 | D40: =SUM(F40:AA40) -> 53699.272 | E40: 万元 | F40: =F15 -> 31636.041 | G40: =G15 -> 22063.232
B41: 3 | C41: 当期还本付息 | D41: =SUM(F41:AA41) -> 69936.646 | E41: 万元 | H41: =-PMT(参数输入表!$H$359,参数输入表!$H$362,'表1-资金筹措及还本付息表'!$D$40) -> 4662.443 | I41: =-PMT(参数输入表!$H$359,参数输入表!$H$362,'表1-资金筹措及还本付息表'!$D$40) -> 4662.443 | J41: =-PMT(参数输入表!$H$359,参数输入表!$H$362,'表1-资金筹措及还本付息表'!$D$40) -> 4662.443 | K41: =-PMT(参数输入表!$H$359,参数输入表!$H$362,'表1-资金筹措及还本付息表'!$D$40) -> 4662.443 | L41: =-PMT(参数输入表!$H$359,参数输入表!$H$362,'表1-资金筹措及还本付息表'!$D$40) -> 4662.443 | M41: =-PMT(参数输入表!$H$359,参数输入表!$H$362,'表1-资金筹措及还本付息表'!$D$40) -> 4662.443 | N41: =-PMT(参数输入表!$H$359,参数输入表!$H$362,'表1-资金筹措及还本付息表'!$D$40) -> 4662.443 | O41: =-PMT(参数输入表!$H$359,参数输入表!$H$362,'表1-资金筹措及还本付息表'!$D$40) -> 4662.443 | ... V41: =-PMT(参数输入表!$H$359,参数输入表!$H$362,'表1-资金筹措及还本付息表'!$D$40) -> 4662.443
C42: 其中：还本（等额本息） | D42: =SUM(F42:AA42) -> 53699.272 | E42: 万元 | H42: =H41-H43 -> 2782.9685 | I42: =I41-I43 -> 2880.3724 | J42: =J41-J43 -> 2981.1854 | K42: =K41-K43 -> 3085.5269 | L42: =L41-L43 -> 3193.5204 | M42: =M41-M43 -> 3305.2936 | N42: =N41-N43 -> 3420.9789 | O42: =O41-O43 -> 3540.7131 | ... V42: =V41-V43 -> 4504.7759
C43: 付息 | D43: =SUM(F43:AA43) -> 16237.373 | E43: 万元 | H43: =(H39+H40/2)*参数输入表!$H$359 -> 1879.4745 | I43: =(I39+I40/2)*参数输入表!$H$359 -> 1782.0706 | J43: =(J39+J40/2)*参数输入表!$H$359 -> 1681.2576 | K43: =(K39+K40/2)*参数输入表!$H$359 -> 1576.9161 | L43: =(L39+L40/2)*参数输入表!$H$359 -> 1468.9227 | M43: =(M39+M40/2)*参数输入表!$H$359 -> 1357.1495 | N43: =(N39+N40/2)*参数输入表!$H$359 -> 1241.4642 | O43: =(O39+O40/2)*参数输入表!$H$359 -> 1121.7299 | ... V43: =(V39+V40/2)*参数输入表!$H$359 -> 157.66716
...

Sheet 表2-折旧摊销表
C1: 中间过程引用（隐藏）
C2: 动态总投资（自主投资_不含流动资金） | D2: =参数输入表!H350 -> 67290.182
C3: 可抵扣进项税 | D3: =参数输入表!H353 -> 4457.01
C4: 固定资产原值 | D4: =D2-D25-D3 -> 46359.172 | F4: 固定资产原值=项目动态总投资（自主投资_不含流动资金）-可抵扣进项税-无形资产原值=项目静态总投资-建设补贴+建设期利息-可抵扣进项税-无形资产原值
C5: 折旧方式 | D5: 直线法/其他
C6: 折旧年限 | D6: =参数输入表!H622 -> 15
C7: 残值率 | D7: =参数输入表!H623 -> 0.05
C8: 其中:
C9: 房屋建筑投资 | D9: =参数输入表!H342 -> 13170.58 | G9: =D14/D2 -> 0.19467922
C10: 可抵扣进项税
C11: 折算原值 | D11: =D4*(D9/D2) -> 9073.793 | G11: =G9-1 -> -0.80532078
C12: 折旧年限 | D12: 15
C13: 残值率 | D13: 0.05
C14: 算力设备投资 | D14: =参数输入表!H341 -> 13100
C15: 折算原值 | D15: =D4*(D14/D2) -> 9025.1674
C16: 折旧年限 | D16: 10
C17: 残值率 | D17: 0.05
C18: 长期待摊费用（第1年） | D18: =参数输入表!H631/(1+参数输入表!H653) -> 0 | F18: 长期待摊费用=计入长期待摊的成本项/（1+增值税税率）
C19: 长期待摊费用（第6年） | D19: =参数输入表!H636/(1+参数输入表!H653) -> 0
C20: 长期待摊费用（第11年） | D20: =参数输入表!H641/(1+参数输入表!H653) -> 0
C21: 长期待摊费用（第16年） | D21: =参数输入表!H646/(1+参数输入表!H653) -> 0
C23: 摊销方式 | D23: 直线法/其他
C24: 摊销年限 | D24: =参数输入表!H652 -> 5
C25: 无形资产原值 | D25: =参数输入表!H345 -> 16474
C26: 摊销方式 | D26: 直线法/其他
C27: 摊销年限 | D27: =参数输入表!H627 -> 30 | F27: 建设期 | H27: 运营期
C28: 残值率 | D28: =参数输入表!H628 -> 0 | F28: 1 | G28: 2 | H28: 1 | I28: 2 | J28: 3 | K28: 4 | L28: 5 | M28: 6 | N28: 7 | O28: 8 | P28: 9 | Q28: 10 | R28: 11 | S28: 12 | T28: 13 | U28: 14 | V28: 15 | W28: 16 | X28: 17 | Y28: 18 | Z28: 19 | AA28: 20
C29: 大修及更新重置资产原值
C30: 摊销方式 | D30: 直线法/其他 | H30: =参数输入表!H656 -> 0 | I30: =参数输入表!H657 -> 0 | J30: =参数输入表!H658 -> 0 | K30: =参数输入表!H659 -> 0 | L30: =参数输入表!H660 -> 0 | M30: =参数输入表!H661 -> 0 | N30: =参数输入表!H662 -> 0 | O30: =参数输入表!H663 -> 0 | P30: =参数输入表!H664 -> 0 | Q30: =参数输入表!H665 -> 0 | R30: =参数输入表!H666/(1+参数输入表!$H$679) -> 0 | S30: =参数输入表!H667 -> 500 | T30: =参数输入表!H668 -> 0 | U30: =参数输入表!H669 -> 0 | V30: =参数输入表!H670 -> 0 | W30: =参数输入表!H671 -> 0 | X30: =参数输入表!H672 -> 0 | Y30: =参数输入表!H673 -> 0 | Z30: =参数输入表!H674 -> 0 | AA30: =参数输入表!H675 -> 0
C31: 摊销年限 | D31: =参数输入表!H677 -> 10
C32: 残值率 | D32: =参数输入表!H678 -> 0.05
B33: 折旧摊销表-资本金
B34: 序号 | C34: 科目 | D34: 合计 | E34: 单位 | F34: 建设期 | H34: 运营期
F35: 1 | G35: 2 | H35: 1 | I35: 2 | J35: 3 | K35: 4 | L35: 5 | M35: 6 | N35: 7 | O35: 8 | P35: 9 | Q35: 10 | R35: 11 | S35: 12 | T35: 13 | U35: 14 | V35: 15 | W35: 16 | X35: 17 | Y35: 18 | Z35: 19 | AA35: 20
B36: 1 | C36: 固定资产净值 | E36: 万元 | F36: =(D4-D11-D15)*'表1-资金筹措及还本付息表'!F5 -> 16956.127 | G36: =(D4-D11-D15)*'表1-资金筹措及还本付息表'!G5 -> 11304.085 | H36: =G36-H37+F36 -> 26470.399 | I36: =H36-I37 -> 24680.585 | J36: =I36-J37 -> 22890.772 | K36: =J36-K37 -> 21100.958 | L36: =K36-L37 -> 19311.145 | M36: =L36-M37 -> 17521.331 | N36: =M36-N37 -> 15731.518 | O36: =N36-O37 -> 13941.705 | P36: =O36-P37 -> 12151.891 | ... AA36: =Z36-AA37 -> 1413.0106
C37: 当期固定资产折旧 | D37: =SUM(F37:AA37) -> 26847.201 | E37: 万元 | H37: =IF(H35<=$D$6,($D$4-$D$11-$D$15)*(1-$D$7)/($D$6),0) -> 1789.8134 | I37: =IF(I35<=$D$6,($D$4-$D$11-$D$15)*(1-$D$7)/($D$6),0) -> 1789.8134 | J37: =IF(J35<=$D$6,($D$4-$D$11-$D$15)*(1-$D$7)/($D$6),0) -> 1789.8134 | K37: =IF(K35<=$D$6,($D$4-$D$11-$D$15)*(1-$D$7)/($D$6),0) -> 1789.8134 | L37: =IF(L35<=$D$6,($D$4-$D$11-$D$15)*(1-$D$7)/($D$6),0) -> 1789.8134 | M37: =IF(M35<=$D$6,($D$4-$D$11-$D$15)*(1-$D$7)/($D$6),0) -> 1789.8134 | N37: =IF(N35<=$D$6,($D$4-$D$11-$D$15)*(1-$D$7)/($D$6),0) -> 1789.8134 | O37: =IF(O35<=$D$6,($D$4-$D$11-$D$15)*(1-$D$7)/($D$6),0) -> 1789.8134 | ... AA37: =IF(AA35<=$D$6,($D$4-$D$11-$D$15)*(1-$D$7)/($D$6),0) -> 0
B38: 2 | C38: 房屋建筑净值 | E38: 万元 | F38: =D11 -> 9073.793 | H38: =F38-H39 -> 8499.1195 | I38: =H38-I39 -> 7924.4459 | J38: =I38-J39 -> 7349.7724 | K38: =J38-K39 -> 6775.0988 | L38: =K38-L39 -> 6200.4252 | M38: =L38-M39 -> 5625.7517 | N38: =M38-N39 -> 5051.0781 | O38: =N38-O39 -> 4476.4046 | P38: =O38-P39 -> 3901.731 | ... AA38: =Z38-AA39 -> 453.68965
C39: 当期折旧 | D39: =SUM(F39:AA39) -> 8620.1034 | E39: 万元 | H39: =IF(H35<=$D$6,$D$11*(1-$D$13)/($D$12),0) -> 574.67356 | I39: =IF(I35<=$D$6,$D$11*(1-$D$13)/($D$12),0) -> 574.67356 | J39: =IF(J35<=$D$6,$D$11*(1-$D$13)/($D$12),0) -> 574.67356 | K39: =IF(K35<=$D$6,$D$11*(1-$D$13)/($D$12),0) -> 574.67356 | L39: =IF(L35<=$D$6,$D$11*(1-$D$13)/($D$12),0) -> 574.67356 | M39: =IF(M35<=$D$6,$D$11*(1-$D$13)/($D$12),0) -> 574.67356 | N39: =IF(N35<=$D$6,$D$11*(1-$D$13)/($D$12),0) -> 574.67356 | O39: =IF(O35<=$D$6,$D$11*(1-$D$13)/($D$12),0) -> 574.67356 | ... AA39: =IF(AA35<=$D$6,$D$11*(1-$D$13)/($D$12),0) -> 0
B40: 3 | C40: 算力设备净值 | E40: 万元 | F40: =D15*'表1-资金筹措及还本付息表'!F5 -> 5415.1004 | G40: =D15*'表1-资金筹措及还本付息表'!G5 -> 3610.0669 | H40: =F40+G40-H41 -> 8167.7765 | I40: =H40-I41 -> 7310.3856 | J40: =I40-J41 -> 6452.9947 | K40: =J40-K41 -> 5595.6038 | L40: =K40-L41 -> 4738.2129 | M40: =L40-M41 -> 3880.822 | N40: =M40-N41 -> 3023.4311 | O40: =N40-O41 -> 2166.0402 | P40: =O40-P41 -> 1308.6493 | ... AA40: =Z40-AA41 -> 451.25837
C41: 当期折旧 | D41: =SUM(F41:AA41) -> 8573.909 | E41: 万元 | H41: =IF(H35<=$D$16,$D$15*(1-$D$17)/($D$16),0) -> 857.3909 | I41: =IF(I35<=$D$16,$D$15*(1-$D$17)/($D$16),0) -> 857.3909 | J41: =IF(J35<=$D$16,$D$15*(1-$D$17)/($D$16),0) -> 857.3909 | K41: =IF(K35<=$D$16,$D$15*(1-$D$17)/($D$16),0) -> 857.3909 | L41: =IF(L35<=$D$16,$D$15*(1-$D$17)/($D$16),0) -> 857.3909 | M41: =IF(M35<=$D$16,$D$15*(1-$D$17)/($D$16),0) -> 857.3909 | N41: =IF(N35<=$D$16,$D$15*(1-$D$17)/($D$16),0) -> 857.3909 | O41: =IF(O35<=$D$16,$D$15*(1-$D$17)/($D$16),0) -> 857.3909 | ... R41: =IF(R35<=$D$16,$D$15*(1-$D$17)/($D$16),0) -> 0
...

Sheet 表3-成本费用表
B2: 成本费用表-资本金
B3: 序号 | C3: 项目 | D3: 合计 | E3: 单位 | F3: 建设期 | H3: 运营期
F4: 1 | G4: 2 | H4: 1 | I4: 2 | J4: 3 | K4: 4 | L4: 5 | M4: 6 | N4: 7 | O4: 8 | P4: 9 | Q4: 10 | R4: 11 | S4: 12 | T4: 13 | U4: 14 | V4: 15 | W4: 16 | X4: 17 | Y4: 18 | Z4: 19 | AA4: 20
B5: 一 | C5: 营业总成本 | D5: =SUM(F5:AA5) -> 335351.07 | E5: 万元 | H5: =H6+H15+H16+H19+H20 -> 18348.333 | I5: =I6+I15+I16+I19+I20 -> 18218.572 | J5: =J6+J15+J16+J19+J20 -> 18088.823 | K5: =K6+K15+K16+K19+K20 -> 17959.087 | L5: =L6+L15+L16+L19+L20 -> 17829.363 | M5: =M6+M15+M16+M19+M20 -> 18526.787 | N5: =N6+N15+N16+N19+N20 -> 18388.487 | O5: =O6+O15+O16+O19+O20 -> 18250.234 | ... AA5: =AA6+AA15+AA16+AA19+AA20 -> 13942.513
B6: 1 | C6: 生产成本 | D6: =SUM(F6:AA6) -> 319691.66 | H6: =SUM(H7:H14) -> 16437.678 | I6: =SUM(I7:I14) -> 16433.215 | J6: =SUM(J7:J14) -> 16428.764 | K6: =SUM(K7:K14) -> 16424.326 | L6: =SUM(L7:L14) -> 16419.901 | M6: =SUM(M7:M14) -> 17242.623 | N6: =SUM(N7:N14) -> 17229.622 | O6: =SUM(O7:O14) -> 17216.667 | ... AA6: =SUM(AA7:AA14) -> 13911.332
B7: 1.1 | C7: 水费、油费 | D7: =SUM(F7:AA7) -> 104000 | E7: 万元 | H7: =参数输入表!$H$374/(1+参数输入表!$H$378) -> 5200 | I7: =参数输入表!$H$374/(1+参数输入表!$H$378) -> 5200 | J7: =参数输入表!$H$374/(1+参数输入表!$H$378) -> 5200 | K7: =参数输入表!$H$374/(1+参数输入表!$H$378) -> 5200 | L7: =参数输入表!$H$374/(1+参数输入表!$H$378) -> 5200 | M7: =参数输入表!$H$375/(1+参数输入表!$H$378) -> 5200 | N7: =参数输入表!$H$375/(1+参数输入表!$H$378) -> 5200 | O7: =参数输入表!$H$375/(1+参数输入表!$H$378) -> 5200 | P7: =参数输入表!$H$375/(1+参数输入表!$H$378) -> 5200 | Q7: =参数输入表!$H$375/(1+参数输入表!$H$378) -> 5200 | R7: =参数输入表!$H$376/(1+参数输入表!$H$378) -> 5200 | S7: =参数输入表!$H$376/(1+参数输入表!$H$378) -> 5200 | T7: =参数输入表!$H$376/(1+参数输入表!$H$378) -> 5200 | U7: =参数输入表!$H$376/(1+参数输入表!$H$378) -> 5200 | V7: =参数输入表!$H$376/(1+参数输入表!$H$378) -> 5200 | W7: =参数输入表!$H$377/(1+参数输入表!$H$378) -> 5200 | X7: =参数输入表!$H$377/(1+参数输入表!$H$378) -> 5200 | Y7: =参数输入表!$H$377/(1+参数输入表!$H$378) -> 5200 | Z7: =参数输入表!$H$377/(1+参数输入表!$H$378) -> 5200 | AA7: =参数输入表!$H$377/(1+参数输入表!$H$378) -> 5200
B8: 1.2 | C8: 维修费 | D8: =SUM(F8:AA8) -> 13910.639 | E8: 万元 | H8: =(参数输入表!$H$350-参数输入表!$H$353-参数输入表!$H$345-参数输入表!$H$346)*参数输入表!$H$382/(1+参数输入表!$H$386) -> 695.20008 | I8: =(参数输入表!$H$350-参数输入表!$H$353-参数输入表!$H$345-参数输入表!$H$346)*参数输入表!$H$382/(1+参数输入表!$H$386) -> 695.20008 | J8: =(参数输入表!$H$350-参数输入表!$H$353-参数输入表!$H$345-参数输入表!$H$346)*参数输入表!$H$382/(1+参数输入表!$H$386) -> 695.20008 | K8: =(参数输入表!$H$350-参数输入表!$H$353-参数输入表!$H$345-参数输入表!$H$346)*参数输入表!$H$382/(1+参数输入表!$H$386) -> 695.20008 | L8: =(参数输入表!$H$350-参数输入表!$H$353-参数输入表!$H$345-参数输入表!$H$346)*参数输入表!$H$382/(1+参数输入表!$H$386) -> 695.20008 | M8: =(参数输入表!$H$350-参数输入表!$H$353-参数输入表!$H$345-参数输入表!$H$346)*参数输入表!$H$382/(1+参数输入表!$H$386) -> 695.20008 | N8: =(参数输入表!$H$350-参数输入表!$H$353-参数输入表!$H$345-参数输入表!$H$346)*参数输入表!$H$382/(1+参数输入表!$H$386) -> 695.20008 | O8: =(参数输入表!$H$350-参数输入表!$H$353-参数输入表!$H$345-参数输入表!$H$346)*参数输入表!$H$382/(1+参数输入表!$H$386) -> 695.20008 | ... Q8: =(参数输入表!$H$350-参数输入表!$H$353-参数输入表!$H$345-参数输入表!$H$346)*参数输入表!$H$382/(1+参数输入表!$H$386) -> 695.20008 | R8: =(参数输入表!$H$350-参数输入表!$H$353-参数输入表!$H$345-参数输入表!$H$346)*参数输入表!$H$382/(1+参数输入表!$H$386)+参数输入表!$H$667*参数输入表!$H$384/(1+参数输入表!$H$679) -> 701.83725 | S8: =(参数输入表!$H$350-参数输入表!$H$353-参数输入表!$H$345-参数输入表!$H$346)*参数输入表!$H$382/(1+参数输入表!$H$386) -> 695.20008 | T8: =(参数输入表!$H$350-参数输入表!$H$353-参数输入表!$H$345-参数输入表!$H$346)*参数输入表!$H$382/(1+参数输入表!$H$386) -> 695.20008 | U8: =(参数输入表!$H$350-参数输入表!$H$353-参数输入表!$H$345-参数输入表!$H$346)*参数输入表!$H$382/(1+参数输入表!$H$386) -> 695.20008 | V8: =(参数输入表!$H$350-参数输入表!$H$353-参数输入表!$H$345-参数输入表!$H$346)*参数输入表!$H$382/(1+参数输入表!$H$386) -> 695.20008 | W8: =(参数输入表!$H$350-参数输入表!$H$353-参数输入表!$H$345-参数输入表!$H$346)*参数输入表!$H$382/(1+参数输入表!$H$386) -> 695.20008 | X8: =(参数输入表!$H$350-参数输入表!$H$353-参数输入表!$H$345-参数输入表!$H$346)*参数输入表!$H$382/(1+参数输入表!$H$386) -> 695.20008 | Y8: =(参数输入表!$H$350-参数输入表!$H$353-参数输入表!$H$345-参数输入表!$H$346)*参数输入表!$H$382/(1+参数输入表!$H$386) -> 695.20008 | Z8: =(参数输入表!$H$350-参数输入表!$H$353-参数输入表!$H$345-参数输入表!$H$346)*参数输入表!$H$382/(1+参数输入表!$H$386) -> 695.20008 | AA8: =(参数输入表!$H$350-参数输入表!$H$353-参数输入表!$H$345-参数输入表!$H$346)*参数输入表!$H$382/(1+参数输入表!$H$386) -> 695.20008
B9: 1.3 | C9: 生产人员薪酬及福利 | D9: =SUM(F9:AA9) -> 15360 | E9: 万元 | H9: =(参数输入表!$H$397*参数输入表!$H$400+参数输入表!$H$398*参数输入表!$H$401)*(1+参数输入表!$H$402)*(1+参数输入表!$H$403*(H4-1))/(1+参数输入表!$H$404) -> 768 | I9: =(参数输入表!$H$397*参数输入表!$H$400+参数输入表!$H$398*参数输入表!$H$401)*(1+参数输入表!$H$402)*(1+参数输入表!$H$403*(I4-1))/(1+参数输入表!$H$404) -> 768 | J9: =(参数输入表!$H$397*参数输入表!$H$400+参数输入表!$H$398*参数输入表!$H$401)*(1+参数输入表!$H$402)*(1+参数输入表!$H$403*(J4-1))/(1+参数输入表!$H$404) -> 768 | K9: =(参数输入表!$H$397*参数输入表!$H$400+参数输入表!$H$398*参数输入表!$H$401)*(1+参数输入表!$H$402)*(1+参数输入表!$H$403*(K4-1))/(1+参数输入表!$H$404) -> 768 | L9: =(参数输入表!$H$397*参数输入表!$H$400+参数输入表!$H$398*参数输入表!$H$401)*(1+参数输入表!$H$402)*(1+参数输入表!$H$403*(L4-1))/(1+参数输入表!$H$404) -> 768 | M9: =(参数输入表!$H$397*参数输入表!$H$400+参数输入表!$H$398*参数输入表!$H$401)*(1+参数输入表!$H$402)*(1+参数输入表!$H$403*(M4-1))/(1+参数输入表!$H$404) -> 768 | N9: =(参数输入表!$H$397*参数输入表!$H$400+参数输入表!$H$398*参数输入表!$H$401)*(1+参数输入表!$H$402)*(1+参数输入表!$H$403*(N4-1))/(1+参数输入表!$H$404) -> 768 | O9: =(参数输入表!$H$397*参数输入表!$H$400+参数输入表!$H$398*参数输入表!$H$401)*(1+参数输入表!$H$402)*(1+参数输入表!$H$403*(O4-1))/(1+参数输入表!$H$404) -> 768 | ... AA9: =(参数输入表!$H$397*参数输入表!$H$400+参数输入表!$H$398*参数输入表!$H$401)*(1+参数输入表!$H$402)*(1+参数输入表!$H$403*(AA4-1))/(1+参数输入表!$H$404) -> 768
B10: 1.4 | C10: 长期待摊费用当期摊销 | D10: =SUM(F10:AA10) -> 0 | E10: 万元 | H10: ='表2-折旧摊销表'!H44 -> 0 | I10: ='表2-折旧摊销表'!I44 -> 0 | J10: ='表2-折旧摊销表'!J44 -> 0 | K10: ='表2-折旧摊销表'!K44 -> 0 | L10: ='表2-折旧摊销表'!L44 -> 0 | M10: ='表2-折旧摊销表'!M44 -> 0 | N10: ='表2-折旧摊销表'!N44 -> 0 | O10: ='表2-折旧摊销表'!O44 -> 0 | ... AA10: ='表2-折旧摊销表'!AA44 -> 0
B11: 1.5 | C11: 营业相关资产折旧及摊销 | D11: =SUM(F11:AA11) -> 55402.199 | E11: 万元 | H11: ='表2-折旧摊销表'!H37+'表2-折旧摊销表'!H47+'表2-折旧摊销表'!H50+'表2-折旧摊销表'!H39+'表2-折旧摊销表'!H41 -> 3771.0112 | I11: ='表2-折旧摊销表'!I37+'表2-折旧摊销表'!I47+'表2-折旧摊销表'!I50+'表2-折旧摊销表'!I39+'表2-折旧摊销表'!I41 -> 3771.0112 | J11: ='表2-折旧摊销表'!J37+'表2-折旧摊销表'!J47+'表2-折旧摊销表'!J50+'表2-折旧摊销表'!J39+'表2-折旧摊销表'!J41 -> 3771.0112 | K11: ='表2-折旧摊销表'!K37+'表2-折旧摊销表'!K47+'表2-折旧摊销表'!K50+'表2-折旧摊销表'!K39+'表2-折旧摊销表'!K41 -> 3771.0112 | L11: ='表2-折旧摊销表'!L37+'表2-折旧摊销表'!L47+'表2-折旧摊销表'!L50+'表2-折旧摊销表'!L39+'表2-折旧摊销表'!L41 -> 3771.0112 | M11: ='表2-折旧摊销表'!M37+'表2-折旧摊销表'!M47+'表2-折旧摊销表'!M50+'表2-折旧摊销表'!M39+'表2-折旧摊销表'!M41 -> 3771.0112 | N11: ='表2-折旧摊销表'!N37+'表2-折旧摊销表'!N47+'表2-折旧摊销表'!N50+'表2-折旧摊销表'!N39+'表2-折旧摊销表'!N41 -> 3771.0112 | O11: ='表2-折旧摊销表'!O37+'表2-折旧摊销表'!O47+'表2-折旧摊销表'!O50+'表2-折旧摊销表'!O39+'表2-折旧摊销表'!O41 -> 3771.0112 | ... AA11: ='表2-折旧摊销表'!AA37+'表2-折旧摊销表'!AA47+'表2-折旧摊销表'!AA50+'表2-折旧摊销表'!AA39+'表2-折旧摊销表'!AA41 -> 591.16873
B12: 1.6 | C12: 其他费用 | D12: =SUM(F12:AA12) -> 44000 | E12: 万元 | H12: =参数输入表!$H$405/(1+参数输入表!$H$406) -> 2200 | I12: =参数输入表!$H$405/(1+参数输入表!$H$406) -> 2200 | J12: =参数输入表!$H$405/(1+参数输入表!$H$406) -> 2200 | K12: =参数输入表!$H$405/(1+参数输入表!$H$406) -> 2200 | L12: =参数输入表!$H$405/(1+参数输入表!$H$406) -> 2200 | M12: =参数输入表!$H$405/(1+参数输入表!$H$406) -> 2200 | N12: =参数输入表!$H$405/(1+参数输入表!$H$406) -> 2200 | O12: =参数输入表!$H$405/(1+参数输入表!$H$406) -> 2200 | ... AA12: =参数输入表!$H$405/(1+参数输入表!$H$406) -> 2200
B13: 1.7 | C13: 电费(每年不同）注意调整 | D13: =SUM(F13:AA13) -> 83018.827 | E13: 万元 | H13: =参数输入表!H417*参数输入表!H418/10/(1+参数输入表!$H$617)+参数输入表!H597/(1+参数输入表!$H$617) -> 3603.4668 | I13: =参数输入表!H426*参数输入表!H427/10/(1+参数输入表!$H$617)+参数输入表!H598/(1+参数输入表!$H$617) -> 3599.0035 | J13: =参数输入表!H435*参数输入表!H436/10/(1+参数输入表!$H$617)+参数输入表!H599/(1+参数输入表!$H$617) -> 3594.5529 | K13: =参数输入表!H444*参数输入表!H445/10/(1+参数输入表!$H$617)+参数输入表!H600/(1+参数输入表!$H$617) -> 3590.115 | L13: =参数输入表!H453*参数输入表!H454/10/(1+参数输入表!$H$617)+参数输入表!H601/(1+参数输入表!$H$617) -> 3585.6898 | M13: =参数输入表!H462*参数输入表!H463/10/(1+参数输入表!$H$617)+参数输入表!H602/(1+参数输入表!$H$617) -> 4408.4122 | N13: =参数输入表!H471*参数输入表!H472/10/(1+参数输入表!$H$617)+参数输入表!H603/(1+参数输入表!$H$617) -> 4395.4108 | O13: =参数输入表!H480*参数输入表!H481/10/(1+参数输入表!$H$617)+参数输入表!H604/(1+参数输入表!$H$617) -> 4382.4561 | P13: =参数输入表!H489*参数输入表!H490/10/(1+参数输入表!$H$617)+参数输入表!H605/(1+参数输入表!$H$617) -> 4369.5478 | Q13: =参数输入表!H498*参数输入表!H499/10/(1+参数输入表!$H$617)+参数输入表!H606/(1+参数输入表!$H$617) -> 4356.6857 | R13: =参数输入表!H507*参数输入表!H508/10/(1+参数输入表!$H$617)+参数输入表!H607/(1+参数输入表!$H$617) -> 4370.2723 | S13: =参数输入表!H516*参数输入表!H517/10/(1+参数输入表!$H$617)+参数输入表!H608/(1+参数输入表!$H$617) -> 4357.502 | T13: =参数输入表!H525*参数输入表!H526/10/(1+参数输入表!$H$617)+参数输入表!H609/(1+参数输入表!$H$617) -> 4344.7773 | U13: =参数输入表!H534*参数输入表!H535/10/(1+参数输入表!$H$617)+参数输入表!H610/(1+参数输入表!$H$617) -> 4332.0979 | V13: =参数输入表!H543*参数输入表!H544/10/(1+参数输入表!$H$617)+参数输入表!H611/(1+参数输入表!$H$617) -> 4319.4637 | W13: =参数输入表!H552*参数输入表!H553/10/(1+参数输入表!$H$617)+参数输入表!H612/(1+参数输入表!$H$617) -> 4306.8746 | X13: =参数输入表!H561*参数输入表!H562/10/(1+参数输入表!$H$617)+参数输入表!H613/(1+参数输入表!$H$617) -> 4294.3301 | Y13: =参数输入表!H570*参数输入表!H571/10/(1+参数输入表!$H$617)+参数输入表!H614/(1+参数输入表!$H$617) -> 4281.8303 | Z13: =参数输入表!H579*参数输入表!H580/10/(1+参数输入表!$H$617)+参数输入表!H615/(1+参数输入表!$H$617) -> 4269.3748 | AA13: =参数输入表!H588*参数输入表!H589/10/(1+参数输入表!$H$617)+参数输入表!H616/(1+参数输入表!$H$617) -> 4256.9635
B14: 1.8 | C14: 宽带费用 | D14: =SUM(F14:AA14) -> 4000 | E14: 万元 | H14: =参数输入表!$H$408/(1+参数输入表!$H$409) -> 200 | I14: =参数输入表!$H$408/(1+参数输入表!$H$409) -> 200 | J14: =参数输入表!$H$408/(1+参数输入表!$H$409) -> 200 | K14: =参数输入表!$H$408/(1+参数输入表!$H$409) -> 200 | L14: =参数输入表!$H$408/(1+参数输入表!$H$409) -> 200 | M14: =参数输入表!$H$408/(1+参数输入表!$H$409) -> 200 | N14: =参数输入表!$H$408/(1+参数输入表!$H$409) -> 200 | O14: =参数输入表!$H$408/(1+参数输入表!$H$409) -> 200 | ... AA14: =参数输入表!$H$408/(1+参数输入表!$H$409) -> 200
B15: 2 | C15: 销售费用 | D15: =SUM(F15:AA15) -> 0 | E15: 万元 | H15: 0 | I15: 0 | J15: 0 | K15: 0 | L15: 0 | M15: 0 | N15: 0 | O15: 0 | P15: 0 | Q15: 0 | R15: 0 | S15: 0 | T15: 0 | U15: 0 | V15: 0 | W15: 0 | X15: 0 | Y15: 0 | Z15: 0 | AA15: 0
B16: 3 | C16: 管理费用 | D16: =SUM(F16:AA16) -> 463.59172 | E16: 万元 | H16: =SUM(H17:H18) -> 23.179586 | I16: =SUM(I17:I18) -> 23.179586 | J16: =SUM(J17:J18) -> 23.179586 | K16: =SUM(K17:K18) -> 23.179586 | L16: =SUM(L17:L18) -> 23.179586 | M16: =SUM(M17:M18) -> 23.179586 | N16: =SUM(N17:N18) -> 23.179586 | O16: =SUM(O17:O18) -> 23.179586 | ... AA16: =SUM(AA17:AA18) -> 23.179586
B17: 3.1 | C17: 保险费 | D17: =SUM(F17:AA17) -> 463.59172 | E17: 万元 | H17: =('表2-折旧摊销表'!$D$4)*参数输入表!$H$390/(1+参数输入表!$H$394) -> 23.179586 | I17: =('表2-折旧摊销表'!$D$4)*参数输入表!$H$390/(1+参数输入表!$H$394) -> 23.179586 | J17: =('表2-折旧摊销表'!$D$4)*参数输入表!$H$390/(1+参数输入表!$H$394) -> 23.179586 | K17: =('表2-折旧摊销表'!$D$4)*参数输入表!$H$390/(1+参数输入表!$H$394) -> 23.179586 | L17: =('表2-折旧摊销表'!$D$4)*参数输入表!$H$390/(1+参数输入表!$H$394) -> 23.179586 | M17: =('表2-折旧摊销表'!$D$4)*参数输入表!$H$390/(1+参数输入表!$H$394) -> 23.179586 | N17: =('表2-折旧摊销表'!$D$4)*参数输入表!$H$390/(1+参数输入表!$H$394) -> 23.179586 | O17: =('表2-折旧摊销表'!$D$4)*参数输入表!$H$390/(1+参数输入表!$H$394) -> 23.179586 | ... AA17: =('表2-折旧摊销表'!$D$4)*参数输入表!$H$390/(1+参数输入表!$H$394) -> 23.179586
B18: 3.2 | C18: 期末拆除费用 | D18: =SUM(F18:AA18) -> 0 | E18: 万元 | H18: 0 | I18: 0 | J18: 0 | K18: 0 | L18: 0 | M18: 0 | N18: 0 | O18: 0 | P18: 0 | Q18: 0 | R18: 0 | S18: 0 | T18: 0 | U18: 0 | V18: 0 | W18: 0 | X18: 0 | Y18: 0 | Z18: 0 | AA18: =参数输入表!H412*参数输入表!H411/(1+参数输入表!$H$413) -> 0
B19: 4 | C19: 研发费用 | D19: =SUM(F19:AA19) -> 0 | E19: 万元 | H19: 0 | I19: 0 | J19: 0 | K19: 0 | L19: 0 | M19: 0 | N19: 0 | O19: 0 | P19: 0 | Q19: 0 | R19: 0 | S19: 0 | T19: 0 | U19: 0 | V19: 0 | W19: 0 | X19: 0 | Y19: 0 | Z19: 0 | AA19: 0
B20: 5 | C20: 财务费用 | D20: =SUM(F20:AA20) -> 15195.816 | E20: 万元 | H20: =SUM(H21:H23) -> 1887.4755 | I20: =SUM(I21:I23) -> 1762.1772 | J20: =SUM(J21:J23) -> 1636.8789 | K20: =SUM(K21:K23) -> 1511.5806 | L20: =SUM(L21:L23) -> 1386.2823 | M20: =SUM(M21:M23) -> 1260.984 | N20: =SUM(N21:N23) -> 1135.6857 | O20: =SUM(O21:O23) -> 1010.3874 | ... AA20: =SUM(AA21:AA23) -> 8.001
B21: 5.1 | C21: 长期借款利息 | D21: =SUM(F21:AA21) -> 15035.796 | E21: 万元 | H21: ='表1-资金筹措及还本付息表'!H43 -> 1879.4745 | I21: ='表1-资金筹措及还本付息表'!I53 -> 1754.1762 | J21: ='表1-资金筹措及还本付息表'!J53 -> 1628.8779 | K21: ='表1-资金筹措及还本付息表'!K53 -> 1503.5796 | L21: ='表1-资金筹措及还本付息表'!L53 -> 1378.2813 | M21: ='表1-资金筹措及还本付息表'!M53 -> 1252.983 | N21: ='表1-资金筹措及还本付息表'!N53 -> 1127.6847 | O21: ='表1-资金筹措及还本付息表'!O53 -> 1002.3864 | P21: ='表1-资金筹措及还本付息表'!P53 -> 877.08812 | ... V21: ='表1-资金筹措及还本付息表'!V53 -> 125.2983 | W21: ='表1-资金筹措及还本付息表'!W43 -> 0 | X21: ='表1-资金筹措及还本付息表'!X43 -> 0 | Y21: ='表1-资金筹措及还本付息表'!Y43 -> 0 | Z21: ='表1-资金筹措及还本付息表'!Z43 -> 0 | AA21: ='表1-资金筹措及还本付息表'!AA43 -> 0
B22: 5.2 | C22: 流动资金利息 | D22: =SUM(F22:AA22) -> 160.02 | E22: 万元 | H22: ='表1-资金筹措及还本付息表'!H63 -> 8.001 | I22: ='表1-资金筹措及还本付息表'!I63 -> 8.001 | J22: ='表1-资金筹措及还本付息表'!J63 -> 8.001 | K22: ='表1-资金筹措及还本付息表'!K63 -> 8.001 | L22: ='表1-资金筹措及还本付息表'!L63 -> 8.001 | M22: ='表1-资金筹措及还本付息表'!M63 -> 8.001 | N22: ='表1-资金筹措及还本付息表'!N63 -> 8.001 | O22: ='表1-资金筹措及还本付息表'!O63 -> 8.001 | ... AA22: ='表1-资金筹措及还本付息表'!AA63 -> 8.001
B23: 5.3 | C23: 短期借款利息 | D23: =SUM(F23:AA23) -> 0 | E23: 万元 | H23: ='表1-资金筹措及还本付息表'!H73 -> 0 | I23: ='表1-资金筹措及还本付息表'!I73 -> 0 | J23: ='表1-资金筹措及还本付息表'!J73 -> 0 | K23: ='表1-资金筹措及还本付息表'!K73 -> 0 | L23: ='表1-资金筹措及还本付息表'!L73 -> 0 | M23: ='表1-资金筹措及还本付息表'!M73 -> 0 | N23: ='表1-资金筹措及还本付息表'!N73 -> 0 | O23: ='表1-资金筹措及还本付息表'!O73 -> 0 | ... AA23: ='表1-资金筹措及还本付息表'!AA73 -> 0
B24: 二 | C24: 营业外支出 | D24: =SUM(F24:AA24) -> 0 | E24: 万元 | H24: =参数输入表!$H$682/(1+参数输入表!$H$686) -> 0 | I24: =参数输入表!$H$682/(1+参数输入表!$H$686) -> 0 | J24: =参数输入表!$H$682/(1+参数输入表!$H$686) -> 0 | K24: =参数输入表!$H$682/(1+参数输入表!$H$686) -> 0 | L24: =参数输入表!$H$682/(1+参数输入表!$H$686) -> 0 | M24: =参数输入表!$H$682/(1+参数输入表!$H$686) -> 0 | N24: =参数输入表!$H$682/(1+参数输入表!$H$686) -> 0 | O24: =参数输入表!$H$682/(1+参数输入表!$H$686) -> 0 | ... AA24: =参数输入表!$H$682/(1+参数输入表!$H$686) -> 0
B26: 成本费用表-全投资
B27: 序号 | C27: 项目 | D27: 合计 | E27: 单位 | F27: 建设期 | H27: 运营期
F28: 1 | G28: 2 | H28: 1 | I28: 2 | J28: 3 | K28: 4 | L28: 5 | M28: 6 | N28: 7 | O28: 8 | P28: 9 | Q28: 10 | R28: 11 | S28: 12 | T28: 13 | U28: 14 | V28: 15 | W28: 16 | X28: 17 | Y28: 18 | Z28: 19 | AA28: 20
B29: 一 | C29: 营业总成本 | D29: =SUM(F29:AA29) -> 320155.26 | E29: 万元 | H29: =H30+H39+H40+H43 -> 16460.858 | I29: =I30+I39+I40+I43 -> 16456.394 | J29: =J30+J39+J40+J43 -> 16451.944 | K29: =K30+K39+K40+K43 -> 16447.506 | L29: =L30+L39+L40+L43 -> 16443.081 | M29: =M30+M39+M40+M43 -> 17265.803 | N29: =N30+N39+N40+N43 -> 17252.802 | O29: =O30+O39+O40+O43 -> 17239.847 | ... AA29: =AA30+AA39+AA40+AA43 -> 13934.512
B30: 1 | C30: 生产成本 | D30: =SUM(F30:AA30) -> 319691.66 | H30: =SUM(H31:H38) -> 16437.678 | I30: =SUM(I31:I38) -> 16433.215 | J30: =SUM(J31:J38) -> 16428.764 | K30: =SUM(K31:K38) -> 16424.326 | L30: =SUM(L31:L38) -> 16419.901 | M30: =SUM(M31:M38) -> 17242.623 | N30: =SUM(N31:N38) -> 17229.622 | O30: =SUM(O31:O38) -> 17216.667 | ... AA30: =SUM(AA31:AA38) -> 13911.332
B31: 1.1 | C31: 材料费 | D31: =SUM(F31:AA31) -> 104000 | E31: 万元 | H31: =H7 -> 5200 | I31: =I7 -> 5200 | J31: =J7 -> 5200 | K31: =K7 -> 5200 | L31: =L7 -> 5200 | M31: =M7 -> 5200 | N31: =N7 -> 5200 | O31: =O7 -> 5200 | ... AA31: =AA7 -> 5200
B32: 1.2 | C32: 维修费 | D32: =SUM(F32:AA32) -> 13910.639 | E32: 万元 | H32: =H8 -> 695.20008 | I32: =I8 -> 695.20008 | J32: =J8 -> 695.20008 | K32: =K8 -> 695.20008 | L32: =L8 -> 695.20008 | M32: =M8 -> 695.20008 | N32: =N8 -> 695.20008 | O32: =O8 -> 695.20008 | ... AA32: =AA8 -> 695.20008
B33: 1.3 | C33: 生产人员薪酬及福利 | D33: =SUM(F33:AA33) -> 15360 | E33: 万元 | H33: =(参数输入表!$H$397*参数输入表!$H$400+参数输入表!$H$398*参数输入表!$H$401)*(1+参数输入表!$H$402)*(1+参数输入表!$H$403*(H28-1))/(1+参数输入表!$H$404) -> 768 | I33: =(参数输入表!$H$397*参数输入表!$H$400+参数输入表!$H$398*参数输入表!$H$401)*(1+参数输入表!$H$402)*(1+参数输入表!$H$403*(I28-1))/(1+参数输入表!$H$404) -> 768 | J33: =(参数输入表!$H$397*参数输入表!$H$400+参数输入表!$H$398*参数输入表!$H$401)*(1+参数输入表!$H$402)*(1+参数输入表!$H$403*(J28-1))/(1+参数输入表!$H$404) -> 768 | K33: =(参数输入表!$H$397*参数输入表!$H$400+参数输入表!$H$398*参数输入表!$H$401)*(1+参数输入表!$H$402)*(1+参数输入表!$H$403*(K28-1))/(1+参数输入表!$H$404) -> 768 | L33: =(参数输入表!$H$397*参数输入表!$H$400+参数输入表!$H$398*参数输入表!$H$401)*(1+参数输入表!$H$402)*(1+参数输入表!$H$403*(L28-1))/(1+参数输入表!$H$404) -> 768 | M33: =(参数输入表!$H$397*参数输入表!$H$400+参数输入表!$H$398*参数输入表!$H$401)*(1+参数输入表!$H$402)*(1+参数输入表!$H$403*(M28-1))/(1+参数输入表!$H$404) -> 768 | N33: =(参数输入表!$H$397*参数输入表!$H$400+参数输入表!$H$398*参数输入表!$H$401)*(1+参数输入表!$H$402)*(1+参数输入表!$H$403*(N28-1))/(1+参数输入表!$H$404) -> 768 | O33: =(参数输入表!$H$397*参数输入表!$H$400+参数输入表!$H$398*参数输入表!$H$401)*(1+参数输入表!$H$402)*(1+参数输入表!$H$403*(O28-1))/(1+参数输入表!$H$404) -> 768 | ... AA33: =(参数输入表!$H$397*参数输入表!$H$400+参数输入表!$H$398*参数输入表!$H$401)*(1+参数输入表!$H$402)*(1+参数输入表!$H$403*(AA28-1))/(1+参数输入表!$H$404) -> 768
B34: 1.4 | C34: 长期待摊费用当期摊销 | D34: =SUM(F34:AA34) -> 0 | E34: 万元 | H34: ='表2-折旧摊销表'!H76 -> 0 | I34: ='表2-折旧摊销表'!I76 -> 0 | J34: ='表2-折旧摊销表'!J76 -> 0 | K34: ='表2-折旧摊销表'!K76 -> 0 | L34: ='表2-折旧摊销表'!L76 -> 0 | M34: ='表2-折旧摊销表'!M76 -> 0 | N34: ='表2-折旧摊销表'!N76 -> 0 | O34: ='表2-折旧摊销表'!O76 -> 0 | ... AA34: ='表2-折旧摊销表'!AA76 -> 0
B35: 1.5 | C35: 营业相关资产折旧及摊销 | D35: =SUM(F35:AA35) -> 55402.199 | E35: 万元 | H35: ='表2-折旧摊销表'!H69+'表2-折旧摊销表'!H79+'表2-折旧摊销表'!H82+'表2-折旧摊销表'!H39+'表2-折旧摊销表'!H41 -> 3771.0112 | I35: ='表2-折旧摊销表'!I69+'表2-折旧摊销表'!I79+'表2-折旧摊销表'!I82+'表2-折旧摊销表'!I39+'表2-折旧摊销表'!I41 -> 3771.0112 | J35: ='表2-折旧摊销表'!J69+'表2-折旧摊销表'!J79+'表2-折旧摊销表'!J82+'表2-折旧摊销表'!J39+'表2-折旧摊销表'!J41 -> 3771.0112 | K35: ='表2-折旧摊销表'!K69+'表2-折旧摊销表'!K79+'表2-折旧摊销表'!K82+'表2-折旧摊销表'!K39+'表2-折旧摊销表'!K41 -> 3771.0112 | L35: ='表2-折旧摊销表'!L69+'表2-折旧摊销表'!L79+'表2-折旧摊销表'!L82+'表2-折旧摊销表'!L39+'表2-折旧摊销表'!L41 -> 3771.0112 | M35: ='表2-折旧摊销表'!M69+'表2-折旧摊销表'!M79+'表2-折旧摊销表'!M82+'表2-折旧摊销表'!M39+'表2-折旧摊销表'!M41 -> 3771.0112 | N35: ='表2-折旧摊销表'!N69+'表2-折旧摊销表'!N79+'表2-折旧摊销表'!N82+'表2-折旧摊销表'!N39+'表2-折旧摊销表'!N41 -> 3771.0112 | O35: ='表2-折旧摊销表'!O69+'表2-折旧摊销表'!O79+'表2-折旧摊销表'!O82+'表2-折旧摊销表'!O39+'表2-折旧摊销表'!O41 -> 3771.0112 | ... AA35: ='表2-折旧摊销表'!AA69+'表2-折旧摊销表'!AA79+'表2-折旧摊销表'!AA82+'表2-折旧摊销表'!AA39+'表2-折旧摊销表'!AA41 -> 591.16873
B36: 1.6 | C36: 其他费用 | D36: =SUM(F36:AA36) -> 44000 | E36: 万元 | H36: =H12 -> 2200 | I36: =I12 -> 2200 | J36: =J12 -> 2200 | K36: =K12 -> 2200 | L36: =L12 -> 2200 | M36: =M12 -> 2200 | N36: =N12 -> 2200 | O36: =O12 -> 2200 | ... AA36: =AA12 -> 2200
B37: 1.7 | C37: 电费(每年不同）注意调整 | D37: =SUM(F37:AA37) -> 83018.827 | E37: 万元 | H37: =H13 -> 3603.4668 | I37: =I13 -> 3599.0035 | J37: =J13 -> 3594.5529 | K37: =K13 -> 3590.115 | L37: =L13 -> 3585.6898 | M37: =M13 -> 4408.4122 | N37: =N13 -> 4395.4108 | O37: =O13 -> 4382.4561 | ... AA37: =AA13 -> 4256.9635
B38: 1.8 | C38: 宽带费用 | D38: =SUM(F38:AA38) -> 4000 | E38: 万元 | H38: =H14 -> 200 | I38: =I14 -> 200 | J38: =J14 -> 200 | K38: =K14 -> 200 | L38: =L14 -> 200 | M38: =M14 -> 200 | N38: =N14 -> 200 | O38: =O14 -> 200 | ... AA38: =AA14 -> 200
B39: 2 | C39: 销售费用 | D39: =SUM(F39:AA39) -> 0 | E39: 万元 | H39: 0 | I39: 0 | J39: 0 | K39: 0 | L39: 0 | M39: 0 | N39: 0 | O39: 0 | P39: 0 | Q39: 0 | R39: 0 | S39: 0 | T39: 0 | U39: 0 | V39: 0 | W39: 0 | X39: 0 | Y39: 0 | Z39: 0 | AA39: 0
B40: 3 | C40: 管理费用 | D40: =SUM(F40:AA40) -> 463.59172 | E40: 万元 | H40: =SUM(H41:H42) -> 23.179586 | I40: =SUM(I41:I42) -> 23.179586 | J40: =SUM(J41:J42) -> 23.179586 | K40: =SUM(K41:K42) -> 23.179586 | L40: =SUM(L41:L42) -> 23.179586 | M40: =SUM(M41:M42) -> 23.179586 | N40: =SUM(N41:N42) -> 23.179586 | O40: =SUM(O41:O42) -> 23.179586 | ... AA40: =SUM(AA41:AA42) -> 23.179586
B41: 3.1 | C41: 保险费 | D41: =SUM(F41:AA41) -> 463.59172 | E41: 万元 | H41: =H17 -> 23.179586 | I41: =I17 -> 23.179586 | J41: =J17 -> 23.179586 | K41: =K17 -> 23.179586 | L41: =L17 -> 23.179586 | M41: =M17 -> 23.179586 | N41: =N17 -> 23.179586 | O41: =O17 -> 23.179586 | ... AA41: =AA17 -> 23.179586
B42: 3.2 | C42: 期末拆除费用 | D42: =SUM(F42:AA42) -> 0 | E42: 万元 | H42: 0 | I42: 0 | J42: 0 | K42: 0 | L42: 0 | M42: 0 | N42: 0 | O42: 0 | P42: 0 | Q42: 0 | R42: 0 | S42: 0 | T42: 0 | U42: 0 | V42: 0 | W42: 0 | X42: 0 | Y42: 0 | Z42: 0 | AA42: =参数输入表!H412*参数输入表!H411/(1+参数输入表!$H$413) -> 0
...

Sheet 表4-收入税金表
B2: 收入表
B3: 序号 | C3: 项目 | D3: 合计 | E3: 单位 | F3: 建设期 | H3: 运营期
F4: 1 | G4: 2 | H4: 1 | I4: 2 | J4: 3 | K4: 4 | L4: 5 | M4: 6 | N4: 7 | O4: 8 | P4: 9 | Q4: 10 | R4: 11 | S4: 12 | T4: 13 | U4: 14 | V4: 15 | W4: 16 | X4: 17 | Y4: 18 | Z4: 19 | AA4: 20
B5: 1 | C5: 营业收入 | D5: =SUM(F5:AA5) -> 373365.74 | E5: 万元 | H5: =H6+H10 -> 25177.721 | I5: =I6+I10 -> 17630.551 | J5: =J6+J10 -> 17630.551 | K5: =K6+K10 -> 17630.551 | L5: =L6+L10 -> 17630.551 | M5: =M6+M10 -> 17630.551 | N5: =N6+N10 -> 18573.947 | O5: =O6+O10 -> 18573.947 | ... AA5: =AA6+AA10 -> 18573.947
B6: 1.1 | C6: 销售收入 | D6: =SUM(F6:AA6) -> 373365.74 | E6: 万元 | H6: =H7 -> 25177.721 | I6: =I7 -> 17630.551 | J6: =J7 -> 17630.551 | K6: =K7 -> 17630.551 | L6: =L7 -> 17630.551 | M6: =M7 -> 17630.551 | N6: =N7 -> 18573.947 | O6: =O7 -> 18573.947 | ... AA6: =AA7 -> 18573.947
B7: 1.1.1 | C7: 租赁收入 | D7: =SUM(H7:AA7) -> 373365.74 | E7: 万元 | G7: =H7*1.06 -> 26688.384 | H7: =H8+H9 -> 25177.721 | I7: =I8+I9 -> 17630.551 | J7: =J8+J9 -> 17630.551 | K7: =K8+K9 -> 17630.551 | L7: =L8+L9 -> 17630.551 | M7: =M8+M9 -> 17630.551 | N7: =N8+N9 -> 18573.947 | O7: =O8+O9 -> 18573.947 | ... AA7: =AA8+AA9 -> 18573.947
C8: 机柜租赁收入 | D8: =SUM(H8:AA8) -> 333743.09 | E8: 万元 | H8: =(参数输入表!H113*参数输入表!H114+参数输入表!H116*参数输入表!H117)/(1+参数输入表!$H$251) -> 16687.155 | I8: =(参数输入表!H120*参数输入表!H121+参数输入表!H123*参数输入表!H124)/(1+参数输入表!$H$251) -> 16687.155 | J8: =(参数输入表!H127*参数输入表!H128+参数输入表!H130*参数输入表!H131)/(1+参数输入表!$H$251) -> 16687.155 | K8: =(参数输入表!H134*参数输入表!H135+参数输入表!H137*参数输入表!H138)/(1+参数输入表!$H$251) -> 16687.155 | L8: =(参数输入表!H141*参数输入表!H142+参数输入表!H144*参数输入表!H145)/(1+参数输入表!$H$251) -> 16687.155 | M8: =(参数输入表!H148*参数输入表!H149+参数输入表!H151*参数输入表!H152)/(1+参数输入表!$H$251) -> 16687.155 | N8: =(参数输入表!H155*参数输入表!H156+参数输入表!H158*参数输入表!H159)/(1+参数输入表!$H$251) -> 16687.155 | O8: =(参数输入表!H162*参数输入表!H163+参数输入表!H165*参数输入表!H166)/(1+参数输入表!$H$251) -> 16687.155 | P8: =(参数输入表!H169*参数输入表!H170+参数输入表!H172*参数输入表!H173)/(1+参数输入表!$H$251) -> 16687.155 | Q8: =(参数输入表!H176*参数输入表!H177+参数输入表!H179*参数输入表!H180)/(1+参数输入表!$H$251) -> 16687.155 | R8: =(参数输入表!H183*参数输入表!H184+参数输入表!H186*参数输入表!H187)/(1+参数输入表!$H$251) -> 16687.155 | S8: =(参数输入表!H190*参数输入表!H191+参数输入表!H193*参数输入表!H194)/(1+参数输入表!$H$251) -> 16687.155 | T8: =(参数输入表!H197*参数输入表!H198+参数输入表!H200*参数输入表!H201)/(1+参数输入表!$H$251) -> 16687.155 | U8: =(参数输入表!H204*参数输入表!H205+参数输入表!H207*参数输入表!H208)/(1+参数输入表!$H$251) -> 16687.155 | V8: =(参数输入表!H211*参数输入表!H212+参数输入表!H214*参数输入表!H215)/(1+参数输入表!$H$251) -> 16687.155 | W8: =(参数输入表!H218*参数输入表!H219+参数输入表!H221*参数输入表!H222)/(1+参数输入表!$H$251) -> 16687.155 | X8: =(参数输入表!H225*参数输入表!H226+参数输入表!H228*参数输入表!H229)/(1+参数输入表!$H$251) -> 16687.155 | Y8: =(参数输入表!H232*参数输入表!H233+参数输入表!H235*参数输入表!H236)/(1+参数输入表!$H$251) -> 16687.155 | Z8: =(参数输入表!H239*参数输入表!H240+参数输入表!H242*参数输入表!H243)/(1+参数输入表!$H$251) -> 16687.155 | AA8: =(参数输入表!H246*参数输入表!H247+参数输入表!H249*参数输入表!H250)/(1+参数输入表!$H$251) -> 16687.155
C9: 算力租赁收入 | D9: =SUM(F9:AA9) -> 39622.642 | E9: 万元 | H9: =参数输入表!H254/(1+参数输入表!$H$293) -> 8490.566 | I9: =参数输入表!H256/(1+参数输入表!$H$293) -> 943.39623 | J9: =参数输入表!H258/(1+参数输入表!$H$293) -> 943.39623 | K9: =参数输入表!H260/(1+参数输入表!$H$293) -> 943.39623 | L9: =参数输入表!H262/(1+参数输入表!$H$293) -> 943.39623 | M9: =参数输入表!H264/(1+参数输入表!$H$293) -> 943.39623 | N9: =参数输入表!H266/(1+参数输入表!$H$293) -> 1886.7925 | O9: =参数输入表!H268/(1+参数输入表!$H$293) -> 1886.7925 | P9: =参数输入表!H270/(1+参数输入表!$H$293) -> 1886.7925 | Q9: =参数输入表!H272/(1+参数输入表!$H$293) -> 1886.7925 | R9: =参数输入表!H274/(1+参数输入表!$H$293) -> 1886.7925 | S9: =参数输入表!H276/(1+参数输入表!$H$293) -> 1886.7925 | T9: =参数输入表!H278/(1+参数输入表!$H$293) -> 1886.7925 | U9: =参数输入表!H280/(1+参数输入表!$H$293) -> 1886.7925 | V9: =参数输入表!H282/(1+参数输入表!$H$293) -> 1886.7925 | W9: =参数输入表!H284/(1+参数输入表!$H$293) -> 1886.7925 | X9: =参数输入表!H286/(1+参数输入表!$H$293) -> 1886.7925 | Y9: =参数输入表!H288/(1+参数输入表!$H$293) -> 1886.7925 | Z9: =参数输入表!H290/(1+参数输入表!$H$293) -> 1886.7925 | AA9: =参数输入表!H290/(1+参数输入表!$H$293) -> 1886.7925
B10: 2 | C10: 其他收入 | D10: =SUM(F10:AA10) -> 0 | E10: 万元 | H10: =(参数输入表!H295)/(1+参数输入表!$H$315) -> 0 | I10: =(参数输入表!H296)/(1+参数输入表!$H$315) -> 0 | J10: =(参数输入表!H297)/(1+参数输入表!$H$315) -> 0 | K10: =(参数输入表!H298)/(1+参数输入表!$H$315) -> 0 | L10: =(参数输入表!H299)/(1+参数输入表!$H$315) -> 0 | M10: =(参数输入表!H300)/(1+参数输入表!$H$315) -> 0 | N10: =(参数输入表!H301)/(1+参数输入表!$H$315) -> 0 | O10: =(参数输入表!H302)/(1+参数输入表!$H$315) -> 0 | P10: =(参数输入表!H303)/(1+参数输入表!$H$315) -> 0 | Q10: =(参数输入表!H304)/(1+参数输入表!$H$315) -> 0 | R10: =(参数输入表!H305)/(1+参数输入表!$H$315) -> 0 | S10: =(参数输入表!H306)/(1+参数输入表!$H$315) -> 0 | T10: =(参数输入表!H307)/(1+参数输入表!$H$315) -> 0 | U10: =(参数输入表!H308)/(1+参数输入表!$H$315) -> 0 | V10: =(参数输入表!H309)/(1+参数输入表!$H$315) -> 0 | W10: =(参数输入表!H310)/(1+参数输入表!$H$315) -> 0 | X10: =(参数输入表!H311)/(1+参数输入表!$H$315) -> 0 | Y10: =(参数输入表!H312)/(1+参数输入表!$H$315) -> 0 | Z10: =(参数输入表!H313)/(1+参数输入表!$H$315) -> 0 | AA10: =(参数输入表!H314)/(1+参数输入表!$H$315) -> 0
B11: 3 | C11: 营业外收入 | D11: =SUM(F11:AA11) -> 0 | E11: 万元 | H11: =SUM(H12:H13) -> 0 | I11: =SUM(I12:I13) -> 0 | J11: =SUM(J12:J13) -> 0 | K11: =SUM(K12:K13) -> 0 | L11: =SUM(L12:L13) -> 0 | M11: =SUM(M12:M13) -> 0 | N11: =SUM(N12:N13) -> 0 | O11: =SUM(O12:O13) -> 0 | ... AA11: =SUM(AA12:AA13) -> 0
B12: 3.1 | C12: 政府一次性运营补贴收入 | D12: =SUM(F12:AA12) -> 0 | E12: 万元 | H12: =参数输入表!H318 -> 0
B13: 3.2 | C13: 增值税即征即退 | D13: =SUM(F13:AA13) -> 0 | E13: 万元 | H13: =H16*参数输入表!$H$688 -> 0 | I13: =I16*参数输入表!$H$688 -> 0 | J13: =J16*参数输入表!$H$688 -> 0 | K13: =K16*参数输入表!$H$688 -> 0 | L13: =L16*参数输入表!$H$688 -> 0 | M13: =M16*参数输入表!$H$688 -> 0 | N13: =N16*参数输入表!$H$688 -> 0 | O13: =O16*参数输入表!$H$688 -> 0 | ... AA13: =AA16*参数输入表!$H$688 -> 0
B15: 税金表
B16: 1 | C16: 当期实缴增值税 | D16: =SUM(F16:AA16) -> 7094.9645 | E16: 万元 | F16: 0 | G16: =IF(G39>0,0,G38-F39) -> 0 | H16: =IF(H39>0,0,H38-G39) -> 0 | I16: =IF(I39>0,0,I38-H39) -> 0 | J16: =IF(J39>0,0,J38-I39) -> 0 | K16: =IF(K39>0,0,K38-J39) -> 0 | L16: =IF(L39>0,0,L38-K39) -> 0 | M16: =IF(M39>0,0,M38-L39) -> 0 | N16: =IF(N39>0,0,N38-M39) -> 0 | ... AA16: =IF(AA39>0,0,AA38-Z39) -> 561.03158
B17: 2 | C17: 增值税销项税 | D17: =SUM(F17:AA17) -> 22401.944 | E17: 万元 | F17: =SUM(F18:F19) -> 0 | G17: =SUM(G18:G19) -> 0 | H17: =SUM(H18:H19) -> 1510.6632 | I17: =SUM(I18:I19) -> 1057.8331 | J17: =SUM(J18:J19) -> 1057.8331 | K17: =SUM(K18:K19) -> 1057.8331 | L17: =SUM(L18:L19) -> 1057.8331 | M17: =SUM(M18:M19) -> 1057.8331 | ... AA17: =SUM(AA18:AA19) -> 1114.4368
C18: 发电收入销项税 | D18: =SUM(F18:AA18) -> 22401.944 | E18: 万元 | H18: =H6*参数输入表!$H$251 -> 1510.6632 | I18: =I6*参数输入表!$H$251 -> 1057.8331 | J18: =J6*参数输入表!$H$251 -> 1057.8331 | K18: =K6*参数输入表!$H$251 -> 1057.8331 | L18: =L6*参数输入表!$H$251 -> 1057.8331 | M18: =M6*参数输入表!$H$251 -> 1057.8331 | N18: =N6*参数输入表!$H$251 -> 1114.4368 | O18: =O6*参数输入表!$H$251 -> 1114.4368 | ... AA18: =AA6*参数输入表!$H$251 -> 1114.4368
C19: 其他收入销项税 | D19: =SUM(F19:AA19) -> 0 | E19: 万元 | H19: =H10*参数输入表!$H$315 -> 0 | I19: =I10*参数输入表!$H$315 -> 0 | J19: =J10*参数输入表!$H$315 -> 0 | K19: =K10*参数输入表!$H$315 -> 0 | L19: =L10*参数输入表!$H$315 -> 0 | M19: =M10*参数输入表!$H$315 -> 0 | N19: =N10*参数输入表!$H$315 -> 0 | O19: =O10*参数输入表!$H$315 -> 0 | ... AA19: =AA10*参数输入表!$H$315 -> 0
B20: 3 | C20: 增值税进项税 | D20: =SUM(F20:AA20) -> 15306.98 | E20: 万元 | F20: =F21+F22+F36+F37 -> 2674.206 | G20: =G21+G22+G36+G37 -> 1782.804 | H20: =H21+H22+H36+H37 -> 468.45069 | I20: =I21+I22+I36+I37 -> 467.87045 | J20: =J21+J22+J36+J37 -> 467.29187 | K20: =K21+K22+K36+K37 -> 466.71495 | L20: =L21+L22+L36+L37 -> 466.13967 | M20: =M21+M22+M36+M37 -> 573.09358 | ... AA20: =AA21+AA22+AA36+AA37 -> 553.40525
B21: 3.1 | C21: 建设投资进项税 | D21: =SUM(F21:AA21) -> 4457.01 | E21: 万元 | F21: =参数输入表!H353*参数输入表!H102 -> 2674.206 | G21: =参数输入表!H353*参数输入表!H103 -> 1782.804
B22: 3.2 | C22: 营业成本进项税 | D22: =SUM(F22:AA22) -> 10792.448 | E22: 万元 | F22: =F23+F31+F32+F35 -> 0 | G22: =G23+G31+G32+G35 -> 0 | H22: =H23+H31+H32+H35 -> 468.45069 | I22: =I23+I31+I32+I35 -> 467.87045 | J22: =J23+J31+J32+J35 -> 467.29187 | K22: =K23+K31+K32+K35 -> 466.71495 | L22: =L23+L31+L32+L35 -> 466.13967 | M22: =M23+M31+M32+M35 -> 573.09358 | ... AA22: =AA23+AA31+AA32+AA35 -> 553.40525
B23: 3.2.1 | C23: 生产成本进项税 | D23: =SUM(F23:AA23) -> 10792.448 | E23: 万元 | H23: =SUM(H24:H30) -> 468.45069 | I23: =SUM(I24:I30) -> 467.87045 | J23: =SUM(J24:J30) -> 467.29187 | K23: =SUM(K24:K30) -> 466.71495 | L23: =SUM(L24:L30) -> 466.13967 | M23: =SUM(M24:M30) -> 573.09358 | N23: =SUM(N24:N30) -> 571.40341 | O23: =SUM(O24:O30) -> 569.7193 | ... AA23: =SUM(AA24:AA30) -> 553.40525
C24: 材料费 | D24: =SUM(F24:AA24) -> 0 | E24: 万元 | H24: ='表3-成本费用表'!H50*参数输入表!$H$378 -> 0 | I24: ='表3-成本费用表'!I50*参数输入表!$H$378 -> 0 | J24: ='表3-成本费用表'!J50*参数输入表!$H$378 -> 0 | K24: ='表3-成本费用表'!K50*参数输入表!$H$378 -> 0 | L24: ='表3-成本费用表'!L50*参数输入表!$H$378 -> 0 | M24: ='表3-成本费用表'!M50*参数输入表!$H$378 -> 0 | N24: ='表3-成本费用表'!N50*参数输入表!$H$378 -> 0 | O24: ='表3-成本费用表'!O50*参数输入表!$H$378 -> 0 | ... AA24: ='表3-成本费用表'!AA50*参数输入表!$H$378 -> 0
C25: 维修费 | D25: =SUM(F25:AA25) -> 0 | E25: 万元 | H25: ='表3-成本费用表'!H51*参数输入表!$H$386 -> 0 | I25: ='表3-成本费用表'!I51/(1+参数输入表!$H$386)*参数输入表!$H$386 -> 0 | J25: ='表3-成本费用表'!J51/(1+参数输入表!$H$386)*参数输入表!$H$386 -> 0 | K25: ='表3-成本费用表'!K51/(1+参数输入表!$H$386)*参数输入表!$H$386 -> 0 | L25: ='表3-成本费用表'!L51/(1+参数输入表!$H$386)*参数输入表!$H$386 -> 0 | M25: ='表3-成本费用表'!M51/(1+参数输入表!$H$386)*参数输入表!$H$386 -> 0 | N25: ='表3-成本费用表'!N51/(1+参数输入表!$H$386)*参数输入表!$H$386 -> 0 | O25: ='表3-成本费用表'!O51/(1+参数输入表!$H$386)*参数输入表!$H$386 -> 0 | P25: ='表3-成本费用表'!P51/(1+参数输入表!$H$386)*参数输入表!$H$386 -> 0 | ... AA25: ='表3-成本费用表'!AA51/(1+参数输入表!$H$386)*参数输入表!$H$386 -> 0
C26: 生产人员薪酬及福利 | D26: =SUM(F26:AA26) -> 0 | E26: 万元 | H26: ='表3-成本费用表'!H52*参数输入表!$H$404 -> 0 | I26: ='表3-成本费用表'!I52/(1+参数输入表!$H$404)*参数输入表!$H$404 -> 0 | J26: ='表3-成本费用表'!J52/(1+参数输入表!$H$404)*参数输入表!$H$404 -> 0 | K26: ='表3-成本费用表'!K52/(1+参数输入表!$H$404)*参数输入表!$H$404 -> 0 | L26: ='表3-成本费用表'!L52/(1+参数输入表!$H$404)*参数输入表!$H$404 -> 0 | M26: ='表3-成本费用表'!M52/(1+参数输入表!$H$404)*参数输入表!$H$404 -> 0 | N26: ='表3-成本费用表'!N52/(1+参数输入表!$H$404)*参数输入表!$H$404 -> 0 | O26: ='表3-成本费用表'!O52/(1+参数输入表!$H$404)*参数输入表!$H$404 -> 0 | P26: ='表3-成本费用表'!P52/(1+参数输入表!$H$404)*参数输入表!$H$404 -> 0 | ... AA26: ='表3-成本费用表'!AA52/(1+参数输入表!$H$404)*参数输入表!$H$404 -> 0
C27: 其他费用 | D27: =SUM(F27:AA27) -> 0 | E27: 万元 | H27: ='表3-成本费用表'!H54*参数输入表!$H$406 -> 0 | I27: ='表3-成本费用表'!I54/(1+参数输入表!$H$406)*参数输入表!$H$406 -> 0 | J27: ='表3-成本费用表'!J54/(1+参数输入表!$H$406)*参数输入表!$H$406 -> 0 | K27: ='表3-成本费用表'!K54/(1+参数输入表!$H$406)*参数输入表!$H$406 -> 0 | L27: ='表3-成本费用表'!L54/(1+参数输入表!$H$406)*参数输入表!$H$406 -> 0 | M27: ='表3-成本费用表'!M54/(1+参数输入表!$H$406)*参数输入表!$H$406 -> 0 | N27: ='表3-成本费用表'!N54/(1+参数输入表!$H$406)*参数输入表!$H$406 -> 0 | O27: ='表3-成本费用表'!O54/(1+参数输入表!$H$406)*参数输入表!$H$406 -> 0 | P27: ='表3-成本费用表'!P54/(1+参数输入表!$H$406)*参数输入表!$H$406 -> 0 | ... AA27: ='表3-成本费用表'!AA54/(1+参数输入表!$H$406)*参数输入表!$H$406 -> 0
C28: 下网电费 | D28: =SUM(F28:AA28) -> 10792.448 | E28: 万元 | H28: ='表3-成本费用表'!H13*参数输入表!$H$617 -> 468.45069 | I28: ='表3-成本费用表'!I13*参数输入表!$H$617 -> 467.87045 | J28: ='表3-成本费用表'!J13*参数输入表!$H$617 -> 467.29187 | K28: ='表3-成本费用表'!K13*参数输入表!$H$617 -> 466.71495 | L28: ='表3-成本费用表'!L13*参数输入表!$H$617 -> 466.13967 | M28: ='表3-成本费用表'!M13*参数输入表!$H$617 -> 573.09358 | N28: ='表3-成本费用表'!N13*参数输入表!$H$617 -> 571.40341 | O28: ='表3-成本费用表'!O13*参数输入表!$H$617 -> 569.7193 | ... AA28: ='表3-成本费用表'!AA13*参数输入表!$H$617 -> 553.40525
C29: 场地租金费用 | D29: =SUM(F29:AA29) -> 0 | E29: 万元 | H29: ='表3-成本费用表'!H56/(1+参数输入表!$H$409)*参数输入表!$H$409 -> 0 | I29: ='表3-成本费用表'!I56/(1+参数输入表!$H$409)*参数输入表!$H$409 -> 0 | J29: ='表3-成本费用表'!J56/(1+参数输入表!$H$409)*参数输入表!$H$409 -> 0 | K29: ='表3-成本费用表'!K56/(1+参数输入表!$H$409)*参数输入表!$H$409 -> 0 | L29: ='表3-成本费用表'!L56/(1+参数输入表!$H$409)*参数输入表!$H$409 -> 0 | M29: ='表3-成本费用表'!M56/(1+参数输入表!$H$409)*参数输入表!$H$409 -> 0 | N29: ='表3-成本费用表'!N56/(1+参数输入表!$H$409)*参数输入表!$H$409 -> 0 | O29: ='表3-成本费用表'!O56/(1+参数输入表!$H$409)*参数输入表!$H$409 -> 0 | ... AA29: ='表3-成本费用表'!AA56/(1+参数输入表!$H$409)*参数输入表!$H$409 -> 0
C30: 计入长期待摊成本项 | D30: =SUM(F30:AA30) -> 0 | E30: 万元 | H30: ='表3-成本费用表'!H53/(1+参数输入表!$H$653)*参数输入表!$H$653 -> 0 | I30: ='表3-成本费用表'!I53/(1+参数输入表!$H$653)*参数输入表!$H$653 -> 0 | J30: ='表3-成本费用表'!J53/(1+参数输入表!$H$653)*参数输入表!$H$653 -> 0 | K30: ='表3-成本费用表'!K53/(1+参数输入表!$H$653)*参数输入表!$H$653 -> 0 | L30: ='表3-成本费用表'!L53/(1+参数输入表!$H$653)*参数输入表!$H$653 -> 0 | M30: ='表3-成本费用表'!M53/(1+参数输入表!$H$653)*参数输入表!$H$653 -> 0 | N30: ='表3-成本费用表'!N53/(1+参数输入表!$H$653)*参数输入表!$H$653 -> 0 | O30: ='表3-成本费用表'!O53/(1+参数输入表!$H$653)*参数输入表!$H$653 -> 0 | ... AA30: ='表3-成本费用表'!AA53/(1+参数输入表!$H$653)*参数输入表!$H$653 -> 0
B31: 3.2.2 | C31: 销售费用进项税 | D31: =SUM(F31:AA31) -> 0 | E31: 万元 | H31: 0 | I31: 0 | J31: 0 | K31: 0 | L31: 0 | M31: 0 | N31: 0 | O31: 0 | P31: 0 | Q31: 0 | R31: 0 | S31: 0 | T31: 0 | U31: 0 | V31: 0 | W31: 0 | X31: 0 | Y31: 0 | Z31: 0 | AA31: 0
B32: 3.2.3 | C32: 管理费用进项税 | D32: =SUM(F32:AA32) -> 0 | E32: 万元 | H32: =SUM(H33:H34) -> 0 | I32: =SUM(I33:I34) -> 0 | J32: =SUM(J33:J34) -> 0 | K32: =SUM(K33:K34) -> 0 | L32: =SUM(L33:L34) -> 0 | M32: =SUM(M33:M34) -> 0 | N32: =SUM(N33:N34) -> 0 | O32: =SUM(O33:O34) -> 0 | ... AA32: =SUM(AA33:AA34) -> 0
C33: 保险费 | D33: =SUM(F33:AA33) -> 0 | E33: 万元 | H33: ='表3-成本费用表'!H17*参数输入表!$H$394 -> 0 | I33: ='表3-成本费用表'!I17*参数输入表!$H$394 -> 0 | J33: ='表3-成本费用表'!J17*参数输入表!$H$394 -> 0 | K33: ='表3-成本费用表'!K17*参数输入表!$H$394 -> 0 | L33: ='表3-成本费用表'!L17*参数输入表!$H$394 -> 0 | M33: ='表3-成本费用表'!M17*参数输入表!$H$394 -> 0 | N33: ='表3-成本费用表'!N17*参数输入表!$H$394 -> 0 | O33: ='表3-成本费用表'!O17*参数输入表!$H$394 -> 0 | ... AA33: ='表3-成本费用表'!AA17*参数输入表!$H$394 -> 0
C34: 期末拆除费用 | D34: =SUM(F34:AA34) -> 0 | E34: 万元 | H34: ='表3-成本费用表'!H18*参数输入表!$H$413 -> 0 | I34: ='表3-成本费用表'!I18*参数输入表!$H$413 -> 0 | J34: ='表3-成本费用表'!J18*参数输入表!$H$413 -> 0 | K34: ='表3-成本费用表'!K18*参数输入表!$H$413 -> 0 | L34: ='表3-成本费用表'!L18*参数输入表!$H$413 -> 0 | M34: ='表3-成本费用表'!M18*参数输入表!$H$413 -> 0 | N34: ='表3-成本费用表'!N18*参数输入表!$H$413 -> 0 | O34: ='表3-成本费用表'!O18*参数输入表!$H$413 -> 0 | ... AA34: ='表3-成本费用表'!AA18*参数输入表!$H$413 -> 0
B35: 3.2.4 | C35: 研发费用进项税 | D35: =SUM(F35:AA35) -> 0 | E35: 万元 | H35: 0 | I35: 0 | J35: 0 | K35: 0 | L35: 0 | M35: 0 | N35: 0 | O35: 0 | P35: 0 | Q35: 0 | R35: 0 | S35: 0 | T35: 0 | U35: 0 | V35: 0 | W35: 0 | X35: 0 | Y35: 0 | Z35: 0 | AA35: 0
B36: 3.3 | C36: 营业外支出进项税 | D36: =SUM(F36:AA36) -> 0 | E36: 万元 | H36: ='表3-成本费用表'!H62*参数输入表!$H$686 -> 0 | I36: ='表3-成本费用表'!I62*参数输入表!$H$686 -> 0 | J36: ='表3-成本费用表'!J62*参数输入表!$H$686 -> 0 | K36: ='表3-成本费用表'!K62*参数输入表!$H$686 -> 0 | L36: ='表3-成本费用表'!L62*参数输入表!$H$686 -> 0 | M36: ='表3-成本费用表'!M62*参数输入表!$H$686 -> 0 | N36: ='表3-成本费用表'!N62*参数输入表!$H$686 -> 0 | O36: ='表3-成本费用表'!O62*参数输入表!$H$686 -> 0 | ... AA36: ='表3-成本费用表'!AA62*参数输入表!$H$686 -> 0
B37: 3.4 | C37: 大修及更新重置进项税 | D37: =SUM(F37:AA37) -> 57.522124 | E37: 万元 | H37: =参数输入表!H656/(1+参数输入表!$H$679)*参数输入表!$H$679 -> 0 | I37: =参数输入表!H657/(1+参数输入表!$H$679)*参数输入表!$H$679 -> 0 | J37: =参数输入表!H658/(1+参数输入表!$H$679)*参数输入表!$H$679 -> 0 | K37: =参数输入表!H659/(1+参数输入表!$H$679)*参数输入表!$H$679 -> 0 | L37: =参数输入表!H660/(1+参数输入表!$H$679)*参数输入表!$H$679 -> 0 | M37: =参数输入表!H661/(1+参数输入表!$H$679)*参数输入表!$H$679 -> 0 | N37: =参数输入表!H662/(1+参数输入表!$H$679)*参数输入表!$H$679 -> 0 | O37: =参数输入表!H663/(1+参数输入表!$H$679)*参数输入表!$H$679 -> 0 | P37: =参数输入表!H664/(1+参数输入表!$H$679)*参数输入表!$H$679 -> 0 | Q37: =参数输入表!H665/(1+参数输入表!$H$679)*参数输入表!$H$679 -> 0 | R37: =参数输入表!H666/(1+参数输入表!$H$679)*参数输入表!$H$679 -> 0 | S37: =参数输入表!H667/(1+参数输入表!$H$679)*参数输入表!$H$679 -> 57.522124 | T37: =参数输入表!H668/(1+参数输入表!$H$679)*参数输入表!$H$679 -> 0 | U37: =参数输入表!H669/(1+参数输入表!$H$679)*参数输入表!$H$679 -> 0 | V37: =参数输入表!H670/(1+参数输入表!$H$679)*参数输入表!$H$679 -> 0 | W37: =参数输入表!H671/(1+参数输入表!$H$679)*参数输入表!$H$679 -> 0 | X37: =参数输入表!H672/(1+参数输入表!$H$679)*参数输入表!$H$679 -> 0 | Y37: =参数输入表!H673/(1+参数输入表!$H$679)*参数输入表!$H$679 -> 0 | Z37: =参数输入表!H674/(1+参数输入表!$H$679)*参数输入表!$H$679 -> 0 | AA37: =参数输入表!H675/(1+参数输入表!$H$679)*参数输入表!$H$679 -> 0
B38: 4 | C38: 销项税-进项税 | D38: =SUM(F38:AA38) -> 7094.9645 | E38: 万元 | F38: =F17-F20 -> -2674.206 | G38: =G17-G20 -> -1782.804 | H38: =H17-H20 -> 1042.2126 | I38: =I17-I20 -> 589.96261 | J38: =J17-J20 -> 590.54118 | K38: =K17-K20 -> 591.11811 | L38: =L17-L20 -> 591.69339 | M38: =M17-M20 -> 484.73947 | ... AA38: =AA17-AA20 -> 561.03158
B39: 5 | C39: 期末可抵扣进项税余额 | E39: 万元 | F39: =IF(F38<0,-F38,0) -> 2674.206 | G39: =IF(F39-G38>0,F39-G38,0) -> 4457.01 | H39: =IF(F39-H38>0,G39-H38,0) -> 3414.7974 | I39: =IF(H39-I38>0,H39-I38,0) -> 2824.8348 | J39: =IF(I39-J38>0,I39-J38,0) -> 2234.2936 | K39: =IF(J39-K38>0,J39-K38,0) -> 1643.1755 | L39: =IF(K39-L38>0,K39-L38,0) -> 1051.4822 | M39: =IF(L39-M38>0,L39-M38,0) -> 566.74268 | N39: =IF(M39-N38>0,M39-N38,0) -> 23.709258 | O39: =IF(N39-O38>0,N39-O38,0) -> 0 | P39: =IF(O39-P38>0,O39-P38,0) -> 0 | ... AA39: =IF(Z39-AA38>0,Z39-AA38,0) -> 0
B40: 6 | C40: 增值税附加税 | D40: =SUM(F40:AA40) -> 709.49645 | E40: 万元 | H40: =SUM(H41:H43) -> 0 | I40: =SUM(I41:I43) -> 0 | J40: =SUM(J41:J43) -> 0 | K40: =SUM(K41:K43) -> 0 | L40: =SUM(L41:L43) -> 0 | M40: =SUM(M41:M43) -> 0 | N40: =SUM(N41:N43) -> 0 | O40: =SUM(O41:O43) -> 52.100828 | ... AA40: =SUM(AA41:AA43) -> 56.103158
B41: 6.1 | C41: 城市维护建设税 | D41: =SUM(F41:AA41) -> 354.74823 | E41: 万元 | H41: =H16*参数输入表!$H$695 -> 0 | I41: =I16*参数输入表!$H$695 -> 0 | J41: =J16*参数输入表!$H$695 -> 0 | K41: =K16*参数输入表!$H$695 -> 0 | L41: =L16*参数输入表!$H$695 -> 0 | M41: =M16*参数输入表!$H$695 -> 0 | N41: =N16*参数输入表!$H$695 -> 0 | O41: =O16*参数输入表!$H$695 -> 26.050414 | ... AA41: =AA16*参数输入表!$H$695 -> 28.051579
B42: 6.2 | C42: 教育附加 | D42: =SUM(F42:AA42) -> 212.84894 | E42: 万元 | H42: =H16*参数输入表!$H$698 -> 0 | I42: =I16*参数输入表!$H$698 -> 0 | J42: =J16*参数输入表!$H$698 -> 0 | K42: =K16*参数输入表!$H$698 -> 0 | L42: =L16*参数输入表!$H$698 -> 0 | M42: =M16*参数输入表!$H$698 -> 0 | N42: =N16*参数输入表!$H$698 -> 0 | O42: =O16*参数输入表!$H$698 -> 15.630248 | ... AA42: =AA16*参数输入表!$H$698 -> 16.830947
...

Sheet 表5-利润表-资本金
B2: 利润表-资本金
B3: 序号 | C3: 项目 | D3: 合计 | E3: 单位 | F3: 建设期 | H3: 运营期
F4: 1 | G4: 2 | H4: 1 | I4: 2 | J4: 3 | K4: 4 | L4: 5 | M4: 6 | N4: 7 | O4: 8 | P4: 9 | Q4: 10 | R4: 11 | S4: 12 | T4: 13 | U4: 14 | V4: 15 | W4: 16 | X4: 17 | Y4: 18 | Z4: 19 | AA4: 20
B5: 1 | C5: 营业总收入 | D5: =SUM(F5:AA5) -> 373365.74 | E5: 万元 | H5: =H6+H7 -> 25177.721 | I5: =I6+I7 -> 17630.551 | J5: =J6+J7 -> 17630.551 | K5: =K6+K7 -> 17630.551 | L5: =L6+L7 -> 17630.551 | M5: =M6+M7 -> 17630.551 | N5: =N6+N7 -> 18573.947 | O5: =O6+O7 -> 18573.947 | ... AA5: =AA6+AA7 -> 18573.947
B6: 1.1 | C6: 营业收入 | D6: =SUM(F6:AA6) -> 373365.74 | E6: 万元 | H6: ='表4-收入税金表'!H6 -> 25177.721 | I6: ='表4-收入税金表'!I6 -> 17630.551 | J6: ='表4-收入税金表'!J6 -> 17630.551 | K6: ='表4-收入税金表'!K6 -> 17630.551 | L6: ='表4-收入税金表'!L6 -> 17630.551 | M6: ='表4-收入税金表'!M6 -> 17630.551 | N6: ='表4-收入税金表'!N6 -> 18573.947 | O6: ='表4-收入税金表'!O6 -> 18573.947 | ... AA6: ='表4-收入税金表'!AA6 -> 18573.947
B7: 1.2 | C7: 其他收入 | D7: =SUM(F7:AA7) -> 0 | E7: 万元 | H7: ='表4-收入税金表'!H10 -> 0 | I7: ='表4-收入税金表'!I10 -> 0 | J7: ='表4-收入税金表'!J10 -> 0 | K7: ='表4-收入税金表'!K10 -> 0 | L7: ='表4-收入税金表'!L10 -> 0 | M7: ='表4-收入税金表'!M10 -> 0 | N7: ='表4-收入税金表'!N10 -> 0 | O7: ='表4-收入税金表'!O10 -> 0 | ... AA7: ='表4-收入税金表'!AA10 -> 0
B8: 2 | C8: 营业总成本 | D8: =SUM(F8:AA8) -> 335351.07 | E8: 万元 | H8: ='表3-成本费用表'!H5 -> 18348.333 | I8: ='表3-成本费用表'!I49-'表3-成本费用表'!I53+'表3-成本费用表'!I15+'表3-成本费用表'!I16+'表3-成本费用表'!I19+'表3-成本费用表'!I20+'表2-折旧摊销表'!I52 -> 18218.572 | J8: ='表3-成本费用表'!J49-'表3-成本费用表'!J53+'表3-成本费用表'!J15+'表3-成本费用表'!J16+'表3-成本费用表'!J19+'表3-成本费用表'!J20+'表2-折旧摊销表'!J52 -> 18088.823 | K8: ='表3-成本费用表'!K49-'表3-成本费用表'!K53+'表3-成本费用表'!K15+'表3-成本费用表'!K16+'表3-成本费用表'!K19+'表3-成本费用表'!K20+'表2-折旧摊销表'!K52 -> 17959.087 | L8: ='表3-成本费用表'!L49-'表3-成本费用表'!L53+'表3-成本费用表'!L15+'表3-成本费用表'!L16+'表3-成本费用表'!L19+'表3-成本费用表'!L20+'表2-折旧摊销表'!L52 -> 17829.363 | M8: ='表3-成本费用表'!M49-'表3-成本费用表'!M53+'表3-成本费用表'!M15+'表3-成本费用表'!M16+'表3-成本费用表'!M19+'表3-成本费用表'!M20+'表2-折旧摊销表'!M52 -> 18526.787 | N8: ='表3-成本费用表'!N49-'表3-成本费用表'!N53+'表3-成本费用表'!N15+'表3-成本费用表'!N16+'表3-成本费用表'!N19+'表3-成本费用表'!N20+'表2-折旧摊销表'!N52 -> 18388.487 | O8: ='表3-成本费用表'!O49-'表3-成本费用表'!O53+'表3-成本费用表'!O15+'表3-成本费用表'!O16+'表3-成本费用表'!O19+'表3-成本费用表'!O20+'表2-折旧摊销表'!O52 -> 18250.234 | P8: ='表3-成本费用表'!P49-'表3-成本费用表'!P53+'表3-成本费用表'!P15+'表3-成本费用表'!P16+'表3-成本费用表'!P19+'表3-成本费用表'!P20+'表2-折旧摊销表'!P52 -> 18112.028 | ... AA8: ='表3-成本费用表'!AA49-'表3-成本费用表'!AA53+'表3-成本费用表'!AA15+'表3-成本费用表'!AA16+'表3-成本费用表'!AA19+'表3-成本费用表'!AA20+'表2-折旧摊销表'!AA52 -> 13942.513
B9: 3 | C9: 营业税金及附加 | D9: =SUM(F9:AA9) -> 709.49645 | E9: 万元 | H9: ='表4-收入税金表'!H40+'表4-收入税金表'!H44 -> 0 | I9: ='表4-收入税金表'!I40+'表4-收入税金表'!I44 -> 0 | J9: ='表4-收入税金表'!J40+'表4-收入税金表'!J44 -> 0 | K9: ='表4-收入税金表'!K40+'表4-收入税金表'!K44 -> 0 | L9: ='表4-收入税金表'!L40+'表4-收入税金表'!L44 -> 0 | M9: ='表4-收入税金表'!M40+'表4-收入税金表'!M44 -> 0 | N9: ='表4-收入税金表'!N40+'表4-收入税金表'!N44 -> 0 | O9: ='表4-收入税金表'!O40+'表4-收入税金表'!O44 -> 52.100828 | ... AA9: ='表4-收入税金表'!AA40+'表4-收入税金表'!AA44 -> 56.103158
B10: 4 | C10: 营业外收入 | D10: =SUM(F10:AA10) -> 0 | E10: 万元 | H10: =SUM(H11:H12) -> 0 | I10: =SUM(I11:I12) -> 0 | J10: =SUM(J11:J12) -> 0 | K10: =SUM(K11:K12) -> 0 | L10: =SUM(L11:L12) -> 0 | M10: =SUM(M11:M12) -> 0 | N10: =SUM(N11:N12) -> 0 | O10: =SUM(O11:O12) -> 0 | ... AA10: =SUM(AA11:AA12) -> 0
B11: 4.1 | C11: 政府一次性运营补贴收入—递延收益 | D11: =SUM(F11:AA11) -> 0 | E11: 万元 | H11: =参数输入表!H320 -> 0 | I11: =参数输入表!H321 -> 0 | J11: =参数输入表!H322 -> 0 | K11: =参数输入表!H323 -> 0 | L11: =参数输入表!H324 -> 0 | M11: =参数输入表!H325 -> 0 | N11: =参数输入表!H326 -> 0 | O11: =参数输入表!H327 -> 0 | P11: =参数输入表!H328 -> 0 | Q11: =参数输入表!H329 -> 0 | R11: =参数输入表!H330 -> 0 | S11: =参数输入表!H331 -> 0 | T11: =参数输入表!H332 -> 0 | U11: =参数输入表!H333 -> 0 | V11: =参数输入表!H334 -> 0 | W11: =参数输入表!H335 -> 0 | X11: =参数输入表!H336 -> 0 | Y11: =参数输入表!H337 -> 0 | Z11: =参数输入表!H338 -> 0 | AA11: =参数输入表!H339 -> 0
B12: 4.2 | C12: 增值税即征即退收入 | D12: =SUM(F12:AA12) -> 0 | E12: 万元 | H12: ='表4-收入税金表'!H13 -> 0 | I12: ='表4-收入税金表'!I13 -> 0 | J12: ='表4-收入税金表'!J13 -> 0 | K12: ='表4-收入税金表'!K13 -> 0 | L12: ='表4-收入税金表'!L13 -> 0 | M12: ='表4-收入税金表'!M13 -> 0 | N12: ='表4-收入税金表'!N13 -> 0 | O12: ='表4-收入税金表'!O13 -> 0 | ... AA12: ='表4-收入税金表'!AA13 -> 0
B13: 5 | C13: 营业外支出 | D13: =SUM(F13:AA13) -> 0 | E13: 万元 | H13: ='表3-成本费用表'!H24 -> 0 | I13: ='表3-成本费用表'!I24 -> 0 | J13: ='表3-成本费用表'!J24 -> 0 | K13: ='表3-成本费用表'!K24 -> 0 | L13: ='表3-成本费用表'!L24 -> 0 | M13: ='表3-成本费用表'!M24 -> 0 | N13: ='表3-成本费用表'!N24 -> 0 | O13: ='表3-成本费用表'!O24 -> 0 | ... AA13: ='表3-成本费用表'!AA24 -> 0
B14: 6 | C14: 利润总额（1+4-2-3-5） | D14: =SUM(F14:AA14) -> 37305.167 | E14: 万元 | H14: =H5+H10-H8-H9-H13 -> 6829.3875 | I14: =I5+I10-I8-I9-I13 -> -588.02062 | J14: =J5+J10-J8-J9-J13 -> -458.27173 | K14: =K5+K10-K8-K9-K13 -> -328.53556 | L14: =L5+L10-L8-L9-L13 -> -198.81204 | M14: =M5+M10-M8-M9-M13 -> -896.23614 | N14: =N5+N10-N8-N9-N13 -> 185.45973 | O14: =O5+O10-O8-O9-O13 -> 271.61192 | ... AA14: =AA5+AA10-AA8-AA9-AA13 -> 4575.3311
B15: 7 | C15: 弥补以前年度亏损 | D15: =SUM(F15:AA15) -> 1880.6554 | E15: 万元 | H15: =SUM(H16:H20) -> 0 | I15: =SUM(I16:I20) -> 0 | J15: =SUM(J16:J20) -> 0 | K15: =SUM(K16:K20) -> 0 | L15: =SUM(L16:L20) -> 0 | M15: =SUM(M16:M20) -> 0 | N15: =SUM(N16:N20) -> 185.45973 | O15: =SUM(O16:O20) -> 271.61192 | ... AA15: =SUM(AA16:AA20) -> 0
