Workbook

Sheet 说明
B2: 参数输入表中：
C3: 标黄项为相对固定模块
C4: 标绿项为对成本类、收入类数据进行分类，成本参数按照：“生产成本/销售费用/管理费用/研发费用”划分；收入参数按照：“营业收入/其他收入/营业外收入”划分
C5: 标橙项为固定的分类原则
C6: 标紫项为在参数表中不需要手动输入、勾选的内容，根据其他输入参数自动计算得出，可不在参数输入界面呈现。
C7: 标红项为引用同样红色sheet中相关数据
C8: 标蓝项为可不展示内容，大部分为中间过程计算表/中间计算过程
C10: 【成本费用表】、【收入税金表】、【利润表】体现的是会计报表相关数据，涉及到的收入及成本数据均为不含增值税金额，不含税金额计算公式为： 【含税金额/（1+增值税税率）】；增值税计算公式为：【不含税金额*增值税税率】或【含税金额/（1+增值税税率）*增值税税率】
C12: 【成本费用表】中各项成本按照：一、营业总成本：（1）生产成本；（2）销售费用；（3）管理费用；（4）研发费用；（5）财务费用；二、营业外支出，进行划分，其中需重点关注长期待摊费用成本项，在成本费用表中以逐年摊销的形式出现。
C14: 【成本费用表】中标蓝的内容为不展示内容，为中间计算表，其中数据均还原成含税金额，用于后续的【现金流量表】引用
C16: 【收入表】中各项收入按照：一、营业收入；二、其他收入；三、营业外收入，营业收入及营业外收入需展示二级目录（具体的收入项）
C18: 【现金流量表】体现的是公司账上实际收到或支付的现金流，因此涉及到的收入及成本数据均为含增值税金额，数据需引用成本费用表中还原后的含税金额或参数输入表中的含税金额。同时，收入数据需关注付款比例及回款期限的应用。原理为当年的部分比例收入的滞后支付，第一年的某项收入现金流为预测现金流*首年支付比例，第二年的某项收入现金流为：当年预测现金流*当年支付比例+上一年预测现金流*（1-上一年支付比例）
C20: 【现金流量表-财务计划】增加IF判定条件，当某年的累计盈余资金<“流动资金（本项目为960万元）”+次年的“生产经营现金支出合计（成本费用表标蓝表第一行）”，给出明显提示（允许用户在参数输入界面填写各年度短期借款当期借款金额及还本金额，再重新生成新的结果）

Sheet 可抵扣进项税
B2: 投资概算 | C2: 序号 | D2: 科目 | E2: 计取基数 | F2: 进项税率 | G2: 进项税
C3: 1 | D3: 设备购置费 | E3: =参数输入表!H69 -> 11947.39 | F3: =参数输入表!H288 -> 0.13 | G3: =E3/(1+F3)*F3 -> 1374.4785
C4: 2 | D4: 建安工程费 | E4: =参数输入表!H70 -> 6235.39 | F4: =参数输入表!H289 -> 0.09 | G4: =E4/(1+F4)*F4 -> 514.84872
C5: 3 | D5: 其他费用 | E5: =参数输入表!H71 -> 3024.1 | F5: =参数输入表!H290 -> 0.06 | G5: =E5/(1+F5)*F5 -> 171.17547
C6: 4 | D6: 预备费 | E6: =参数输入表!H72 -> 442.56 | F6: =参数输入表!H291 -> 0 | G6: =E6/(1+F6)*F6 -> 0
C7: 5 | D7: 储能投资 | E7: =参数输入表!H73 -> 920.92 | F7: =参数输入表!H292 -> 0.13 | G7: =E7/(1+F7)*F7 -> 105.94655
C8: 6 | D8: 送出线路投资 | E8: =参数输入表!H74 -> 1832 | F8: =参数输入表!H293 -> 0.09 | G8: =E8/(1+F8)*F8 -> 151.26606
C9: 7 | D9: 配套支持资金 | E9: =参数输入表!H75 -> 0 | F9: =参数输入表!H294 -> 0 | G9: =E9/(1+F9)*F9 -> 0
C10: 8 | D10: 静态总投资 | E10: =参数输入表!H76 -> 24402.36
C11: 9 | D11: 建设期利息 | E11: =参数输入表!H78 -> 350.1335
C12: 10 | D12: 动态总投资 | E12: =参数输入表!H79 -> 24752.494
C13: 11 | D13: 流动资金 | E13: =参数输入表!H81 -> 150
C14: 12 | D14: 可抵扣进项税 | E14: =SUM(G3:G9) -> 2317.7153
C18: 可抵扣进项税为后台计算，不需要作为成果展示

Sheet 参数输入表
G1: 【风储】财务评价计算模型边界条件输入参数表
B3: 类别 | C3: 序号 | D3: 参数 | E3: 操作类型 | F3: 收入/成本归类 | G3: 参数释义/计算公式 | H3: 数值 | I3: 单位 | J3: 取值说明 | K3: 备注
B4: 基础信息 | C4: 1 | D4: 建设期 | E4: 手动输入 | H4: 12 | I4: 月 | J4: 在初核阶段，不含升压站的集中式光伏项目建设期一般按5个月计算，含升压站的按7个月计算，大型基地项目根据实际情况调整。
C5: 2 | D5: 动工年月 | E5: 手动输入/下拉菜单选择【日历】 | I5: 年/月
C6: 3 | D6: 施工进度安排 | I6: %
D7: 建设期第1年 | E7: 手动输入 | H7: 1
D8: 建设期第2年 | E8: 手动输入
C9: 4 | D9: 运营期 | E9: 手动输入 | H9: 20 | I9: 年 | J9: 原则上按照20年考虑
C10: 5 | D10: 项目所在地 | E10: 下拉菜单选择 | J10: 判定是否属于西部地区
D11: 所在省份 | E11: 下拉菜单选择
D12: 所在市、县 | E12: 下拉菜单选择
B13: 生产相关 | D13: 实际装机容量 | E13: 手动输入 | H13: 50 | I13: MW | J13: 1MW=1000kW
D14: 储能额定功率 | E14: 手动输入 | H14: 10 | I14: MW
D15: 储能容量 | E15: 手动输入 | H15: 20 | I15: MWh
D16: 年均利用小时数 | E16: 手动输入 | H16: 2138.54 | I16: h
D17: 发电量 | E17: 自动计算 | G17: 各年上网电量=年利用小时数*实际装机容量 | H17: =H13*H16 -> 106927 | I17: MWh | J17: 年均
C18: 1 | D18: 上网电量 | G18: 各年上网电量=（（年利用小时数*实际装机容量）-数能融合消纳电量）*（1-限电率） | J18: 1MWh=0.1万度电
D19: 运营期第1年 | E19: 自动计算 | H19: =$H$17*(1-H45)*(1-$H$43) -> 50576.471 | I19: MWh
D20: 运营期第2年 | E20: 自动计算 | H20: =$H$17*(1-H46)*(1-$H$43) -> 50576.471 | I20: MWh
D21: 运营期第3年 | E21: 自动计算 | H21: =$H$17*(1-H47)*(1-$H$43) -> 50576.471 | I21: MWh
D22: 运营期第4年 | E22: 自动计算 | H22: =$H$17*(1-H48)*(1-$H$43) -> 50576.471 | I22: MWh
D23: 运营期第5年 | E23: 自动计算 | H23: =$H$17*(1-H49)*(1-$H$43) -> 50576.471 | I23: MWh
D24: 运营期第6年 | E24: 自动计算 | H24: =$H$17*(1-H50)*(1-$H$43) -> 30345.883 | I24: MWh
D25: 运营期第7年 | E25: 自动计算 | H25: =$H$17*(1-H51)*(1-$H$43) -> 30345.883 | I25: MWh
D26: 运营期第8年 | E26: 自动计算 | H26: =$H$17*(1-H52)*(1-$H$43) -> 30345.883 | I26: MWh
D27: 运营期第9年 | E27: 自动计算 | H27: =$H$17*(1-H53)*(1-$H$43) -> 30345.883 | I27: MWh
D28: 运营期第10年 | E28: 自动计算 | H28: =$H$17*(1-H54)*(1-$H$43) -> 30345.883 | I28: MWh
D29: 运营期第11年 | E29: 自动计算 | H29: =$H$17*(1-H55)*(1-$H$43) -> 30345.883 | I29: MWh
D30: 运营期第12年 | E30: 自动计算 | H30: =$H$17*(1-H56)*(1-$H$43) -> 30345.883 | I30: MWh
... D38: 运营期第20年 | E38: 自动计算 | H38: =$H$17*(1-H64)*(1-$H$43) -> 30345.883 | I38: MWh
D39: 上网电价
D40: 运营期第1年 | E40: 手动输入 | H40: 0.3044 | I40: 元/kWh
D41: …… | E41: 手动输入 | H41: 0.3044 | I41: 元/kWh
D42: 运营期第20年 | E42: 手动输入 | H42: 0.3044 | I42: 元/kWh
D43: 限电率 | E43: 手动输入 | H43: 0.054 | I43: %
C44: 2 | D44: 数能融合消纳风电电量占比
D45: 运营期第1年 | E45: 手动输入 | H45: 0.5 | I45: %
D46: 运营期第2年 | E46: 手动输入 | H46: 0.5 | I46: %
D47: 运营期第3年 | E47: 手动输入 | H47: 0.5 | I47: %
D48: 运营期第4年 | E48: 手动输入 | H48: 0.5 | I48: %
...

Sheet 表1-资金筹措及还本付息表
B2: 资金筹措表
B3: 序号 | C3: 建设期 | D3: 合计 | E3: 单位 | F3: 建设期 | H3: 运营期
F4: 1 | G4: 2 | H4: 1 | I4: 2 | J4: 3 | K4: 4 | L4: 5 | M4: 6 | N4: 7 | O4: 8 | P4: 9 | Q4: 10 | R4: 11 | S4: 12 | T4: 13 | U4: 14 | V4: 15 | W4: 16 | X4: 17 | Y4: 18 | Z4: 19 | AA4: 20
C5: 施工进度安排 | D5: =SUM(F5:M5) -> 1 | F5: =参数输入表!H7 -> 1 | G5: =参数输入表!H8 -> 0
B6: 1 | C6: 动态总投资（自主投资） | D6: =D7+D8+D9 -> 24902.494 | E6: 万元 | F6: =SUM(F7:F9) -> 24752.494 | G6: =SUM(G7:G9) -> 0 | H6: =SUM(H7:H9) -> 150
B7: 1.1 | C7: 静态总投资（自主投资） | D7: =SUM(F7:AA7) -> 24402.36 | E7: 万元 | F7: =参数输入表!$H$77*F5 -> 24402.36 | G7: =参数输入表!$H$77*G5 -> 0 | H7: 0
B8: 1.2 | C8: 建设期利息 | D8: =SUM(F8:AA8) -> 350.1335 | E8: 万元 | F8: =F17 -> 350.1335 | G8: =G17 -> 0 | H8: =H17 -> 0
B9: 1.3 | C9: 流动资金 | D9: =SUM(F9:AA9) -> 150 | E9: 万元 | F9: 0 | G9: 0 | H9: =参数输入表!H81 -> 150
B10: 2 | C10: 资金来源
B11: 2.1 | C11: 资本金 | D11: =SUM(F11:AA11) -> 4995.4987 | E11: 万元 | F11: =F6*参数输入表!$H$85 -> 4950.4987 | G11: =G6*参数输入表!$H$85 -> 0 | H11: =H6*参数输入表!$H$93 -> 45
B12: 2.1.1 | C12: 用于建设投资 | D12: =SUM(F12:AA12) -> 4950.4987 | E12: 万元 | F12: =F11-F13-F14 -> 4950.4987 | G12: =G11-G13-G14 -> 0 | H12: 0
B13: 2.1.2 | C13: 用于建设期利息 | D13: =SUM(F13:AA13) -> 0 | E13: 万元 | F13: 0 | G13: 0 | H13: 0
B14: 2.1.3 | C14: 用于流动资金 | D14: =SUM(F14:AA14) -> 45 | F14: 0 | G14: 0 | H14: =H9*参数输入表!H93 -> 45
B15: 2.2 | C15: 债务资金 | D15: =SUM(F15:M15) -> 19906.995 | E15: 万元 | F15: =SUM(F16:F18) -> 19801.995 | G15: =SUM(G16:G18) -> 0 | H15: =SUM(H16:H18) -> 105
B16: 2.2.1 | C16: 用于建设投资 | D16: =SUM(F16:AA16) -> 19451.861 | E16: 万元 | F16: =F7-F12 -> 19451.861 | G16: =G7-G12 -> 0 | H16: =H7-H12 -> 0
B17: 2.1.2 | C17: 用于建设期利息 | D17: =SUM(F17:AA17) -> 350.1335 | E17: 万元 | F17: =F16/2*参数输入表!$H$88*(参数输入表!H4/12) -> 350.1335 | G17: =IF(G5>0,((G16/2+F15)*参数输入表!$H$88),0) -> 0 | H17: 0
B18: 2.1.3 | C18: 用于流动资金 | D18: =SUM(F18:AA18) -> 105 | E18: 万元 | F18: 0 | G18: 0 | H18: =H9-H14 -> 105
B20: 营运资本变动
B21: 序号 | C21: 项目 | D21: 合计 | E21: 单位 | F21: 建设期 | H21: 运营期
F22: 1 | G22: 2 | H22: 1 | I22: 2 | J22: 3 | K22: 4 | L22: 5 | M22: 6 | N22: 7 | O22: 8 | P22: 9 | Q22: 10 | R22: 11 | S22: 12 | T22: 13 | U22: 14 | V22: 15 | W22: 16 | X22: 17 | Y22: 18 | Z22: 19 | AA22: 20
B23: 1 | C23: 流动资产 | D23: =SUM(F23:AA23) -> 126032.64 | E23: 万元 | F23: =SUM(F24:F27) -> 2317.7153 | G23: =SUM(G24:G27) -> 2317.7153 | H23: =SUM(H24:H27) -> 2581.26 | I23: =SUM(I24:I27) -> 2873.5605 | J23: =SUM(J24:J27) -> 3192.2166 | K23: =SUM(K24:K27) -> 3498.4989 | L23: =SUM(L24:L27) -> 3824.8812 | M23: =SUM(M24:M27) -> 4099.9845 | ... AA23: =SUM(AA24:AA27) -> 11912.077
C24: 货币资金 | D24: =SUM(F24:AA24) -> 115088.24 | E24: 万元 | F24: ='表9-现金流量表-财务计划'!F34 -> 0 | G24: ='表9-现金流量表-财务计划'!G34 -> 0 | H24: ='表9-现金流量表-财务计划'!H34 -> 625.18088 | I24: ='表9-现金流量表-财务计划'!I34 -> 1279.1176 | J24: ='表9-现金流量表-财务计划'!J34 -> 1959.4098 | K24: ='表9-现金流量表-财务计划'!K34 -> 2627.3282 | L24: ='表9-现金流量表-财务计划'!L34 -> 3315.3467 | M24: ='表9-现金流量表-财务计划'!M34 -> 3955.0477 | ... AA24: ='表9-现金流量表-财务计划'!AA34 -> 11912.077
C25: 应收账款 | D25: =SUM(F25:AA25) -> 0 | E25: 万元 | H25: ='表4-收入税金表'!H60 -> 0 | I25: ='表4-收入税金表'!I60 -> 0 | J25: ='表4-收入税金表'!J60 -> 0 | K25: ='表4-收入税金表'!K60 -> 0 | L25: ='表4-收入税金表'!L60 -> 0 | M25: ='表4-收入税金表'!M60 -> 0 | N25: ='表4-收入税金表'!N60 -> 0 | O25: ='表4-收入税金表'!O60 -> 0 | ... AA25: ='表4-收入税金表'!AA60 -> 0
C26: 存货 | D26: =SUM(F26:AA26) -> 0 | E26: 万元
C27: 其他流动资产（留抵税额） | D27: =SUM(F27:AA27) -> 10944.401 | E27: 万元 | F27: ='表4-收入税金表'!F45 -> 2317.7153 | G27: ='表4-收入税金表'!G45 -> 2317.7153 | H27: ='表4-收入税金表'!H45 -> 1956.0791 | I27: ='表4-收入税金表'!I45 -> 1594.443 | J27: ='表4-收入税金表'!J45 -> 1232.8068 | K27: ='表4-收入税金表'!K45 -> 871.17065 | L27: ='表4-收入税金表'!L45 -> 509.53449 | M27: ='表4-收入税金表'!M45 -> 144.93675 | ... AA27: ='表4-收入税金表'!AA45 -> 0
B28: 2 | C28: 流动负债 | D28: =SUM(F28:AA28) -> 17802.258 | E28: 万元 | F28: =SUM(F29:F34) -> 0 | G28: =SUM(G29:G34) -> 0 | H28: =SUM(H29:H34) -> 255.50193 | I28: =SUM(I29:I34) -> 169.2709 | J28: =SUM(J29:J34) -> 190.4402 | K28: =SUM(K29:K34) -> 250.33869 | L28: =SUM(L29:L34) -> 277.76348 | M28: =SUM(M29:M34) -> 288.92538 | ... AA28: =SUM(AA29:AA34) -> 1829.4912
C29: 短期借款 | D29: =SUM(F29:AA29) -> 105 | E29: 万元 | F29: =F64+F74 -> 0 | G29: =G60+G70 -> 0 | H29: =H60+H70 -> 105 | I29: =I60+I70 -> 0 | J29: =J60+J70 -> 0 | K29: =K60+K70 -> 0 | L29: =L60+L70 -> 0 | M29: =M60+M70 -> 0 | N29: =N60+N70 -> 0 | ... AA29: =AA60+AA70 -> 0
C30: 预收款项 | D30: =SUM(F30:AA30) -> 0 | E30: 万元
C31: 应付职工薪酬 | D31: =SUM(F31:AA31) -> 2688 | E31: 万元 | H31: ='表3-成本费用表'!H52 -> 134.4 | I31: ='表3-成本费用表'!I52 -> 134.4 | J31: ='表3-成本费用表'!J52 -> 134.4 | K31: ='表3-成本费用表'!K52 -> 134.4 | L31: ='表3-成本费用表'!L52 -> 134.4 | M31: ='表3-成本费用表'!M52 -> 134.4 | N31: ='表3-成本费用表'!N52 -> 134.4 | O31: ='表3-成本费用表'!O52 -> 134.4 | ... AA31: ='表3-成本费用表'!AA52 -> 134.4
C32: 应交税费 | D32: =SUM(F32:AA32) -> 9626.9904 | E32: 万元 | H32: ='表6-现金流量表-资本金'!H24+'表6-现金流量表-资本金'!H25+'表6-现金流量表-资本金'!H29 -> 0 | I32: ='表6-现金流量表-资本金'!I24+'表6-现金流量表-资本金'!I25+'表6-现金流量表-资本金'!I29 -> 0 | J32: ='表6-现金流量表-资本金'!J24+'表6-现金流量表-资本金'!J25+'表6-现金流量表-资本金'!J29 -> 0 | K32: ='表6-现金流量表-资本金'!K24+'表6-现金流量表-资本金'!K25+'表6-现金流量表-资本金'!K29 -> 40.185589 | L32: ='表6-现金流量表-资本金'!L24+'表6-现金流量表-资本金'!L25+'表6-现金流量表-资本金'!L29 -> 46.126187 | M32: ='表6-现金流量表-资本金'!M24+'表6-现金流量表-资本金'!M25+'表6-现金流量表-资本金'!M29 -> 41.111547 | N32: ='表6-现金流量表-资本金'!N24+'表6-现金流量表-资本金'!N25+'表6-现金流量表-资本金'!N29 -> 360.99238 | O32: ='表6-现金流量表-资本金'!O24+'表6-现金流量表-资本金'!O25+'表6-现金流量表-资本金'!O29 -> 548.97173 | ... AA32: ='表6-现金流量表-资本金'!AA24+'表6-现金流量表-资本金'!AA25+'表6-现金流量表-资本金'!AA29 -> 933.93852
C33: 应付股利 | D33: =SUM(F33:AA33) -> 5382.2673 | E33: 万元 | H33: ='表5-利润表-资本金'!H31 -> 16.101931 | I33: ='表5-利润表-资本金'!I31 -> 34.8709 | J33: ='表5-利润表-资本金'!J31 -> 56.040203 | K33: ='表5-利润表-资本金'!K31 -> 75.753104 | L33: ='表5-利润表-资本金'!L31 -> 97.237292 | M33: ='表5-利润表-资本金'!M31 -> 113.41384 | N33: ='表5-利润表-资本金'!N31 -> 133.11492 | O33: ='表5-利润表-资本金'!O31 -> 157.77144 | ... AA33: ='表5-利润表-资本金'!AA31 -> 761.15263
C34: 其他流动负债 | D34: =SUM(F34:AA34) -> 0 | E34: 万元
B36: 借款还本付息表（长期借款）
B37: 序号 | C37: 项目 | D37: 合计 | E37: 单位 | F37: 建设期 | H37: 运营期
F38: 1 | G38: 2 | H38: 1 | I38: 2 | J38: 3 | K38: 4 | L38: 5 | M38: 6 | N38: 7 | O38: 8 | P38: 9 | Q38: 10 | R38: 11 | S38: 12 | T38: 13 | U38: 14 | V38: 15 | W38: 16 | X38: 17 | Y38: 18 | Z38: 19 | AA38: 20
B39: 1 | C39: 期初借款累计 | E39: 万元 | F39: 0 | G39: =F44 -> 19801.995 | H39: =G44 -> 19801.995 | I39: =H44 -> 18783.307 | J39: =I44 -> 17727.946 | K39: =J44 -> 16634.593 | L39: =K44 -> 15501.878 | M39: =L44 -> 14328.386 | N39: =M44 -> 13112.649 | ... AA39: =Z44 -> 0
B40: 2 | C40: 当期借款 | D40: =SUM(F40:AA40) -> 19801.995 | E40: 万元 | F40: =F15 -> 19801.995 | G40: =G15 -> 0
B41: 3 | C41: 当期还本付息 | D41: =SUM(F41:AA41) -> 25973.395 | E41: 万元 | H41: =-PMT(参数输入表!$H$89,参数输入表!$H$92,'表1-资金筹措及还本付息表'!$D$40) -> 1731.5597 | I41: =-PMT(参数输入表!$H$89,参数输入表!$H$92,'表1-资金筹措及还本付息表'!$D$40) -> 1731.5597 | J41: =-PMT(参数输入表!$H$89,参数输入表!$H$92,'表1-资金筹措及还本付息表'!$D$40) -> 1731.5597 | K41: =-PMT(参数输入表!$H$89,参数输入表!$H$92,'表1-资金筹措及还本付息表'!$D$40) -> 1731.5597 | L41: =-PMT(参数输入表!$H$89,参数输入表!$H$92,'表1-资金筹措及还本付息表'!$D$40) -> 1731.5597 | M41: =-PMT(参数输入表!$H$89,参数输入表!$H$92,'表1-资金筹措及还本付息表'!$D$40) -> 1731.5597 | N41: =-PMT(参数输入表!$H$89,参数输入表!$H$92,'表1-资金筹措及还本付息表'!$D$40) -> 1731.5597 | O41: =-PMT(参数输入表!$H$89,参数输入表!$H$92,'表1-资金筹措及还本付息表'!$D$40) -> 1731.5597 | ... V41: =-PMT(参数输入表!$H$89,参数输入表!$H$92,'表1-资金筹措及还本付息表'!$D$40) -> 1731.5597
C42: 其中：还本（等额本息） | D42: =SUM(F42:AA42) -> 19801.995 | E42: 万元 | H42: =H41-H43 -> 1018.6879 | I42: =I41-I43 -> 1055.3606 | J42: =J41-J43 -> 1093.3536 | K42: =K41-K43 -> 1132.7143 | L42: =L41-L43 -> 1173.4921 | M42: =M41-M43 -> 1215.7378 | N42: =N41-N43 -> 1259.5043 | O42: =O41-O43 -> 1304.8465 | ... V42: =V41-V43 -> 1671.3897
C43: 付息 | D43: =SUM(F43:AA43) -> 6171.4004 | E43: 万元 | H43: =(H39+H40/2)*参数输入表!$H$89 -> 712.87181 | I43: =(I39+I40/2)*参数输入表!$H$89 -> 676.19905 | J43: =(J39+J40/2)*参数输入表!$H$89 -> 638.20607 | K43: =(K39+K40/2)*参数输入表!$H$89 -> 598.84534 | L43: =(L39+L40/2)*参数输入表!$H$89 -> 558.06762 | M43: =(M39+M40/2)*参数输入表!$H$89 -> 515.82191 | N43: =(N39+N40/2)*参数输入表!$H$89 -> 472.05535 | O43: =(O39+O40/2)*参数输入表!$H$89 -> 426.71319 | ... V43: =(V39+V40/2)*参数输入表!$H$89 -> 60.170027
...

Sheet 表2-折旧摊销表
C1: 中间过程引用（隐藏）
C2: 动态总投资（自主投资_不含流动资金） | D2: =参数输入表!H80 -> 24752.494
C3: 可抵扣进项税 | D3: =参数输入表!H83 -> 2317.7153
C4: 固定资产原值 | D4: =D2-D15-D3 -> 22434.778 | F4: 固定资产原值=项目动态总投资（自主投资_不含流动资金）-可抵扣进项税-无形资产原值=项目静态总投资-建设补贴+建设期利息-可抵扣进项税-无形资产原值
C5: 折旧方式 | D5: 直线法/其他
C6: 折旧年限 | D6: =参数输入表!H151 -> 15
C7: 残值率 | D7: =参数输入表!H152 -> 0.05
C8: 长期待摊费用（第1年） | D8: =参数输入表!H160/(1+参数输入表!H182) -> 0 | F8: 长期待摊费用=计入长期待摊的成本项/（1+增值税税率）
C9: 长期待摊费用（第6年） | D9: =参数输入表!H165/(1+参数输入表!H182) -> 0
C10: 长期待摊费用（第11年） | D10: =参数输入表!H170/(1+参数输入表!H182) -> 0
C11: 长期待摊费用（第16年） | D11: =参数输入表!H175/(1+参数输入表!H182) -> 0
C13: 摊销方式 | D13: 直线法/其他
C14: 摊销年限 | D14: =参数输入表!H181 -> 5
C15: 无形资产原值 | D15: =参数输入表!H154 -> 0
C16: 摊销方式 | D16: 直线法/其他
C17: 摊销年限 | D17: =参数输入表!H156 -> 10 | F17: 建设期 | H17: 运营期
C18: 残值率 | D18: =参数输入表!H157 -> 0 | F18: 1 | G18: 2 | H18: 1 | I18: 2 | J18: 3 | K18: 4 | L18: 5 | M18: 6 | N18: 7 | O18: 8 | P18: 9 | Q18: 10 | R18: 11 | S18: 12 | T18: 13 | U18: 14 | V18: 15 | W18: 16 | X18: 17 | Y18: 18 | Z18: 19 | AA18: 20
C19: 大修及更新重置资产原值
C20: 摊销方式 | D20: 直线法/其他 | H20: =参数输入表!H185 -> 0 | I20: =参数输入表!H186 -> 0 | J20: =参数输入表!H187 -> 0 | K20: =参数输入表!H188 -> 0 | L20: =参数输入表!H189 -> 0 | M20: =参数输入表!H190 -> 0 | N20: =参数输入表!H191 -> 0 | O20: =参数输入表!H192 -> 0 | P20: =参数输入表!H193 -> 0 | Q20: =参数输入表!H194 -> 0 | R20: =参数输入表!H195 -> 480 | S20: =参数输入表!H196 -> 0 | T20: =参数输入表!H197 -> 0 | U20: =参数输入表!H198 -> 0 | V20: =参数输入表!H199 -> 0 | W20: =参数输入表!H200 -> 0 | X20: =参数输入表!H201 -> 0 | Y20: =参数输入表!H202 -> 0 | Z20: =参数输入表!H203 -> 0 | AA20: =参数输入表!H204 -> 0
C21: 摊销年限 | D21: =参数输入表!H206 -> 10
C22: 残值率 | D22: =参数输入表!H207 -> 0.05
B23: 折旧摊销表-资本金
B24: 序号 | C24: 科目 | D24: 合计 | E24: 单位 | F24: 建设期 | H24: 运营期
F25: 1 | G25: 2 | H25: 1 | I25: 2 | J25: 3 | K25: 4 | L25: 5 | M25: 6 | N25: 7 | O25: 8 | P25: 9 | Q25: 10 | R25: 11 | S25: 12 | T25: 13 | U25: 14 | V25: 15 | W25: 16 | X25: 17 | Y25: 18 | Z25: 19 | AA25: 20
B26: 1 | C26: 固定资产净值 | E26: 万元 | F26: =D27 -> 21313.039 | H26: =IF('表1-资金筹措及还本付息表'!G5=0,F26-H27,G26-H27) -> 19892.17 | I26: =H26-I27 -> 18471.301 | J26: =I26-J27 -> 17050.431 | K26: =J26-K27 -> 15629.562 | L26: =K26-L27 -> 14208.693 | M26: =L26-M27 -> 12787.824 | N26: =M26-N27 -> 11366.954 | O26: =N26-O27 -> 9946.085 | P26: =O26-P27 -> 8525.2157 | ... AA26: =Z26-AA27 -> 2.2737368e-12
C27: 当期固定资产折旧 | D27: =SUM(F27:AA27) -> 21313.039 | E27: 万元 | H27: =IF(H25<=$D$6,$D$4*(1-$D$7)/($D$6),0) -> 1420.8693 | I27: =IF(I25<=$D$6,$D$4*(1-$D$7)/($D$6),0) -> 1420.8693 | J27: =IF(J25<=$D$6,$D$4*(1-$D$7)/($D$6),0) -> 1420.8693 | K27: =IF(K25<=$D$6,$D$4*(1-$D$7)/($D$6),0) -> 1420.8693 | L27: =IF(L25<=$D$6,$D$4*(1-$D$7)/($D$6),0) -> 1420.8693 | M27: =IF(M25<=$D$6,$D$4*(1-$D$7)/($D$6),0) -> 1420.8693 | N27: =IF(N25<=$D$6,$D$4*(1-$D$7)/($D$6),0) -> 1420.8693 | O27: =IF(O25<=$D$6,$D$4*(1-$D$7)/($D$6),0) -> 1420.8693 | ... AA27: =IF(AA25<=$D$6,$D$4*(1-$D$7)/($D$6),0) -> 0
B28: 2 | C28: 期初长期待摊费用 | E28: 万元 | H28: 0 | I28: =H31 -> 0 | J28: =I31 -> 0 | K28: =J31 -> 0 | L28: =K31 -> 0 | M28: =L31 -> 0 | N28: =M31 -> 0 | O28: =N31 -> 0 | P28: =O31 -> 0 | ... AA28: =Z31 -> 0
C29: 当期新增长期待摊费用 | H29: =参数输入表!H160/(1+参数输入表!H182) -> 0 | I29: =参数输入表!H161/(1+参数输入表!H182) -> 0 | J29: =参数输入表!H162/(1+参数输入表!H182) -> 0 | K29: =参数输入表!H163/(1+参数输入表!H182) -> 0 | L29: =参数输入表!H164/(1+参数输入表!H182) -> 0 | M29: =参数输入表!H165/(1+参数输入表!H182) -> 0 | N29: =参数输入表!H166/(1+参数输入表!H182) -> 0 | O29: =参数输入表!H167/(1+参数输入表!H182) -> 0 | P29: =参数输入表!H168/(1+参数输入表!H182) -> 0 | Q29: =参数输入表!H169/(1+参数输入表!H182) -> 0 | R29: =参数输入表!H170/(1+参数输入表!H182) -> 0 | S29: =参数输入表!H171/(1+参数输入表!H182) -> 0 | T29: =参数输入表!H172/(1+参数输入表!H182) -> 0 | U29: =参数输入表!H173/(1+参数输入表!H182) -> 0 | V29: =参数输入表!H174/(1+参数输入表!H182) -> 0 | W29: =参数输入表!H175/(1+参数输入表!H182) -> 0 | X29: =参数输入表!H176/(1+参数输入表!H182) -> 0 | Y29: =参数输入表!H177/(1+参数输入表!H182) -> 0 | Z29: =参数输入表!H178/(1+参数输入表!H182) -> 0 | AA29: =参数输入表!H179/(1+参数输入表!H182) -> 0
C30: 当期摊销 | D30: =SUM(F30:AA30) -> 0 | E30: 万元 | H30: =H29/$D$14 -> 0 | I30: =H30 -> 0 | J30: =I30 -> 0 | K30: =J30 -> 0 | L30: =K30 -> 0 | M30: =M29/$D$14 -> 0 | N30: =M30 -> 0 | O30: =N30 -> 0 | P30: =O30 -> 0 | Q30: =P30 -> 0 | R30: =R29/$D$14 -> 0 | S30: =R30 -> 0 | T30: =S30 -> 0 | U30: =T30 -> 0 | V30: =U30 -> 0 | W30: =W29/$D$14 -> 0 | X30: =W30 -> 0 | Y30: =X30 -> 0 | Z30: =Y30 -> 0 | AA30: =Z30 -> 0
C31: 期末期初长期待摊费用 | H31: =H28+H29-H30 -> 0 | I31: =I28+I29-I30 -> 0 | J31: =J28+J29-J30 -> 0 | K31: =K28+K29-K30 -> 0 | L31: =L28+L29-L30 -> 0 | M31: =M28+M29-M30 -> 0 | N31: =N28+N29-N30 -> 0 | O31: =O28+O29-O30 -> 0 | ... AA31: =AA28+AA29-AA30 -> 0
B32: 3 | C32: 无形资产净值 | E32: 万元 | F32: =参数输入表!$H$154*参数输入表!$H$7 -> 0 | G32: =参数输入表!$H$154*参数输入表!$H$7+参数输入表!$H$154*参数输入表!$H$8 -> 0 | H32: =G32-H33 -> 0 | I32: =H32-I33 -> 0 | J32: =I32-J33 -> 0 | K32: =J32-K33 -> 0 | L32: =K32-L33 -> 0 | M32: =L32-M33 -> 0 | N32: =M32-N33 -> 0 | O32: =N32-O33 -> 0 | ... AA32: =Z32-AA33 -> 0
C33: 当期无形资产摊销 | D33: =SUM(F33:AA33) -> 0 | E33: 万元 | H33: =IF(H25<=$D$17,G32*(1-$D$18)/($D$17-H25+1),0) -> 0 | I33: =IF(I25<=$D$17,H32*(1-$D$18)/($D$17-I25+1),0) -> 0 | J33: =IF(J25<=$D$17,I32*(1-$D$18)/($D$17-J25+1),0) -> 0 | K33: =IF(K25<=$D$17,J32*(1-$D$18)/($D$17-K25+1),0) -> 0 | L33: =IF(L25<=$D$17,K32*(1-$D$18)/($D$17-L25+1),0) -> 0 | M33: =IF(M25<=$D$17,L32*(1-$D$18)/($D$17-M25+1),0) -> 0 | N33: =IF(N25<=$D$17,M32*(1-$D$18)/($D$17-N25+1),0) -> 0 | O33: =IF(O25<=$D$17,N32*(1-$D$18)/($D$17-O25+1),0) -> 0 | ... AA33: =IF(AA25<=$D$17,Z32*(1-$D$18)/($D$17-AA25+1),0) -> 0
B34: 4 | C34: 期初大修及更新重置资产净值 | E34: 万元 | H34: 0 | I34: =H37 -> 0 | J34: =I37 -> 0 | K34: =J37 -> 0 | L34: =K37 -> 0 | M34: =L37 -> 0 | N34: =M37 -> 0 | O34: =N37 -> 0 | P34: =O37 -> 0 | ... AA34: =Z37 -> 61.59292
C35: 当期新增大修及更新重置资产 | H35: =参数输入表!H185/(1+参数输入表!$H$208) -> 0 | I35: =参数输入表!H186/(1+参数输入表!$H$208) -> 0 | J35: =参数输入表!H187/(1+参数输入表!$H$208) -> 0 | K35: =参数输入表!H188/(1+参数输入表!$H$208) -> 0 | L35: =参数输入表!H189/(1+参数输入表!$H$208) -> 0 | M35: =参数输入表!H190/(1+参数输入表!$H$208) -> 0 | N35: =参数输入表!H191/(1+参数输入表!$H$208) -> 0 | O35: =参数输入表!H192/(1+参数输入表!$H$208) -> 0 | P35: =参数输入表!H193/(1+参数输入表!$H$208) -> 0 | Q35: =参数输入表!H194/(1+参数输入表!$H$208) -> 0 | R35: =参数输入表!H195/(1+参数输入表!$H$208) -> 424.77876 | S35: =参数输入表!H196/(1+参数输入表!$H$208) -> 0 | T35: =参数输入表!H197/(1+参数输入表!$H$208) -> 0 | U35: =参数输入表!H198/(1+参数输入表!$H$208) -> 0 | V35: =参数输入表!H199/(1+参数输入表!$H$208) -> 0 | W35: =参数输入表!H200/(1+参数输入表!$H$208) -> 0 | X35: =参数输入表!H201/(1+参数输入表!$H$208) -> 0 | Y35: =参数输入表!H202/(1+参数输入表!$H$208) -> 0 | Z35: =参数输入表!H203/(1+参数输入表!$H$208) -> 0 | AA35: =参数输入表!H204/(1+参数输入表!$H$208) -> 0
C36: 当期大修及更新重置资产折旧摊销 | D36: =SUM(F36:AA36) -> 403.53982 | E36: 万元 | H36: 0 | I36: 0 | J36: 0 | K36: 0 | L36: 0 | M36: 0 | N36: 0 | O36: 0 | P36: 0 | Q36: =Q35/D21 -> 0 | R36: =R35*(1-$D$22)/D21 -> 40.353982 | S36: =R36 -> 40.353982 | T36: =S36 -> 40.353982 | U36: =T36 -> 40.353982 | V36: =U36 -> 40.353982 | W36: =V36 -> 40.353982 | X36: =W36 -> 40.353982 | Y36: =X36 -> 40.353982 | Z36: =Y36 -> 40.353982 | AA36: =Z36 -> 40.353982
C37: 期末大修及更新重置资产净值 | H37: =H34+H35-H36 -> 0 | I37: =I34+I35-I36 -> 0 | J37: =J34+J35-J36 -> 0 | K37: =K34+K35-K36 -> 0 | L37: =L34+L35-L36 -> 0 | M37: =M34+M35-M36 -> 0 | N37: =N34+N35-N36 -> 0 | O37: =O34+O35-O36 -> 0 | ... AA37: =AA34+AA35-AA36 -> 21.238938
B38: 5 | C38: 当期折旧摊销 | D38: =SUM(F38:AA38) -> 21716.579 | E38: 万元 | F38: =F27+F30+F33+F36 -> 0 | G38: =G27+G30+G33+G36 -> 0 | H38: =H27+H30+H33+H36 -> 1420.8693 | I38: =I27+I30+I33+I36 -> 1420.8693 | J38: =J27+J30+J33+J36 -> 1420.8693 | K38: =K27+K30+K33+K36 -> 1420.8693 | L38: =L27+L30+L33+L36 -> 1420.8693 | M38: =M27+M30+M33+M36 -> 1420.8693 | ... AA38: =AA27+AA30+AA33+AA36 -> 40.353982
C41: 上述为“直线法”下折旧摊销计算，若在参数输入表中下拉菜单选择为“其他”，设置为手动输入各年份折旧额/摊销额
C43: 中间过程引用（隐藏）
C44: 静态总投资（自主投资） | D44: =D2 -> 24752.494
...

Sheet 表3-成本费用表
B2: 成本费用表-资本金
B3: 序号 | C3: 项目 | D3: 合计 | E3: 单位 | F3: 建设期 | H3: 运营期
F4: 1 | G4: 2 | H4: 1 | I4: 2 | J4: 3 | K4: 4 | L4: 5 | M4: 6 | N4: 7 | O4: 8 | P4: 9 | Q4: 10 | R4: 11 | S4: 12 | T4: 13 | U4: 14 | V4: 15 | W4: 16 | X4: 17 | Y4: 18 | Z4: 19 | AA4: 20
B5: 一 | C5: 营业总成本 | D5: =SUM(F5:AA5) -> 40115.554 | E5: 万元 | H5: =H6+H15+H16+H19+H20 -> 2602.9063 | I5: =I6+I15+I16+I19+I20 -> 2555.3815 | J5: =J6+J15+J16+J19+J20 -> 2507.8567 | K5: =K6+K15+K16+K19+K20 -> 2460.3319 | L5: =L6+L15+L16+L19+L20 -> 2412.8071 | M5: =M6+M15+M16+M19+M20 -> 2475.7056 | N5: =N6+N15+N16+N19+N20 -> 2428.1808 | O5: =O6+O15+O16+O19+O20 -> 2380.656 | ... AA5: =AA6+AA15+AA16+AA19+AA20 -> 840.78882
B6: 1 | C6: 生产成本 | D6: =SUM(F6:AA6) -> 33225.74 | H6: =SUM(H7:H14) -> 1830.6925 | I6: =SUM(I7:I14) -> 1830.6925 | J6: =SUM(J7:J14) -> 1830.6925 | K6: =SUM(K7:K14) -> 1830.6925 | L6: =SUM(L7:L14) -> 1830.6925 | M6: =SUM(M7:M14) -> 1941.1157 | N6: =SUM(N7:N14) -> 1941.1157 | O6: =SUM(O7:O14) -> 1941.1157 | ... AA6: =SUM(AA7:AA14) -> 781.44688
B7: 1.1 | C7: 材料费 | D7: =SUM(F7:AA7) -> 1800 | E7: 万元 | H7: =参数输入表!$H$104*参数输入表!$H$13/(1+参数输入表!$H$108) -> 90 | I7: =参数输入表!$H$104*参数输入表!$H$13/(1+参数输入表!$H$108) -> 90 | J7: =参数输入表!$H$104*参数输入表!$H$13/(1+参数输入表!$H$108) -> 90 | K7: =参数输入表!$H$104*参数输入表!$H$13/(1+参数输入表!$H$108) -> 90 | L7: =参数输入表!$H$104*参数输入表!$H$13/(1+参数输入表!$H$108) -> 90 | M7: =参数输入表!$H$105*参数输入表!$H$13/(1+参数输入表!$H$108) -> 90 | N7: =参数输入表!$H$105*参数输入表!$H$13/(1+参数输入表!$H$108) -> 90 | O7: =参数输入表!$H$105*参数输入表!$H$13/(1+参数输入表!$H$108) -> 90 | P7: =参数输入表!$H$105*参数输入表!$H$13/(1+参数输入表!$H$108) -> 90 | Q7: =参数输入表!$H$105*参数输入表!$H$13/(1+参数输入表!$H$108) -> 90 | R7: =参数输入表!$H$106*参数输入表!$H$13/(1+参数输入表!$H$108) -> 90 | S7: =参数输入表!$H$106*参数输入表!$H$13/(1+参数输入表!$H$108) -> 90 | T7: =参数输入表!$H$106*参数输入表!$H$13/(1+参数输入表!$H$108) -> 90 | U7: =参数输入表!$H$106*参数输入表!$H$13/(1+参数输入表!$H$108) -> 90 | V7: =参数输入表!$H$106*参数输入表!$H$13/(1+参数输入表!$H$108) -> 90 | W7: =参数输入表!$H$107*参数输入表!$H$13/(1+参数输入表!$H$108) -> 90 | X7: =参数输入表!$H$107*参数输入表!$H$13/(1+参数输入表!$H$108) -> 90 | Y7: =参数输入表!$H$107*参数输入表!$H$13/(1+参数输入表!$H$108) -> 90 | Z7: =参数输入表!$H$107*参数输入表!$H$13/(1+参数输入表!$H$108) -> 90 | AA7: =参数输入表!$H$107*参数输入表!$H$13/(1+参数输入表!$H$108) -> 90
B8: 1.2 | C8: 维修费 | D8: =SUM(F8:AA8) -> 5521.1612 | E8: 万元 | H8: =(参数输入表!$H$76-参数输入表!$H$83)*参数输入表!$H$112/(1+参数输入表!$H$116) -> 110.42322 | I8: =(参数输入表!$H$76-参数输入表!$H$83)*参数输入表!$H$112/(1+参数输入表!$H$116) -> 110.42322 | J8: =(参数输入表!$H$76-参数输入表!$H$83)*参数输入表!$H$112/(1+参数输入表!$H$116) -> 110.42322 | K8: =(参数输入表!$H$76-参数输入表!$H$83)*参数输入表!$H$112/(1+参数输入表!$H$116) -> 110.42322 | L8: =(参数输入表!$H$76-参数输入表!$H$83)*参数输入表!$H$112/(1+参数输入表!$H$116) -> 110.42322 | M8: =(参数输入表!$H$76-参数输入表!$H$83)*参数输入表!$H$113/(1+参数输入表!$H$116) -> 220.84645 | N8: =(参数输入表!$H$76-参数输入表!$H$83)*参数输入表!$H$113/(1+参数输入表!$H$116) -> 220.84645 | O8: =(参数输入表!$H$76-参数输入表!$H$83)*参数输入表!$H$113/(1+参数输入表!$H$116) -> 220.84645 | P8: =(参数输入表!$H$76-参数输入表!$H$83)*参数输入表!$H$113/(1+参数输入表!$H$116) -> 220.84645 | Q8: =(参数输入表!$H$76-参数输入表!$H$83)*参数输入表!$H$113/(1+参数输入表!$H$116) -> 220.84645 | R8: =(参数输入表!$H$76-参数输入表!$H$83)*参数输入表!$H$114/(1+参数输入表!$H$116) -> 331.26967 | S8: =(参数输入表!$H$76-参数输入表!$H$83)*参数输入表!$H$114/(1+参数输入表!$H$116) -> 331.26967 | T8: =(参数输入表!$H$76-参数输入表!$H$83)*参数输入表!$H$114/(1+参数输入表!$H$116) -> 331.26967 | U8: =(参数输入表!$H$76-参数输入表!$H$83)*参数输入表!$H$114/(1+参数输入表!$H$116) -> 331.26967 | V8: =(参数输入表!$H$76-参数输入表!$H$83)*参数输入表!$H$114/(1+参数输入表!$H$116) -> 331.26967 | W8: =(参数输入表!$H$76-参数输入表!$H$83)*参数输入表!$H$115/(1+参数输入表!$H$116) -> 441.69289 | X8: =(参数输入表!$H$76-参数输入表!$H$83)*参数输入表!$H$115/(1+参数输入表!$H$116) -> 441.69289 | Y8: =(参数输入表!$H$76-参数输入表!$H$83)*参数输入表!$H$115/(1+参数输入表!$H$116) -> 441.69289 | Z8: =(参数输入表!$H$76-参数输入表!$H$83)*参数输入表!$H$115/(1+参数输入表!$H$116) -> 441.69289 | AA8: =(参数输入表!$H$76-参数输入表!$H$83)*参数输入表!$H$115/(1+参数输入表!$H$116) -> 441.69289
B9: 1.3 | C9: 生产人员薪酬及福利 | D9: =SUM(F9:AA9) -> 2688 | E9: 万元 | H9: =(参数输入表!$H$127*参数输入表!$H$130+参数输入表!$H$128*参数输入表!$H$131)*(1+参数输入表!$H$132)*(1+参数输入表!$H$133*(H4-1))/(1+参数输入表!$H$134) -> 134.4 | I9: =(参数输入表!$H$127*参数输入表!$H$130+参数输入表!$H$128*参数输入表!$H$131)*(1+参数输入表!$H$132)*(1+参数输入表!$H$133*(I4-1))/(1+参数输入表!$H$134) -> 134.4 | J9: =(参数输入表!$H$127*参数输入表!$H$130+参数输入表!$H$128*参数输入表!$H$131)*(1+参数输入表!$H$132)*(1+参数输入表!$H$133*(J4-1))/(1+参数输入表!$H$134) -> 134.4 | K9: =(参数输入表!$H$127*参数输入表!$H$130+参数输入表!$H$128*参数输入表!$H$131)*(1+参数输入表!$H$132)*(1+参数输入表!$H$133*(K4-1))/(1+参数输入表!$H$134) -> 134.4 | L9: =(参数输入表!$H$127*参数输入表!$H$130+参数输入表!$H$128*参数输入表!$H$131)*(1+参数输入表!$H$132)*(1+参数输入表!$H$133*(L4-1))/(1+参数输入表!$H$134) -> 134.4 | M9: =(参数输入表!$H$127*参数输入表!$H$130+参数输入表!$H$128*参数输入表!$H$131)*(1+参数输入表!$H$132)*(1+参数输入表!$H$133*(M4-1))/(1+参数输入表!$H$134) -> 134.4 | N9: =(参数输入表!$H$127*参数输入表!$H$130+参数输入表!$H$128*参数输入表!$H$131)*(1+参数输入表!$H$132)*(1+参数输入表!$H$133*(N4-1))/(1+参数输入表!$H$134) -> 134.4 | O9: =(参数输入表!$H$127*参数输入表!$H$130+参数输入表!$H$128*参数输入表!$H$131)*(1+参数输入表!$H$132)*(1+参数输入表!$H$133*(O4-1))/(1+参数输入表!$H$134) -> 134.4 | ... AA9: =(参数输入表!$H$127*参数输入表!$H$130+参数输入表!$H$128*参数输入表!$H$131)*(1+参数输入表!$H$132)*(1+参数输入表!$H$133*(AA4-1))/(1+参数输入表!$H$134) -> 134.4
B10: 1.4 | C10: 长期待摊费用当期摊销 | D10: =SUM(F10:AA10) -> 0 | E10: 万元 | H10: ='表2-折旧摊销表'!H30 -> 0 | I10: ='表2-折旧摊销表'!I30 -> 0 | J10: ='表2-折旧摊销表'!J30 -> 0 | K10: ='表2-折旧摊销表'!K30 -> 0 | L10: ='表2-折旧摊销表'!L30 -> 0 | M10: ='表2-折旧摊销表'!M30 -> 0 | N10: ='表2-折旧摊销表'!N30 -> 0 | O10: ='表2-折旧摊销表'!O30 -> 0 | ... AA10: ='表2-折旧摊销表'!AA30 -> 0
B11: 1.5 | C11: 营业相关资产折旧及摊销 | D11: =SUM(F11:AA11) -> 21716.579 | E11: 万元 | H11: ='表2-折旧摊销表'!H27+'表2-折旧摊销表'!H33+'表2-折旧摊销表'!H36 -> 1420.8693 | I11: ='表2-折旧摊销表'!I27+'表2-折旧摊销表'!I33+'表2-折旧摊销表'!I36 -> 1420.8693 | J11: ='表2-折旧摊销表'!J27+'表2-折旧摊销表'!J33+'表2-折旧摊销表'!J36 -> 1420.8693 | K11: ='表2-折旧摊销表'!K27+'表2-折旧摊销表'!K33+'表2-折旧摊销表'!K36 -> 1420.8693 | L11: ='表2-折旧摊销表'!L27+'表2-折旧摊销表'!L33+'表2-折旧摊销表'!L36 -> 1420.8693 | M11: ='表2-折旧摊销表'!M27+'表2-折旧摊销表'!M33+'表2-折旧摊销表'!M36 -> 1420.8693 | N11: ='表2-折旧摊销表'!N27+'表2-折旧摊销表'!N33+'表2-折旧摊销表'!N36 -> 1420.8693 | O11: ='表2-折旧摊销表'!O27+'表2-折旧摊销表'!O33+'表2-折旧摊销表'!O36 -> 1420.8693 | ... AA11: ='表2-折旧摊销表'!AA27+'表2-折旧摊销表'!AA33+'表2-折旧摊销表'!AA36 -> 40.353982
B12: 1.6 | C12: 其他费用 | D12: =SUM(F12:AA12) -> 1500 | E12: 万元 | H12: =参数输入表!$H$135*参数输入表!$H$13/(1+参数输入表!$H$136) -> 75 | I12: =参数输入表!$H$135*参数输入表!$H$13/(1+参数输入表!$H$136) -> 75 | J12: =参数输入表!$H$135*参数输入表!$H$13/(1+参数输入表!$H$136) -> 75 | K12: =参数输入表!$H$135*参数输入表!$H$13/(1+参数输入表!$H$136) -> 75 | L12: =参数输入表!$H$135*参数输入表!$H$13/(1+参数输入表!$H$136) -> 75 | M12: =参数输入表!$H$135*参数输入表!$H$13/(1+参数输入表!$H$136) -> 75 | N12: =参数输入表!$H$135*参数输入表!$H$13/(1+参数输入表!$H$136) -> 75 | O12: =参数输入表!$H$135*参数输入表!$H$13/(1+参数输入表!$H$136) -> 75 | ... AA12: =参数输入表!$H$135*参数输入表!$H$13/(1+参数输入表!$H$136) -> 75
B13: 1.7 | C13: 储能费用 | D13: =SUM(F13:AA13) -> 0 | E13: 万元 | H13: =参数输入表!$H$145*参数输入表!$H$13*1000/10000/(1+参数输入表!$H$146) -> 0 | I13: =参数输入表!$H$145*参数输入表!$H$13*1000/10000/(1+参数输入表!$H$146) -> 0 | J13: =参数输入表!$H$145*参数输入表!$H$13*1000/10000/(1+参数输入表!$H$146) -> 0 | K13: =参数输入表!$H$145*参数输入表!$H$13*1000/10000/(1+参数输入表!$H$146) -> 0 | L13: =参数输入表!$H$145*参数输入表!$H$13*1000/10000/(1+参数输入表!$H$146) -> 0 | M13: =参数输入表!$H$145*参数输入表!$H$13*1000/10000/(1+参数输入表!$H$146) -> 0 | N13: =参数输入表!$H$145*参数输入表!$H$13*1000/10000/(1+参数输入表!$H$146) -> 0 | O13: =参数输入表!$H$145*参数输入表!$H$13*1000/10000/(1+参数输入表!$H$146) -> 0 | ... AA13: =参数输入表!$H$145*参数输入表!$H$13*1000/10000/(1+参数输入表!$H$146) -> 0
B14: 1.8 | C14: 场地租金费用 | D14: =SUM(F14:AA14) -> 0 | E14: 万元 | H14: =参数输入表!$H$138*参数输入表!$H$139/10000*(1)/(1+参数输入表!$H$140) -> 0 | I14: =参数输入表!$H$138*参数输入表!$H$139/10000*(1)/(1+参数输入表!$H$140) -> 0 | J14: =参数输入表!$H$138*参数输入表!$H$139/10000*(1)/(1+参数输入表!$H$140) -> 0 | K14: =参数输入表!$H$138*参数输入表!$H$139/10000*(1)/(1+参数输入表!$H$140) -> 0 | L14: =参数输入表!$H$138*参数输入表!$H$139/10000*(1)/(1+参数输入表!$H$140) -> 0 | M14: =参数输入表!$H$138*参数输入表!$H$139/10000*(1)/(1+参数输入表!$H$140) -> 0 | N14: =参数输入表!$H$138*参数输入表!$H$139/10000*(1)/(1+参数输入表!$H$140) -> 0 | O14: =参数输入表!$H$138*参数输入表!$H$139/10000*(1)/(1+参数输入表!$H$140) -> 0 | ... AA14: =参数输入表!$H$138*参数输入表!$H$139/10000*(1)/(1+参数输入表!$H$140) -> 0
B15: 2 | C15: 销售费用 | D15: =SUM(F15:AA15) -> 0 | E15: 万元 | H15: 0 | I15: 0 | J15: 0 | K15: 0 | L15: 0 | M15: 0 | N15: 0 | O15: 0 | P15: 0 | Q15: 0 | R15: 0 | S15: 0 | T15: 0 | U15: 0 | V15: 0 | W15: 0 | X15: 0 | Y15: 0 | Z15: 0 | AA15: 0
B16: 3 | C16: 管理费用 | D16: =SUM(F16:AA16) -> 1121.7389 | E16: 万元 | H16: =SUM(H17:H18) -> 56.086946 | I16: =SUM(I17:I18) -> 56.086946 | J16: =SUM(J17:J18) -> 56.086946 | K16: =SUM(K17:K18) -> 56.086946 | L16: =SUM(L17:L18) -> 56.086946 | M16: =SUM(M17:M18) -> 56.086946 | N16: =SUM(N17:N18) -> 56.086946 | O16: =SUM(O17:O18) -> 56.086946 | ... AA16: =SUM(AA17:AA18) -> 56.086946
B17: 3.1 | C17: 保险费 | D17: =SUM(F17:AA17) -> 1121.7389 | E17: 万元 | H17: ='表2-折旧摊销表'!$D$4*参数输入表!$H$120/(1+参数输入表!$H$124) -> 56.086946 | I17: ='表2-折旧摊销表'!$D$4*参数输入表!$H$120/(1+参数输入表!$H$124) -> 56.086946 | J17: ='表2-折旧摊销表'!$D$4*参数输入表!$H$120/(1+参数输入表!$H$124) -> 56.086946 | K17: ='表2-折旧摊销表'!$D$4*参数输入表!$H$120/(1+参数输入表!$H$124) -> 56.086946 | L17: ='表2-折旧摊销表'!$D$4*参数输入表!$H$120/(1+参数输入表!$H$124) -> 56.086946 | M17: ='表2-折旧摊销表'!$D$4*参数输入表!$H$121/(1+参数输入表!$H$124) -> 56.086946 | N17: ='表2-折旧摊销表'!$D$4*参数输入表!$H$121/(1+参数输入表!$H$124) -> 56.086946 | O17: ='表2-折旧摊销表'!$D$4*参数输入表!$H$121/(1+参数输入表!$H$124) -> 56.086946 | P17: ='表2-折旧摊销表'!$D$4*参数输入表!$H$121/(1+参数输入表!$H$124) -> 56.086946 | Q17: ='表2-折旧摊销表'!$D$4*参数输入表!$H$121/(1+参数输入表!$H$124) -> 56.086946 | R17: ='表2-折旧摊销表'!$D$4*参数输入表!$H$122/(1+参数输入表!$H$124) -> 56.086946 | S17: ='表2-折旧摊销表'!$D$4*参数输入表!$H$122/(1+参数输入表!$H$124) -> 56.086946 | T17: ='表2-折旧摊销表'!$D$4*参数输入表!$H$122/(1+参数输入表!$H$124) -> 56.086946 | U17: ='表2-折旧摊销表'!$D$4*参数输入表!$H$122/(1+参数输入表!$H$124) -> 56.086946 | V17: ='表2-折旧摊销表'!$D$4*参数输入表!$H$122/(1+参数输入表!$H$124) -> 56.086946 | W17: ='表2-折旧摊销表'!$D$4*参数输入表!$H$123/(1+参数输入表!$H$124) -> 56.086946 | X17: ='表2-折旧摊销表'!$D$4*参数输入表!$H$123/(1+参数输入表!$H$124) -> 56.086946 | Y17: ='表2-折旧摊销表'!$D$4*参数输入表!$H$123/(1+参数输入表!$H$124) -> 56.086946 | Z17: ='表2-折旧摊销表'!$D$4*参数输入表!$H$123/(1+参数输入表!$H$124) -> 56.086946 | AA17: ='表2-折旧摊销表'!$D$4*参数输入表!$H$123/(1+参数输入表!$H$124) -> 56.086946
B18: 3.2 | C18: 期末拆除费用 | D18: =SUM(F18:AA18) -> 0 | E18: 万元 | H18: 0 | I18: 0 | J18: 0 | K18: 0 | L18: 0 | M18: 0 | N18: 0 | O18: 0 | P18: 0 | Q18: 0 | R18: 0 | S18: 0 | T18: 0 | U18: 0 | V18: 0 | W18: 0 | X18: 0 | Y18: 0 | Z18: 0 | AA18: =参数输入表!H143*参数输入表!H142/(1+参数输入表!$H$144) -> 0
B19: 4 | C19: 研发费用 | D19: =SUM(F19:AA19) -> 0 | E19: 万元 | H19: 0 | I19: 0 | J19: 0 | K19: 0 | L19: 0 | M19: 0 | N19: 0 | O19: 0 | P19: 0 | Q19: 0 | R19: 0 | S19: 0 | T19: 0 | U19: 0 | V19: 0 | W19: 0 | X19: 0 | Y19: 0 | Z19: 0 | AA19: 0
B20: 5 | C20: 财务费用 | D20: =SUM(F20:AA20) -> 5768.0745 | E20: 万元 | H20: =SUM(H21:H23) -> 716.12681 | I20: =SUM(I21:I23) -> 668.60203 | J20: =SUM(J21:J23) -> 621.07724 | K20: =SUM(K21:K23) -> 573.55245 | L20: =SUM(L21:L23) -> 526.02766 | M20: =SUM(M21:M23) -> 478.50288 | N20: =SUM(N21:N23) -> 430.97809 | O20: =SUM(O21:O23) -> 383.4533 | ... AA20: =SUM(AA21:AA23) -> 3.255
B21: 5.1 | C21: 长期借款利息 | D21: =SUM(F21:AA21) -> 5702.9745 | E21: 万元 | H21: ='表1-资金筹措及还本付息表'!H43 -> 712.87181 | I21: ='表1-资金筹措及还本付息表'!I53 -> 665.34703 | J21: ='表1-资金筹措及还本付息表'!J53 -> 617.82224 | K21: ='表1-资金筹措及还本付息表'!K53 -> 570.29745 | L21: ='表1-资金筹措及还本付息表'!L53 -> 522.77266 | M21: ='表1-资金筹措及还本付息表'!M53 -> 475.24788 | N21: ='表1-资金筹措及还本付息表'!N53 -> 427.72309 | O21: ='表1-资金筹措及还本付息表'!O53 -> 380.1983 | P21: ='表1-资金筹措及还本付息表'!P53 -> 332.67351 | ... V21: ='表1-资金筹措及还本付息表'!V53 -> 47.524788 | W21: ='表1-资金筹措及还本付息表'!W43 -> 0 | X21: ='表1-资金筹措及还本付息表'!X43 -> 0 | Y21: ='表1-资金筹措及还本付息表'!Y43 -> 0 | Z21: ='表1-资金筹措及还本付息表'!Z43 -> 0 | AA21: ='表1-资金筹措及还本付息表'!AA43 -> 0
B22: 5.2 | C22: 流动资金利息 | D22: =SUM(F22:AA22) -> 65.1 | E22: 万元 | H22: ='表1-资金筹措及还本付息表'!H63 -> 3.255 | I22: ='表1-资金筹措及还本付息表'!I63 -> 3.255 | J22: ='表1-资金筹措及还本付息表'!J63 -> 3.255 | K22: ='表1-资金筹措及还本付息表'!K63 -> 3.255 | L22: ='表1-资金筹措及还本付息表'!L63 -> 3.255 | M22: ='表1-资金筹措及还本付息表'!M63 -> 3.255 | N22: ='表1-资金筹措及还本付息表'!N63 -> 3.255 | O22: ='表1-资金筹措及还本付息表'!O63 -> 3.255 | ... AA22: ='表1-资金筹措及还本付息表'!AA63 -> 3.255
B23: 5.3 | C23: 短期借款利息 | D23: =SUM(F23:AA23) -> 0 | E23: 万元 | H23: ='表1-资金筹措及还本付息表'!H73 -> 0 | I23: ='表1-资金筹措及还本付息表'!I73 -> 0 | J23: ='表1-资金筹措及还本付息表'!J73 -> 0 | K23: ='表1-资金筹措及还本付息表'!K73 -> 0 | L23: ='表1-资金筹措及还本付息表'!L73 -> 0 | M23: ='表1-资金筹措及还本付息表'!M73 -> 0 | N23: ='表1-资金筹措及还本付息表'!N73 -> 0 | O23: ='表1-资金筹措及还本付息表'!O73 -> 0 | ... AA23: ='表1-资金筹措及还本付息表'!AA73 -> 0
B24: 二 | C24: 营业外支出 | D24: =SUM(F24:AA24) -> 0 | E24: 万元 | H24: =参数输入表!$H$211/(1+参数输入表!$H$215) -> 0 | I24: =参数输入表!$H$211/(1+参数输入表!$H$215) -> 0 | J24: =参数输入表!$H$211/(1+参数输入表!$H$215) -> 0 | K24: =参数输入表!$H$211/(1+参数输入表!$H$215) -> 0 | L24: =参数输入表!$H$211/(1+参数输入表!$H$215) -> 0 | M24: =参数输入表!$H$211/(1+参数输入表!$H$215) -> 0 | N24: =参数输入表!$H$211/(1+参数输入表!$H$215) -> 0 | O24: =参数输入表!$H$211/(1+参数输入表!$H$215) -> 0 | ... AA24: =参数输入表!$H$211/(1+参数输入表!$H$215) -> 0
B26: 成本费用表-全投资
B27: 序号 | C27: 项目 | D27: 合计 | E27: 单位 | F27: 建设期 | H27: 运营期
F28: 1 | G28: 2 | H28: 1 | I28: 2 | J28: 3 | K28: 4 | L28: 5 | M28: 6 | N28: 7 | O28: 8 | P28: 9 | Q28: 10 | R28: 11 | S28: 12 | T28: 13 | U28: 14 | V28: 15 | W28: 16 | X28: 17 | Y28: 18 | Z28: 19 | AA28: 20
B29: 一 | C29: 营业总成本 | D29: =SUM(F29:AA29) -> 34347.479 | E29: 万元 | H29: =H30+H39+H40+H43 -> 1886.7795 | I29: =I30+I39+I40+I43 -> 1886.7795 | J29: =J30+J39+J40+J43 -> 1886.7795 | K29: =K30+K39+K40+K43 -> 1886.7795 | L29: =L30+L39+L40+L43 -> 1886.7795 | M29: =M30+M39+M40+M43 -> 1997.2027 | N29: =N30+N39+N40+N43 -> 1997.2027 | O29: =O30+O39+O40+O43 -> 1997.2027 | ... AA29: =AA30+AA39+AA40+AA43 -> 837.53382
B30: 1 | C30: 生产成本 | D30: =SUM(F30:AA30) -> 33225.74 | H30: =SUM(H31:H38) -> 1830.6925 | I30: =SUM(I31:I38) -> 1830.6925 | J30: =SUM(J31:J38) -> 1830.6925 | K30: =SUM(K31:K38) -> 1830.6925 | L30: =SUM(L31:L38) -> 1830.6925 | M30: =SUM(M31:M38) -> 1941.1157 | N30: =SUM(N31:N38) -> 1941.1157 | O30: =SUM(O31:O38) -> 1941.1157 | ... AA30: =SUM(AA31:AA38) -> 781.44688
B31: 1.1 | C31: 材料费 | D31: =SUM(F31:AA31) -> 1800 | E31: 万元 | H31: =参数输入表!$H$104*参数输入表!$H$13/(1+参数输入表!$H$108) -> 90 | I31: =参数输入表!$H$104*参数输入表!$H$13/(1+参数输入表!$H$108) -> 90 | J31: =参数输入表!$H$104*参数输入表!$H$13/(1+参数输入表!$H$108) -> 90 | K31: =参数输入表!$H$104*参数输入表!$H$13/(1+参数输入表!$H$108) -> 90 | L31: =参数输入表!$H$104*参数输入表!$H$13/(1+参数输入表!$H$108) -> 90 | M31: =参数输入表!$H$105*参数输入表!$H$13/(1+参数输入表!$H$108) -> 90 | N31: =参数输入表!$H$105*参数输入表!$H$13/(1+参数输入表!$H$108) -> 90 | O31: =参数输入表!$H$105*参数输入表!$H$13/(1+参数输入表!$H$108) -> 90 | P31: =参数输入表!$H$105*参数输入表!$H$13/(1+参数输入表!$H$108) -> 90 | Q31: =参数输入表!$H$105*参数输入表!$H$13/(1+参数输入表!$H$108) -> 90 | R31: =参数输入表!$H$106*参数输入表!$H$13/(1+参数输入表!$H$108) -> 90 | S31: =参数输入表!$H$106*参数输入表!$H$13/(1+参数输入表!$H$108) -> 90 | T31: =参数输入表!$H$106*参数输入表!$H$13/(1+参数输入表!$H$108) -> 90 | U31: =参数输入表!$H$106*参数输入表!$H$13/(1+参数输入表!$H$108) -> 90 | V31: =参数输入表!$H$106*参数输入表!$H$13/(1+参数输入表!$H$108) -> 90 | W31: =参数输入表!$H$107*参数输入表!$H$13/(1+参数输入表!$H$108) -> 90 | X31: =参数输入表!$H$107*参数输入表!$H$13/(1+参数输入表!$H$108) -> 90 | Y31: =参数输入表!$H$107*参数输入表!$H$13/(1+参数输入表!$H$108) -> 90 | Z31: =参数输入表!$H$107*参数输入表!$H$13/(1+参数输入表!$H$108) -> 90 | AA31: =参数输入表!$H$107*参数输入表!$H$13/(1+参数输入表!$H$108) -> 90
B32: 1.2 | C32: 维修费 | D32: =SUM(F32:AA32) -> 5521.1612 | E32: 万元 | H32: =(参数输入表!$H$76-参数输入表!$H$83)*参数输入表!$H$112/(1+参数输入表!$H$116) -> 110.42322 | I32: =(参数输入表!$H$76-参数输入表!$H$83)*参数输入表!$H$112/(1+参数输入表!$H$116) -> 110.42322 | J32: =(参数输入表!$H$76-参数输入表!$H$83)*参数输入表!$H$112/(1+参数输入表!$H$116) -> 110.42322 | K32: =(参数输入表!$H$76-参数输入表!$H$83)*参数输入表!$H$112/(1+参数输入表!$H$116) -> 110.42322 | L32: =(参数输入表!$H$76-参数输入表!$H$83)*参数输入表!$H$112/(1+参数输入表!$H$116) -> 110.42322 | M32: =(参数输入表!$H$76-参数输入表!$H$83)*参数输入表!$H$113/(1+参数输入表!$H$116) -> 220.84645 | N32: =(参数输入表!$H$76-参数输入表!$H$83)*参数输入表!$H$113/(1+参数输入表!$H$116) -> 220.84645 | O32: =(参数输入表!$H$76-参数输入表!$H$83)*参数输入表!$H$113/(1+参数输入表!$H$116) -> 220.84645 | P32: =(参数输入表!$H$76-参数输入表!$H$83)*参数输入表!$H$113/(1+参数输入表!$H$116) -> 220.84645 | Q32: =(参数输入表!$H$76-参数输入表!$H$83)*参数输入表!$H$113/(1+参数输入表!$H$116) -> 220.84645 | R32: =(参数输入表!$H$76-参数输入表!$H$83)*参数输入表!$H$114/(1+参数输入表!$H$116) -> 331.26967 | S32: =(参数输入表!$H$76-参数输入表!$H$83)*参数输入表!$H$114/(1+参数输入表!$H$116) -> 331.26967 | T32: =(参数输入表!$H$76-参数输入表!$H$83)*参数输入表!$H$114/(1+参数输入表!$H$116) -> 331.26967 | U32: =(参数输入表!$H$76-参数输入表!$H$83)*参数输入表!$H$114/(1+参数输入表!$H$116) -> 331.26967 | V32: =(参数输入表!$H$76-参数输入表!$H$83)*参数输入表!$H$114/(1+参数输入表!$H$116) -> 331.26967 | W32: =(参数输入表!$H$76-参数输入表!$H$83)*参数输入表!$H$115/(1+参数输入表!$H$116) -> 441.69289 | X32: =(参数输入表!$H$76-参数输入表!$H$83)*参数输入表!$H$115/(1+参数输入表!$H$116) -> 441.69289 | Y32: =(参数输入表!$H$76-参数输入表!$H$83)*参数输入表!$H$115/(1+参数输入表!$H$116) -> 441.69289 | Z32: =(参数输入表!$H$76-参数输入表!$H$83)*参数输入表!$H$115/(1+参数输入表!$H$116) -> 441.69289 | AA32: =(参数输入表!$H$76-参数输入表!$H$83)*参数输入表!$H$115/(1+参数输入表!$H$116) -> 441.69289
B33: 1.3 | C33: 生产人员薪酬及福利 | D33: =SUM(F33:AA33) -> 2688 | E33: 万元 | H33: =(参数输入表!$H$127*参数输入表!$H$130+参数输入表!$H$128*参数输入表!$H$131)*(1+参数输入表!$H$132)*(1+参数输入表!$H$133*(H28-1))/(1+参数输入表!$H$134) -> 134.4 | I33: =(参数输入表!$H$127*参数输入表!$H$130+参数输入表!$H$128*参数输入表!$H$131)*(1+参数输入表!$H$132)*(1+参数输入表!$H$133*(I28-1))/(1+参数输入表!$H$134) -> 134.4 | J33: =(参数输入表!$H$127*参数输入表!$H$130+参数输入表!$H$128*参数输入表!$H$131)*(1+参数输入表!$H$132)*(1+参数输入表!$H$133*(J28-1))/(1+参数输入表!$H$134) -> 134.4 | K33: =(参数输入表!$H$127*参数输入表!$H$130+参数输入表!$H$128*参数输入表!$H$131)*(1+参数输入表!$H$132)*(1+参数输入表!$H$133*(K28-1))/(1+参数输入表!$H$134) -> 134.4 | L33: =(参数输入表!$H$127*参数输入表!$H$130+参数输入表!$H$128*参数输入表!$H$131)*(1+参数输入表!$H$132)*(1+参数输入表!$H$133*(L28-1))/(1+参数输入表!$H$134) -> 134.4 | M33: =(参数输入表!$H$127*参数输入表!$H$130+参数输入表!$H$128*参数输入表!$H$131)*(1+参数输入表!$H$132)*(1+参数输入表!$H$133*(M28-1))/(1+参数输入表!$H$134) -> 134.4 | N33: =(参数输入表!$H$127*参数输入表!$H$130+参数输入表!$H$128*参数输入表!$H$131)*(1+参数输入表!$H$132)*(1+参数输入表!$H$133*(N28-1))/(1+参数输入表!$H$134) -> 134.4 | O33: =(参数输入表!$H$127*参数输入表!$H$130+参数输入表!$H$128*参数输入表!$H$131)*(1+参数输入表!$H$132)*(1+参数输入表!$H$133*(O28-1))/(1+参数输入表!$H$134) -> 134.4 | ... AA33: =(参数输入表!$H$127*参数输入表!$H$130+参数输入表!$H$128*参数输入表!$H$131)*(1+参数输入表!$H$132)*(1+参数输入表!$H$133*(AA28-1))/(1+参数输入表!$H$134) -> 134.4
B34: 1.4 | C34: 长期待摊费用当期摊销 | D34: =SUM(F34:AA34) -> 0 | E34: 万元 | H34: ='表2-折旧摊销表'!H58 -> 0 | I34: ='表2-折旧摊销表'!I58 -> 0 | J34: ='表2-折旧摊销表'!J58 -> 0 | K34: ='表2-折旧摊销表'!K58 -> 0 | L34: ='表2-折旧摊销表'!L58 -> 0 | M34: ='表2-折旧摊销表'!M58 -> 0 | N34: ='表2-折旧摊销表'!N58 -> 0 | O34: ='表2-折旧摊销表'!O58 -> 0 | ... AA34: ='表2-折旧摊销表'!AA58 -> 0
B35: 1.5 | C35: 营业相关资产折旧及摊销 | D35: =SUM(F35:AA35) -> 21716.579 | E35: 万元 | H35: ='表2-折旧摊销表'!H55+'表2-折旧摊销表'!H61+'表2-折旧摊销表'!H64 -> 1420.8693 | I35: ='表2-折旧摊销表'!I55+'表2-折旧摊销表'!I61+'表2-折旧摊销表'!I64 -> 1420.8693 | J35: ='表2-折旧摊销表'!J55+'表2-折旧摊销表'!J61+'表2-折旧摊销表'!J64 -> 1420.8693 | K35: ='表2-折旧摊销表'!K55+'表2-折旧摊销表'!K61+'表2-折旧摊销表'!K64 -> 1420.8693 | L35: ='表2-折旧摊销表'!L55+'表2-折旧摊销表'!L61+'表2-折旧摊销表'!L64 -> 1420.8693 | M35: ='表2-折旧摊销表'!M55+'表2-折旧摊销表'!M61+'表2-折旧摊销表'!M64 -> 1420.8693 | N35: ='表2-折旧摊销表'!N55+'表2-折旧摊销表'!N61+'表2-折旧摊销表'!N64 -> 1420.8693 | O35: ='表2-折旧摊销表'!O55+'表2-折旧摊销表'!O61+'表2-折旧摊销表'!O64 -> 1420.8693 | ... AA35: ='表2-折旧摊销表'!AA55+'表2-折旧摊销表'!AA61+'表2-折旧摊销表'!AA64 -> 40.353982
B36: 1.6 | C36: 其他费用 | D36: =SUM(F36:AA36) -> 1500 | E36: 万元 | H36: =参数输入表!$H$135*参数输入表!$H$13/(1+参数输入表!$H$136) -> 75 | I36: =参数输入表!$H$135*参数输入表!$H$13/(1+参数输入表!$H$136) -> 75 | J36: =参数输入表!$H$135*参数输入表!$H$13/(1+参数输入表!$H$136) -> 75 | K36: =参数输入表!$H$135*参数输入表!$H$13/(1+参数输入表!$H$136) -> 75 | L36: =参数输入表!$H$135*参数输入表!$H$13/(1+参数输入表!$H$136) -> 75 | M36: =参数输入表!$H$135*参数输入表!$H$13/(1+参数输入表!$H$136) -> 75 | N36: =参数输入表!$H$135*参数输入表!$H$13/(1+参数输入表!$H$136) -> 75 | O36: =参数输入表!$H$135*参数输入表!$H$13/(1+参数输入表!$H$136) -> 75 | ... AA36: =参数输入表!$H$135*参数输入表!$H$13/(1+参数输入表!$H$136) -> 75
B37: 1.7 | C37: 储能费用 | D37: =SUM(F37:AA37) -> 0 | E37: 万元 | H37: =参数输入表!$H$145*参数输入表!$H$13*1000/10000/(1+参数输入表!$H$146) -> 0 | I37: =参数输入表!$H$145*参数输入表!$H$13*1000/10000/(1+参数输入表!$H$146) -> 0 | J37: =参数输入表!$H$145*参数输入表!$H$13*1000/10000/(1+参数输入表!$H$146) -> 0 | K37: =参数输入表!$H$145*参数输入表!$H$13*1000/10000/(1+参数输入表!$H$146) -> 0 | L37: =参数输入表!$H$145*参数输入表!$H$13*1000/10000/(1+参数输入表!$H$146) -> 0 | M37: =参数输入表!$H$145*参数输入表!$H$13*1000/10000/(1+参数输入表!$H$146) -> 0 | N37: =参数输入表!$H$145*参数输入表!$H$13*1000/10000/(1+参数输入表!$H$146) -> 0 | O37: =参数输入表!$H$145*参数输入表!$H$13*1000/10000/(1+参数输入表!$H$146) -> 0 | ... AA37: =参数输入表!$H$145*参数输入表!$H$13*1000/10000/(1+参数输入表!$H$146) -> 0
B38: 1.8 | C38: 场地租金费用 | D38: =SUM(F38:AA38) -> 0 | E38: 万元 | H38: =参数输入表!$H$138*参数输入表!$H$139/10000*(1+0)/(1+参数输入表!$H$140) -> 0 | I38: =参数输入表!$H$138*参数输入表!$H$139/10000*(1+0)/(1+参数输入表!$H$140) -> 0 | J38: =参数输入表!$H$138*参数输入表!$H$139/10000*(1+0)/(1+参数输入表!$H$140) -> 0 | K38: =参数输入表!$H$138*参数输入表!$H$139/10000*(1+0)/(1+参数输入表!$H$140) -> 0 | L38: =参数输入表!$H$138*参数输入表!$H$139/10000*(1+0)/(1+参数输入表!$H$140) -> 0 | M38: =参数输入表!$H$138*参数输入表!$H$139/10000*(1+0)/(1+参数输入表!$H$140) -> 0 | N38: =参数输入表!$H$138*参数输入表!$H$139/10000*(1+0)/(1+参数输入表!$H$140) -> 0 | O38: =参数输入表!$H$138*参数输入表!$H$139/10000*(1+0)/(1+参数输入表!$H$140) -> 0 | ... AA38: =参数输入表!$H$138*参数输入表!$H$139/10000*(1+0)/(1+参数输入表!$H$140) -> 0
B39: 2 | C39: 销售费用 | D39: =SUM(F39:AA39) -> 0 | E39: 万元 | H39: 0 | I39: 0 | J39: 0 | K39: 0 | L39: 0 | M39: 0 | N39: 0 | O39: 0 | P39: 0 | Q39: 0 | R39: 0 | S39: 0 | T39: 0 | U39: 0 | V39: 0 | W39: 0 | X39: 0 | Y39: 0 | Z39: 0 | AA39: 0
B40: 3 | C40: 管理费用 | D40: =SUM(F40:AA40) -> 1121.7389 | E40: 万元 | H40: =SUM(H41:H42) -> 56.086946 | I40: =SUM(I41:I42) -> 56.086946 | J40: =SUM(J41:J42) -> 56.086946 | K40: =SUM(K41:K42) -> 56.086946 | L40: =SUM(L41:L42) -> 56.086946 | M40: =SUM(M41:M42) -> 56.086946 | N40: =SUM(N41:N42) -> 56.086946 | O40: =SUM(O41:O42) -> 56.086946 | ... AA40: =SUM(AA41:AA42) -> 56.086946
B41: 3.1 | C41: 保险费 | D41: =SUM(F41:AA41) -> 1121.7389 | E41: 万元 | H41: ='表2-折旧摊销表'!$D$4*参数输入表!$H$120/(1+参数输入表!$H$124) -> 56.086946 | I41: ='表2-折旧摊销表'!$D$4*参数输入表!$H$120/(1+参数输入表!$H$124) -> 56.086946 | J41: ='表2-折旧摊销表'!$D$4*参数输入表!$H$120/(1+参数输入表!$H$124) -> 56.086946 | K41: ='表2-折旧摊销表'!$D$4*参数输入表!$H$120/(1+参数输入表!$H$124) -> 56.086946 | L41: ='表2-折旧摊销表'!$D$4*参数输入表!$H$120/(1+参数输入表!$H$124) -> 56.086946 | M41: ='表2-折旧摊销表'!$D$4*参数输入表!$H$121/(1+参数输入表!$H$124) -> 56.086946 | N41: ='表2-折旧摊销表'!$D$4*参数输入表!$H$121/(1+参数输入表!$H$124) -> 56.086946 | O41: ='表2-折旧摊销表'!$D$4*参数输入表!$H$121/(1+参数输入表!$H$124) -> 56.086946 | P41: ='表2-折旧摊销表'!$D$4*参数输入表!$H$121/(1+参数输入表!$H$124) -> 56.086946 | Q41: ='表2-折旧摊销表'!$D$4*参数输入表!$H$121/(1+参数输入表!$H$124) -> 56.086946 | R41: ='表2-折旧摊销表'!$D$4*参数输入表!$H$122/(1+参数输入表!$H$124) -> 56.086946 | S41: ='表2-折旧摊销表'!$D$4*参数输入表!$H$122/(1+参数输入表!$H$124) -> 56.086946 | T41: ='表2-折旧摊销表'!$D$4*参数输入表!$H$122/(1+参数输入表!$H$124) -> 56.086946 | U41: ='表2-折旧摊销表'!$D$4*参数输入表!$H$122/(1+参数输入表!$H$124) -> 56.086946 | V41: ='表2-折旧摊销表'!$D$4*参数输入表!$H$122/(1+参数输入表!$H$124) -> 56.086946 | W41: ='表2-折旧摊销表'!$D$4*参数输入表!$H$123/(1+参数输入表!$H$124) -> 56.086946 | X41: ='表2-折旧摊销表'!$D$4*参数输入表!$H$123/(1+参数输入表!$H$124) -> 56.086946 | Y41: ='表2-折旧摊销表'!$D$4*参数输入表!$H$123/(1+参数输入表!$H$124) -> 56.086946 | Z41: ='表2-折旧摊销表'!$D$4*参数输入表!$H$123/(1+参数输入表!$H$124) -> 56.086946 | AA41: ='表2-折旧摊销表'!$D$4*参数输入表!$H$123/(1+参数输入表!$H$124) -> 56.086946
B42: 3.2 | C42: 期末拆除费用 | D42: =SUM(F42:AA42) -> 0 | E42: 万元 | H42: 0 | I42: 0 | J42: 0 | K42: 0 | L42: 0 | M42: 0 | N42: 0 | O42: 0 | P42: 0 | Q42: 0 | R42: 0 | S42: 0 | T42: 0 | U42: 0 | V42: 0 | W42: 0 | X42: 0 | Y42: 0 | Z42: 0 | AA42: =参数输入表!H143*参数输入表!H142/(1+参数输入表!$H$144) -> 0
...

Sheet 表4-收入税金表
B2: 收入表
B3: 序号 | C3: 项目 | D3: 合计 | E3: 单位 | F3: 建设期 | H3: 运营期
F4: 1 | G4: 2 | H4: 1 | I4: 2 | J4: 3 | K4: 4 | L4: 5 | M4: 6 | N4: 7 | O4: 8 | P4: 9 | Q4: 10 | R4: 11 | S4: 12 | T4: 13 | U4: 14 | V4: 15 | W4: 16 | X4: 17 | Y4: 18 | Z4: 19 | AA4: 20
B5: 1 | C5: 营业收入 | D5: =SUM(F5:AA5) -> 55978.052 | E5: 万元 | H5: =H6+H16 -> 2781.8166 | I5: =I6+I16 -> 2781.8166 | J5: =J6+J16 -> 2781.8166 | K5: =K6+K16 -> 2781.8166 | L5: =L6+L16 -> 2781.8166 | M5: =M6+M16 -> 2804.5979 | N5: =N6+N16 -> 2804.5979 | O5: =O6+O16 -> 2804.5979 | ... AA5: =AA6+AA16 -> 2804.5979
B6: 1.1 | C6: 发电销售收入 | D6: =SUM(F6:AA6) -> 55978.052 | E6: 万元 | H6: =(H9*H10-H11-H12)/(1+参数输入表!$H$233)+(H14*H15)/(1+参数输入表!$H$237) -> 2781.8166 | I6: =(I9*I10-I11-I12)/(1+参数输入表!$H$233)+(I14*I15)/(1+参数输入表!$H$237) -> 2781.8166 | J6: =(J9*J10-J11-J12)/(1+参数输入表!$H$233)+(J14*J15)/(1+参数输入表!$H$237) -> 2781.8166 | K6: =(K9*K10-K11-K12)/(1+参数输入表!$H$233)+(K14*K15)/(1+参数输入表!$H$237) -> 2781.8166 | L6: =(L9*L10-L11-L12)/(1+参数输入表!$H$233)+(L14*L15)/(1+参数输入表!$H$237) -> 2781.8166 | M6: =(M9*M10-M11-M12)/(1+参数输入表!$H$233)+(M14*M15)/(1+参数输入表!$H$237) -> 2804.5979 | N6: =(N9*N10-N11-N12)/(1+参数输入表!$H$233)+(N14*N15)/(1+参数输入表!$H$237) -> 2804.5979 | O6: =(O9*O10-O11-O12)/(1+参数输入表!$H$233)+(O14*O15)/(1+参数输入表!$H$237) -> 2804.5979 | ... AA6: =(AA9*AA10-AA11-AA12)/(1+参数输入表!$H$233)+(AA14*AA15)/(1+参数输入表!$H$237) -> 2804.5979
C7: 发电量 | D7: =SUM(F7:AA7) -> 213854 | E7: 万度 | H7: =参数输入表!H17/10 -> 10692.7 | I7: =H7 -> 10692.7 | J7: =I7 -> 10692.7 | K7: =J7 -> 10692.7 | L7: =K7 -> 10692.7 | M7: =L7 -> 10692.7 | N7: =M7 -> 10692.7 | O7: =N7 -> 10692.7 | P7: =O7 -> 10692.7 | ... AA7: =Z7 -> 10692.7
C8: 上网售电收入 | D8: =SUM(F8:AA8) -> 19074.043 | E8: 万元 | H8: =H9*H10/1.13 -> 1362.4317 | I8: =I9*I10/1.13 -> 1362.4317 | J8: =J9*J10/1.13 -> 1362.4317 | K8: =K9*K10/1.13 -> 1362.4317 | L8: =L9*L10/1.13 -> 1362.4317 | M8: =M9*M10/1.13 -> 817.459 | N8: =N9*N10/1.13 -> 817.459 | O8: =O9*O10/1.13 -> 817.459 | ... AA8: =AA9*AA10/1.13 -> 817.459
C9: 上网电量 | D9: =SUM(F9:AA9) -> 70807.059 | E9: 万度 | H9: =参数输入表!H19/10 -> 5057.6471 | I9: =参数输入表!H20/10 -> 5057.6471 | J9: =参数输入表!H21/10 -> 5057.6471 | K9: =参数输入表!H22/10 -> 5057.6471 | L9: =参数输入表!H23/10 -> 5057.6471 | M9: =参数输入表!H24/10 -> 3034.5883 | N9: =参数输入表!H25/10 -> 3034.5883 | O9: =参数输入表!H26/10 -> 3034.5883 | P9: =参数输入表!H27/10 -> 3034.5883 | Q9: =参数输入表!H28/10 -> 3034.5883 | R9: =参数输入表!H29/10 -> 3034.5883 | S9: =参数输入表!H30/10 -> 3034.5883 | T9: =参数输入表!H31/10 -> 3034.5883 | U9: =参数输入表!H32/10 -> 3034.5883 | V9: =参数输入表!H33/10 -> 3034.5883 | W9: =参数输入表!H34/10 -> 3034.5883 | X9: =参数输入表!H35/10 -> 3034.5883 | Y9: =参数输入表!H36/10 -> 3034.5883 | Z9: =参数输入表!H37/10 -> 3034.5883 | AA9: =参数输入表!H38/10 -> 3034.5883
C10: 上网电价（含税） | E10: 元/度 | H10: =参数输入表!$H$40 -> 0.3044 | I10: =参数输入表!$H$40 -> 0.3044 | J10: =参数输入表!$H$40 -> 0.3044 | K10: =参数输入表!$H$40 -> 0.3044 | L10: =参数输入表!$H$40 -> 0.3044 | M10: =参数输入表!$H$40 -> 0.3044 | N10: =参数输入表!$H$40 -> 0.3044 | O10: =参数输入表!$H$40 -> 0.3044 | ... AA10: =参数输入表!$H$40 -> 0.3044
C11: 电网辅助服务分摊 | D11: =SUM(F11:AA11) -> 0 | E11: 万元 | H11: =H9*参数输入表!$H$226 -> 0 | I11: =I9*参数输入表!$H$226 -> 0 | J11: =J9*参数输入表!$H$226 -> 0 | K11: =K9*参数输入表!$H$226 -> 0 | L11: =L9*参数输入表!$H$226 -> 0 | M11: =M9*参数输入表!$H$226 -> 0 | N11: =N9*参数输入表!$H$226 -> 0 | O11: =O9*参数输入表!$H$226 -> 0 | ... AA11: =AA9*参数输入表!$H$226 -> 0
C12: 两个细则考核 | D12: =SUM(F12:AA12) -> 0 | E12: 万元 | H12: =H9*参数输入表!$H$230 -> 0 | I12: =I9*参数输入表!$H$230 -> 0 | J12: =J9*参数输入表!$H$230 -> 0 | K12: =K9*参数输入表!$H$230 -> 0 | L12: =L9*参数输入表!$H$230 -> 0 | M12: =M9*参数输入表!$H$230 -> 0 | N12: =N9*参数输入表!$H$230 -> 0 | O12: =O9*参数输入表!$H$230 -> 0 | ... AA12: =AA9*参数输入表!$H$230 -> 0
C13: 数能融合售电收入 | D13: =SUM(H13:AA13) -> 36904.009 | H13: =H14*H15/1.13 -> 1419.385 | I13: =I14*I15/1.13 -> 1419.385 | J13: =J14*J15/1.13 -> 1419.385 | K13: =K14*K15/1.13 -> 1419.385 | L13: =L14*L15/1.13 -> 1419.385 | M13: =M14*M15/1.13 -> 1987.1389 | N13: =N14*N15/1.13 -> 1987.1389 | O13: =O14*O15/1.13 -> 1987.1389 | ... AA13: =AA14*AA15/1.13 -> 1987.1389
C14: 数能融合消纳电量 | D14: =SUM(F14:AA14) -> 139005.1 | E14: 万度 | H14: =参数输入表!H45*参数输入表!$H$17/10 -> 5346.35 | I14: =参数输入表!H46*参数输入表!$H$17/10 -> 5346.35 | J14: =参数输入表!H47*参数输入表!$H$17/10 -> 5346.35 | K14: =参数输入表!H48*参数输入表!$H$17/10 -> 5346.35 | L14: =参数输入表!H49*参数输入表!$H$17/10 -> 5346.35 | M14: =参数输入表!H50*参数输入表!$H$17/10 -> 7484.89 | N14: =参数输入表!H51*参数输入表!$H$17/10 -> 7484.89 | O14: =参数输入表!H52*参数输入表!$H$17/10 -> 7484.89 | P14: =参数输入表!H53*参数输入表!$H$17/10 -> 7484.89 | Q14: =参数输入表!H54*参数输入表!$H$17/10 -> 7484.89 | R14: =参数输入表!H55*参数输入表!$H$17/10 -> 7484.89 | S14: =参数输入表!H56*参数输入表!$H$17/10 -> 7484.89 | T14: =参数输入表!H57*参数输入表!$H$17/10 -> 7484.89 | U14: =参数输入表!H58*参数输入表!$H$17/10 -> 7484.89 | V14: =参数输入表!H59*参数输入表!$H$17/10 -> 7484.89 | W14: =参数输入表!H60*参数输入表!$H$17/10 -> 7484.89 | X14: =参数输入表!H61*参数输入表!$H$17/10 -> 7484.89 | Y14: =参数输入表!H62*参数输入表!$H$17/10 -> 7484.89 | Z14: =参数输入表!H63*参数输入表!$H$17/10 -> 7484.89 | AA14: =参数输入表!H64*参数输入表!$H$17/10 -> 7484.89
C15: 数能融合机制电价（含税） | E15: 元/度 | H15: =参数输入表!H66 -> 0.3 | I15: =H15 -> 0.3 | J15: =I15 -> 0.3 | K15: =J15 -> 0.3 | L15: =K15 -> 0.3 | M15: =L15 -> 0.3 | N15: =M15 -> 0.3 | O15: =N15 -> 0.3 | P15: =O15 -> 0.3 | ... AA15: =Z15 -> 0.3
B16: 2 | C16: 其他收入 | D16: =SUM(F16:AA16) -> 0 | E16: 万元 | H16: =(参数输入表!$H$239*参数输入表!$H$240)/(1+参数输入表!$H$241) -> 0 | I16: =(参数输入表!$H$239*参数输入表!$H$240)/(1+参数输入表!$H$241) -> 0 | J16: =(参数输入表!$H$239*参数输入表!$H$240)/(1+参数输入表!$H$241) -> 0 | K16: =(参数输入表!$H$239*参数输入表!$H$240)/(1+参数输入表!$H$241) -> 0 | L16: =(参数输入表!$H$239*参数输入表!$H$240)/(1+参数输入表!$H$241) -> 0 | M16: =(参数输入表!$H$239*参数输入表!$H$240)/(1+参数输入表!$H$241) -> 0 | N16: =(参数输入表!$H$239*参数输入表!$H$240)/(1+参数输入表!$H$241) -> 0 | O16: =(参数输入表!$H$239*参数输入表!$H$240)/(1+参数输入表!$H$241) -> 0 | ... AA16: =(参数输入表!$H$239*参数输入表!$H$240)/(1+参数输入表!$H$241) -> 0
B17: 3 | C17: 营业外收入 | D17: =SUM(F17:AA17) -> 2452.1051 | E17: 万元 | H17: =SUM(H18:H19) -> 0 | I17: =SUM(I18:I19) -> 0 | J17: =SUM(J18:J19) -> 0 | K17: =SUM(K18:K19) -> 0 | L17: =SUM(L18:L19) -> 0 | M17: =SUM(M18:M19) -> 0 | N17: =SUM(N18:N19) -> 109.83049 | O17: =SUM(O18:O19) -> 182.29887 | ... AA17: =SUM(AA18:AA19) -> 182.29887
B18: 3.1 | C18: 政府一次性运营补贴收入 | D18: =SUM(F18:AA18) -> 0 | E18: 万元 | H18: =参数输入表!H244 -> 0
B19: 3.2 | C19: 增值税即征即退 | D19: =SUM(F19:AA19) -> 2452.1051 | E19: 万元 | H19: =H22*参数输入表!$H$267 -> 0 | I19: =I22*参数输入表!$H$267 -> 0 | J19: =J22*参数输入表!$H$267 -> 0 | K19: =K22*参数输入表!$H$267 -> 0 | L19: =L22*参数输入表!$H$267 -> 0 | M19: =M22*参数输入表!$H$267 -> 0 | N19: =N22*参数输入表!$H$267 -> 109.83049 | O19: =O22*参数输入表!$H$267 -> 182.29887 | ... AA19: =AA22*参数输入表!$H$267 -> 182.29887
B21: 税金表
B22: 1 | C22: 当期实缴增值税 | D22: =SUM(F22:AA22) -> 4904.2102 | E22: 万元 | F22: 0 | G22: =IF(G45>0,0,G44-F45) -> 0 | H22: =IF(H45>0,0,H44-G45) -> 0 | I22: =IF(I45>0,0,I44-H45) -> 0 | J22: =IF(J45>0,0,J44-I45) -> 0 | K22: =IF(K45>0,0,K44-J45) -> 0 | L22: =IF(L45>0,0,L44-K45) -> 0 | M22: =IF(M45>0,0,M44-L45) -> 0 | N22: =IF(N45>0,0,N44-M45) -> 219.66098 | ... AA22: =IF(AA45>0,0,AA44-Z45) -> 364.59773
B23: 2 | C23: 增值税销项税 | D23: =SUM(F23:AA23) -> 7277.1468 | E23: 万元 | F23: =SUM(F24:F25) -> 0 | G23: =SUM(G24:G25) -> 0 | H23: =SUM(H24:H25) -> 361.63616 | I23: =SUM(I24:I25) -> 361.63616 | J23: =SUM(J24:J25) -> 361.63616 | K23: =SUM(K24:K25) -> 361.63616 | L23: =SUM(L24:L25) -> 361.63616 | M23: =SUM(M24:M25) -> 364.59773 | ... AA23: =SUM(AA24:AA25) -> 364.59773
C24: 发电收入销项税 | D24: =SUM(F24:AA24) -> 7277.1468 | E24: 万元 | H24: =H6*参数输入表!$H$233 -> 361.63616 | I24: =I6*参数输入表!$H$233 -> 361.63616 | J24: =J6*参数输入表!$H$233 -> 361.63616 | K24: =K6*参数输入表!$H$233 -> 361.63616 | L24: =L6*参数输入表!$H$233 -> 361.63616 | M24: =M6*参数输入表!$H$233 -> 364.59773 | N24: =N6*参数输入表!$H$233 -> 364.59773 | O24: =O6*参数输入表!$H$233 -> 364.59773 | ... AA24: =AA6*参数输入表!$H$233 -> 364.59773
C25: 其他收入销项税 | D25: =SUM(F25:AA25) -> 0 | E25: 万元 | H25: =H16*参数输入表!$H$241 -> 0 | I25: =I16*参数输入表!$H$241 -> 0 | J25: =J16*参数输入表!$H$241 -> 0 | K25: =K16*参数输入表!$H$241 -> 0 | L25: =L16*参数输入表!$H$241 -> 0 | M25: =M16*参数输入表!$H$241 -> 0 | N25: =N16*参数输入表!$H$241 -> 0 | O25: =O16*参数输入表!$H$241 -> 0 | ... AA25: =AA16*参数输入表!$H$241 -> 0
B26: 3 | C26: 增值税进项税 | D26: =SUM(F26:AA26) -> 2372.9365 | E26: 万元 | F26: =F27+F28+F42+F43 -> 2317.7153 | G26: =G27+G28+G42+G43 -> 0 | H26: =H27+H28+H42+H43 -> 0 | I26: =I27+I28+I42+I43 -> 0 | J26: =J27+J28+J42+J43 -> 0 | K26: =K27+K28+K42+K43 -> 0 | L26: =L27+L28+L42+L43 -> 0 | M26: =M27+M28+M42+M43 -> 0 | ... AA26: =AA27+AA28+AA42+AA43 -> 0
B27: 3.1 | C27: 建设投资进项税 | D27: =SUM(F27:AA27) -> 2317.7153 | E27: 万元 | F27: =参数输入表!H83*参数输入表!H7 -> 2317.7153 | G27: =参数输入表!H83*参数输入表!H8 -> 0
B28: 3.2 | C28: 营业成本进项税 | D28: =SUM(F28:AA28) -> 0 | E28: 万元 | F28: =F29+F37+F38+F41 -> 0 | G28: =G29+G37+G38+G41 -> 0 | H28: =H29+H37+H38+H41 -> 0 | I28: =I29+I37+I38+I41 -> 0 | J28: =J29+J37+J38+J41 -> 0 | K28: =K29+K37+K38+K41 -> 0 | L28: =L29+L37+L38+L41 -> 0 | M28: =M29+M37+M38+M41 -> 0 | ... AA28: =AA29+AA37+AA38+AA41 -> 0
B29: 3.2.1 | C29: 生产成本进项税 | D29: =SUM(F29:AA29) -> 0 | E29: 万元 | H29: =SUM(H30:H36) -> 0 | I29: =SUM(I30:I36) -> 0 | J29: =SUM(J30:J36) -> 0 | K29: =SUM(K30:K36) -> 0 | L29: =SUM(L30:L36) -> 0 | M29: =SUM(M30:M36) -> 0 | N29: =SUM(N30:N36) -> 0 | O29: =SUM(O30:O36) -> 0 | ... AA29: =SUM(AA30:AA36) -> 0
C30: 材料费 | D30: =SUM(F30:AA30) -> 0 | E30: 万元 | H30: ='表3-成本费用表'!H50/(1+参数输入表!$H$108)*参数输入表!$H$108 -> 0 | I30: ='表3-成本费用表'!I50/(1+参数输入表!$H$108)*参数输入表!$H$108 -> 0 | J30: ='表3-成本费用表'!J50/(1+参数输入表!$H$108)*参数输入表!$H$108 -> 0 | K30: ='表3-成本费用表'!K50/(1+参数输入表!$H$108)*参数输入表!$H$108 -> 0 | L30: ='表3-成本费用表'!L50/(1+参数输入表!$H$108)*参数输入表!$H$108 -> 0 | M30: ='表3-成本费用表'!M50/(1+参数输入表!$H$108)*参数输入表!$H$108 -> 0 | N30: ='表3-成本费用表'!N50/(1+参数输入表!$H$108)*参数输入表!$H$108 -> 0 | O30: ='表3-成本费用表'!O50/(1+参数输入表!$H$108)*参数输入表!$H$108 -> 0 | ... AA30: ='表3-成本费用表'!AA50/(1+参数输入表!$H$108)*参数输入表!$H$108 -> 0
C31: 维修费 | D31: =SUM(F31:AA31) -> 0 | E31: 万元 | H31: ='表3-成本费用表'!H51/(1+参数输入表!$H$116)*参数输入表!$H$116 -> 0 | I31: ='表3-成本费用表'!I51/(1+参数输入表!$H$116)*参数输入表!$H$116 -> 0 | J31: ='表3-成本费用表'!J51/(1+参数输入表!$H$116)*参数输入表!$H$116 -> 0 | K31: ='表3-成本费用表'!K51/(1+参数输入表!$H$116)*参数输入表!$H$116 -> 0 | L31: ='表3-成本费用表'!L51/(1+参数输入表!$H$116)*参数输入表!$H$116 -> 0 | M31: ='表3-成本费用表'!M51/(1+参数输入表!$H$116)*参数输入表!$H$116 -> 0 | N31: ='表3-成本费用表'!N51/(1+参数输入表!$H$116)*参数输入表!$H$116 -> 0 | O31: ='表3-成本费用表'!O51/(1+参数输入表!$H$116)*参数输入表!$H$116 -> 0 | ... AA31: ='表3-成本费用表'!AA51/(1+参数输入表!$H$116)*参数输入表!$H$116 -> 0
C32: 生产人员薪酬及福利 | D32: =SUM(F32:AA32) -> 0 | E32: 万元 | H32: ='表3-成本费用表'!H52/(1+参数输入表!$H$134)*参数输入表!$H$134 -> 0 | I32: ='表3-成本费用表'!I52/(1+参数输入表!$H$134)*参数输入表!$H$134 -> 0 | J32: ='表3-成本费用表'!J52/(1+参数输入表!$H$134)*参数输入表!$H$134 -> 0 | K32: ='表3-成本费用表'!K52/(1+参数输入表!$H$134)*参数输入表!$H$134 -> 0 | L32: ='表3-成本费用表'!L52/(1+参数输入表!$H$134)*参数输入表!$H$134 -> 0 | M32: ='表3-成本费用表'!M52/(1+参数输入表!$H$134)*参数输入表!$H$134 -> 0 | N32: ='表3-成本费用表'!N52/(1+参数输入表!$H$134)*参数输入表!$H$134 -> 0 | O32: ='表3-成本费用表'!O52/(1+参数输入表!$H$134)*参数输入表!$H$134 -> 0 | ... AA32: ='表3-成本费用表'!AA52/(1+参数输入表!$H$134)*参数输入表!$H$134 -> 0
C33: 其他费用 | D33: =SUM(F33:AA33) -> 0 | E33: 万元 | H33: ='表3-成本费用表'!H54/(1+参数输入表!$H$136)*参数输入表!$H$136 -> 0 | I33: ='表3-成本费用表'!I54/(1+参数输入表!$H$136)*参数输入表!$H$136 -> 0 | J33: ='表3-成本费用表'!J54/(1+参数输入表!$H$136)*参数输入表!$H$136 -> 0 | K33: ='表3-成本费用表'!K54/(1+参数输入表!$H$136)*参数输入表!$H$136 -> 0 | L33: ='表3-成本费用表'!L54/(1+参数输入表!$H$136)*参数输入表!$H$136 -> 0 | M33: ='表3-成本费用表'!M54/(1+参数输入表!$H$136)*参数输入表!$H$136 -> 0 | N33: ='表3-成本费用表'!N54/(1+参数输入表!$H$136)*参数输入表!$H$136 -> 0 | O33: ='表3-成本费用表'!O54/(1+参数输入表!$H$136)*参数输入表!$H$136 -> 0 | ... AA33: ='表3-成本费用表'!AA54/(1+参数输入表!$H$136)*参数输入表!$H$136 -> 0
C34: 储能费用 | D34: =SUM(F34:AA34) -> 0 | E34: 万元 | H34: ='表3-成本费用表'!H55/(1+参数输入表!$H$146)*参数输入表!$H$146 -> 0 | I34: ='表3-成本费用表'!I55/(1+参数输入表!$H$146)*参数输入表!$H$146 -> 0 | J34: ='表3-成本费用表'!J55/(1+参数输入表!$H$146)*参数输入表!$H$146 -> 0 | K34: ='表3-成本费用表'!K55/(1+参数输入表!$H$146)*参数输入表!$H$146 -> 0 | L34: ='表3-成本费用表'!L55/(1+参数输入表!$H$146)*参数输入表!$H$146 -> 0 | M34: ='表3-成本费用表'!M55/(1+参数输入表!$H$146)*参数输入表!$H$146 -> 0 | N34: ='表3-成本费用表'!N55/(1+参数输入表!$H$146)*参数输入表!$H$146 -> 0 | O34: ='表3-成本费用表'!O55/(1+参数输入表!$H$146)*参数输入表!$H$146 -> 0 | ... AA34: ='表3-成本费用表'!AA55/(1+参数输入表!$H$146)*参数输入表!$H$146 -> 0
C35: 场地租金费用 | D35: =SUM(F35:AA35) -> 0 | E35: 万元 | H35: ='表3-成本费用表'!H56/(1+参数输入表!$H$140)*参数输入表!$H$140 -> 0 | I35: ='表3-成本费用表'!I56/(1+参数输入表!$H$140)*参数输入表!$H$140 -> 0 | J35: ='表3-成本费用表'!J56/(1+参数输入表!$H$140)*参数输入表!$H$140 -> 0 | K35: ='表3-成本费用表'!K56/(1+参数输入表!$H$140)*参数输入表!$H$140 -> 0 | L35: ='表3-成本费用表'!L56/(1+参数输入表!$H$140)*参数输入表!$H$140 -> 0 | M35: ='表3-成本费用表'!M56/(1+参数输入表!$H$140)*参数输入表!$H$140 -> 0 | N35: ='表3-成本费用表'!N56/(1+参数输入表!$H$140)*参数输入表!$H$140 -> 0 | O35: ='表3-成本费用表'!O56/(1+参数输入表!$H$140)*参数输入表!$H$140 -> 0 | ... AA35: ='表3-成本费用表'!AA56/(1+参数输入表!$H$140)*参数输入表!$H$140 -> 0
C36: 计入长期待摊成本项 | D36: =SUM(F36:AA36) -> 0 | E36: 万元 | H36: ='表3-成本费用表'!H53/(1+参数输入表!$H$182)*参数输入表!$H$182 -> 0 | I36: ='表3-成本费用表'!I53/(1+参数输入表!$H$182)*参数输入表!$H$182 -> 0 | J36: ='表3-成本费用表'!J53/(1+参数输入表!$H$182)*参数输入表!$H$182 -> 0 | K36: ='表3-成本费用表'!K53/(1+参数输入表!$H$182)*参数输入表!$H$182 -> 0 | L36: ='表3-成本费用表'!L53/(1+参数输入表!$H$182)*参数输入表!$H$182 -> 0 | M36: ='表3-成本费用表'!M53/(1+参数输入表!$H$182)*参数输入表!$H$182 -> 0 | N36: ='表3-成本费用表'!N53/(1+参数输入表!$H$182)*参数输入表!$H$182 -> 0 | O36: ='表3-成本费用表'!O53/(1+参数输入表!$H$182)*参数输入表!$H$182 -> 0 | ... AA36: ='表3-成本费用表'!AA53/(1+参数输入表!$H$182)*参数输入表!$H$182 -> 0
B37: 3.2.2 | C37: 销售费用进项税 | D37: =SUM(F37:AA37) -> 0 | E37: 万元 | H37: 0 | I37: 0 | J37: 0 | K37: 0 | L37: 0 | M37: 0 | N37: 0 | O37: 0 | P37: 0 | Q37: 0 | R37: 0 | S37: 0 | T37: 0 | U37: 0 | V37: 0 | W37: 0 | X37: 0 | Y37: 0 | Z37: 0 | AA37: 0
B38: 3.2.3 | C38: 管理费用进项税 | D38: =SUM(F38:AA38) -> 0 | E38: 万元 | H38: =SUM(H39:H40) -> 0 | I38: =SUM(I39:I40) -> 0 | J38: =SUM(J39:J40) -> 0 | K38: =SUM(K39:K40) -> 0 | L38: =SUM(L39:L40) -> 0 | M38: =SUM(M39:M40) -> 0 | N38: =SUM(N39:N40) -> 0 | O38: =SUM(O39:O40) -> 0 | ... AA38: =SUM(AA39:AA40) -> 0
C39: 保险费 | D39: =SUM(F39:AA39) -> 0 | E39: 万元 | H39: ='表3-成本费用表'!H17/(1+参数输入表!$H$124)*参数输入表!$H$124 -> 0 | I39: ='表3-成本费用表'!I17/(1+参数输入表!$H$124)*参数输入表!$H$124 -> 0 | J39: ='表3-成本费用表'!J17/(1+参数输入表!$H$124)*参数输入表!$H$124 -> 0 | K39: ='表3-成本费用表'!K17/(1+参数输入表!$H$124)*参数输入表!$H$124 -> 0 | L39: ='表3-成本费用表'!L17/(1+参数输入表!$H$124)*参数输入表!$H$124 -> 0 | M39: ='表3-成本费用表'!M17/(1+参数输入表!$H$124)*参数输入表!$H$124 -> 0 | N39: ='表3-成本费用表'!N17/(1+参数输入表!$H$124)*参数输入表!$H$124 -> 0 | O39: ='表3-成本费用表'!O17/(1+参数输入表!$H$124)*参数输入表!$H$124 -> 0 | ... AA39: ='表3-成本费用表'!AA17/(1+参数输入表!$H$124)*参数输入表!$H$124 -> 0
C40: 期末拆除费用 | D40: =SUM(F40:AA40) -> 0 | E40: 万元 | H40: ='表3-成本费用表'!H18/(1+参数输入表!$H$144)*参数输入表!$H$144 -> 0 | I40: ='表3-成本费用表'!I18/(1+参数输入表!$H$144)*参数输入表!$H$144 -> 0 | J40: ='表3-成本费用表'!J18/(1+参数输入表!$H$144)*参数输入表!$H$144 -> 0 | K40: ='表3-成本费用表'!K18/(1+参数输入表!$H$144)*参数输入表!$H$144 -> 0 | L40: ='表3-成本费用表'!L18/(1+参数输入表!$H$144)*参数输入表!$H$144 -> 0 | M40: ='表3-成本费用表'!M18/(1+参数输入表!$H$144)*参数输入表!$H$144 -> 0 | N40: ='表3-成本费用表'!N18/(1+参数输入表!$H$144)*参数输入表!$H$144 -> 0 | O40: ='表3-成本费用表'!O18/(1+参数输入表!$H$144)*参数输入表!$H$144 -> 0 | ... AA40: ='表3-成本费用表'!AA18/(1+参数输入表!$H$144)*参数输入表!$H$144 -> 0
B41: 3.2.4 | C41: 研发费用进项税 | D41: =SUM(F41:AA41) -> 0 | E41: 万元 | H41: 0 | I41: 0 | J41: 0 | K41: 0 | L41: 0 | M41: 0 | N41: 0 | O41: 0 | P41: 0 | Q41: 0 | R41: 0 | S41: 0 | T41: 0 | U41: 0 | V41: 0 | W41: 0 | X41: 0 | Y41: 0 | Z41: 0 | AA41: 0
B42: 3.3 | C42: 营业外支出进项税 | D42: =SUM(F42:AA42) -> 0 | E42: 万元 | H42: ='表3-成本费用表'!H62/(1+参数输入表!$H$215)*参数输入表!$H$215 -> 0 | I42: ='表3-成本费用表'!I62/(1+参数输入表!$H$215)*参数输入表!$H$215 -> 0 | J42: ='表3-成本费用表'!J62/(1+参数输入表!$H$215)*参数输入表!$H$215 -> 0 | K42: ='表3-成本费用表'!K62/(1+参数输入表!$H$215)*参数输入表!$H$215 -> 0 | L42: ='表3-成本费用表'!L62/(1+参数输入表!$H$215)*参数输入表!$H$215 -> 0 | M42: ='表3-成本费用表'!M62/(1+参数输入表!$H$215)*参数输入表!$H$215 -> 0 | N42: ='表3-成本费用表'!N62/(1+参数输入表!$H$215)*参数输入表!$H$215 -> 0 | O42: ='表3-成本费用表'!O62/(1+参数输入表!$H$215)*参数输入表!$H$215 -> 0 | ... AA42: ='表3-成本费用表'!AA62/(1+参数输入表!$H$215)*参数输入表!$H$215 -> 0
...

Sheet 表5-利润表-资本金
B2: 利润表-资本金
B3: 序号 | C3: 项目 | D3: 合计 | E3: 单位 | F3: 建设期 | H3: 运营期
F4: 1 | G4: 2 | H4: 1 | I4: 2 | J4: 3 | K4: 4 | L4: 5 | M4: 6 | N4: 7 | O4: 8 | P4: 9 | Q4: 10 | R4: 11 | S4: 12 | T4: 13 | U4: 14 | V4: 15 | W4: 16 | X4: 17 | Y4: 18 | Z4: 19 | AA4: 20
B5: 1 | C5: 营业总收入 | D5: =SUM(F5:AA5) -> 55978.052 | E5: 万元 | H5: =H6+H7 -> 2781.8166 | I5: =I6+I7 -> 2781.8166 | J5: =J6+J7 -> 2781.8166 | K5: =K6+K7 -> 2781.8166 | L5: =L6+L7 -> 2781.8166 | M5: =M6+M7 -> 2804.5979 | N5: =N6+N7 -> 2804.5979 | O5: =O6+O7 -> 2804.5979 | ... AA5: =AA6+AA7 -> 2804.5979
B6: 1.1 | C6: 营业收入 | D6: =SUM(F6:AA6) -> 55978.052 | E6: 万元 | H6: ='表4-收入税金表'!H6 -> 2781.8166 | I6: ='表4-收入税金表'!I6 -> 2781.8166 | J6: ='表4-收入税金表'!J6 -> 2781.8166 | K6: ='表4-收入税金表'!K6 -> 2781.8166 | L6: ='表4-收入税金表'!L6 -> 2781.8166 | M6: ='表4-收入税金表'!M6 -> 2804.5979 | N6: ='表4-收入税金表'!N6 -> 2804.5979 | O6: ='表4-收入税金表'!O6 -> 2804.5979 | ... AA6: ='表4-收入税金表'!AA6 -> 2804.5979
