Workbook

Sheet 说明
B2: 参数输入表中：
C3: 标黄项为相对固定模块
C4: 标绿项为对成本类、收入类数据进行分类，成本参数按照：“生产成本/销售费用/管理费用/研发费用”划分；收入参数按照：“营业收入/其他收入/营业外收入”划分
C5: 标橙项为固定的分类原则
C6: 标紫项为在参数表中不需要手动输入、勾选的内容，根据其他输入参数自动计算得出，可不在参数输入界面呈现。
C7: 标红项为引用同样红色sheet中相关数据
C8: 标蓝项为可不展示内容，大部分为中间过程计算表/中间计算过程
C10: 【成本费用表】、【收入税金表】、【利润表】体现的是会计报表相关数据，涉及到的收入及成本数据均为不含增值税金额，不含税金额计算公式为： 【含税金额/（1+增值税税率）】；增值税计算公式为：【不含税金额*增值税税率】或【含税金额/（1+增值税税率）*增值税税率】
C12: 【成本费用表】中各项成本按照：一、营业总成本：（1）生产成本；（2）销售费用；（3）管理费用；（4）研发费用；（5）财务费用；二、营业外支出，进行划分，其中需重点关注长期待摊费用成本项，在成本费用表中以逐年摊销的形式出现。
C14: 【成本费用表】中标蓝的内容为不展示内容，为中间计算表，其中数据均还原成含税金额，用于后续的【现金流量表】引用
C16: 【收入表】中各项收入按照：一、营业收入；二、其他收入；三、营业外收入，营业收入及营业外收入需展示二级目录（具体的收入项）
C18: 【现金流量表】体现的是公司账上实际收到或支付的现金流，因此涉及到的收入及成本数据均为含增值税金额，数据需引用成本费用表中还原后的含税金额或参数输入表中的含税金额。同时，收入数据需关注付款比例及回款期限的应用。原理为当年的部分比例收入的滞后支付，第一年的某项收入现金流为预测现金流*首年支付比例，第二年的某项收入现金流为：当年预测现金流*当年支付比例+上一年预测现金流*（1-上一年支付比例）
C20: 【现金流量表-财务计划】增加IF判定条件，当某年的累计盈余资金<“流动资金（本项目为960万元）”+次年的“生产经营现金支出合计（成本费用表标蓝表第一行）”，给出明显提示（允许用户在参数输入界面填写各年度短期借款当期借款金额及还本金额，再重新生成新的结果）

Sheet 可抵扣进项税
B2: 投资概算 | C2: 序号 | D2: 科目 | E2: 计取基数 | F2: 进项税率 | G2: 进项税
C3: 1 | D3: 设备购置费 | E3: =参数输入表!H106 -> 15000 | F3: =参数输入表!H353 -> 0.13 | G3: =E3/(1+F3)*F3 -> 1725.6637
C4: 2 | D4: 建安工程费 | E4: =参数输入表!H107 -> 4000 | F4: =参数输入表!H354 -> 0.09 | G4: =E4/(1+F4)*F4 -> 330.27523
C5: 3 | D5: 其他费用 | E5: =参数输入表!H108 -> 4000 | F5: =参数输入表!H355 -> 0.06 | G5: =E5/(1+F5)*F5 -> 226.41509
C6: 4 | D6: 预备费 | E6: =参数输入表!H109 -> 400 | F6: =参数输入表!H356 -> 0 | G6: =E6/(1+F6)*F6 -> 0
C7: 5 | D7: 储能投资 | E7: =参数输入表!H110 -> 500 | F7: =参数输入表!H357 -> 0.13 | G7: =E7/(1+F7)*F7 -> 57.522124
C8: 6 | D8: 送出线路投资 | E8: =参数输入表!H111 -> 2800 | F8: =参数输入表!H358 -> 0.09 | G8: =E8/(1+F8)*F8 -> 231.19266
C9: 7 | D9: 配套支持资金 | E9: =参数输入表!H112 -> 0 | F9: =参数输入表!H359 -> 0 | G9: =E9/(1+F9)*F9 -> 0
C10: 8 | D10: 静态总投资 | E10: =参数输入表!H113 -> 26700
C11: 9 | D11: 建设期利息 | E11: =参数输入表!H115 -> 383.10084
C12: 10 | D12: 动态总投资 | E12: =参数输入表!H116 -> 27083.101
C13: 11 | D13: 流动资金 | E13: =参数输入表!H118 -> 240
C14: 12 | D14: 可抵扣进项税 | E14: =SUM(G3:G9) -> 2571.0688
C18: 可抵扣进项税为后台计算，不需要作为成果展示

Sheet 参数输入表
G1: 【光伏】财务评价计算模型边界条件输入参数表
B3: 类别 | C3: 序号 | D3: 参数 | E3: 操作类型 | F3: 收入/成本归类 | G3: 参数释义/计算公式 | H3: 数值 | I3: 单位 | J3: 取值说明 | K3: 备注
B4: 基础信息 | C4: 1 | D4: 建设期 | E4: 手动输入 | H4: 12 | I4: 月 | J4: 在初核阶段，不含升压站的集中式光伏项目建设期一般按5个月计算，含升压站的按7个月计算，屋顶分布式项目、大型基地项目根据实际情况调整。
C5: 2 | D5: 动工年月 | E5: 手动输入/下拉菜单选择【日历】 | I5: 年/月
C6: 3 | D6: 施工进度安排 | I6: %
D7: 建设期第1年 | E7: 手动输入 | H7: 1
D8: 建设期第2年 | E8: 手动输入 | H8: =1-H7 -> 0
C9: 4 | D9: 运营期 | E9: 手动输入 | H9: 25 | I9: 年 | J9: 原则上按照25年考虑
C10: 5 | D10: 项目所在地 | E10: 下拉菜单选择 | J10: 判定是否属于西部地区
D11: 所在省份 | E11: 下拉菜单选择
D12: 所在市、县 | E12: 下拉菜单选择
D13: 实际装机容量 | E13: 手动输入 | H13: 80 | I13: MW | J13: 1MW=1000kW
D14: 储能额定功率 | E14: 手动输入 | H14: 10 | I14: MW
D15: 储能容量 | E15: 手动输入 | H15: 20 | I15: MWh
D16: 首年年利用小时数 | E16: 手动输入 | H16: 1200 | I16: h
D17: 发电量 | E17: 自动计算 | G17: 各年上网电量=（（首年年利用小时数*实际装机容量*各年衰减系数） | I17: MWh | J17: 1MWh=0.1万度电
D18: 衰减率（首年） | E18: 手动输入 | H18: 0.01 | I18: %
D19: 衰减率（其他年） | E19: 手动输入 | H19: 0.0045 | I19: %
D20: 限电率 | E20: 手动输入 | H20: 0.054 | I20: %
D21: 运营期第1年 | E21: 自动计算 | H21: =$H$13*$H$16*(1-$H$18) -> 95040
D22: 运营期第2年 | E22: 自动计算 | H22: =H21*(1-$H$19) -> 94612.32
D23: 运营期第3年 | E23: 自动计算 | H23: =H22*(1-$H$19) -> 94186.565
D24: 运营期第4年 | E24: 自动计算 | H24: =H23*(1-$H$19) -> 93762.725
D25: 运营期第5年 | E25: 自动计算 | H25: =H24*(1-$H$19) -> 93340.793
D26: 运营期第6年 | E26: 自动计算 | H26: =H25*(1-$H$19) -> 92920.759
D27: 运营期第7年 | E27: 自动计算 | H27: =H26*(1-$H$19) -> 92502.616
D28: 运营期第8年 | E28: 自动计算 | H28: =H27*(1-$H$19) -> 92086.354
D29: 运营期第9年 | E29: 自动计算 | H29: =H28*(1-$H$19) -> 91671.965
D30: 运营期第10年 | E30: 自动计算 | H30: =H29*(1-$H$19) -> 91259.442
D31: 运营期第11年 | E31: 自动计算 | H31: =H30*(1-$H$19) -> 90848.774
D32: 运营期第12年 | E32: 自动计算 | H32: =H31*(1-$H$19) -> 90439.955
D33: 运营期第13年 | E33: 自动计算 | H33: =H32*(1-$H$19) -> 90032.975
... D45: 运营期第25年 | E45: 自动计算 | H45: =H44*(1-$H$19) -> 85289.736
D46: 上网电量 | G46: 各年上网电量=（（首年年利用小时数*实际装机容量*各年衰减系数）-数能融合消纳电量）*（1-限电率）
D47: 运营期第1年 | E47: 自动计算 | H47: =IF((H21*(1-H77)*(1-$H$20))>0,H21*(1-H77)*(1-$H$20),0) -> 44953.92
D48: 运营期第2年 | E48: 自动计算 | H48: =IF((H22*(1-H78)*(1-$H$20))>0,H22*(1-H78)*(1-$H$20),0) -> 44751.627
D49: 运营期第3年 | E49: 自动计算 | H49: =IF((H23*(1-H79)*(1-$H$20))>0,H23*(1-H79)*(1-$H$20),0) -> 44550.245
D50: 运营期第4年 | E50: 自动计算 | H50: =IF((H24*(1-H80)*(1-$H$20))>0,H24*(1-H80)*(1-$H$20),0) -> 44349.769
D51: 运营期第5年 | E51: 自动计算 | H51: =IF((H25*(1-H81)*(1-$H$20))>0,H25*(1-H81)*(1-$H$20),0) -> 44150.195
D52: 运营期第6年 | E52: 自动计算 | H52: =IF((H26*(1-H82)*(1-$H$20))>0,H26*(1-H82)*(1-$H$20),0) -> 26370.911
...

Sheet 表1-资金筹措及还本付息表
B2: 资金筹措表
B3: 序号 | C3: 建设期 | D3: 合计 | E3: 单位 | F3: 建设期 | H3: 运营期
F4: 1 | G4: 2 | H4: 1 | I4: 2 | J4: 3 | K4: 4 | L4: 5 | M4: 6 | N4: 7 | O4: 8 | P4: 9 | Q4: 10 | R4: 11 | S4: 12 | T4: 13 | U4: 14 | V4: 15 | W4: 16 | X4: 17 | Y4: 18 | Z4: 19 | AA4: 20 | AB4: 21 | AC4: 22 | AD4: 23 | AE4: 24 | AF4: 25
C5: 施工进度安排 | D5: =SUM(F5:M5) -> 1 | F5: =参数输入表!H7 -> 1 | G5: =参数输入表!H8 -> 0
B6: 1 | C6: 动态总投资（自主投资） | D6: =D7+D8+D9 -> 27323.101 | E6: 万元 | F6: =SUM(F7:F9) -> 27083.101 | G6: =SUM(G7:G9) -> 0 | H6: =SUM(H7:H9) -> 240
B7: 1.1 | C7: 静态总投资（自主投资） | D7: =SUM(F7:AF7) -> 26700 | E7: 万元 | F7: =参数输入表!$H$114*F5 -> 26700 | G7: =参数输入表!$H$114*G5 -> 0 | H7: 0
B8: 1.2 | C8: 建设期利息 | D8: =SUM(F8:AF8) -> 383.10084 | E8: 万元 | F8: =F17 -> 383.10084 | G8: =G17 -> 0 | H8: =H17 -> 0
B9: 1.3 | C9: 流动资金 | D9: =SUM(F9:AF9) -> 240 | E9: 万元 | F9: 0 | G9: 0 | H9: =参数输入表!H118 -> 240
B10: 2 | C10: 资金来源
B11: 2.1 | C11: 资本金 | D11: =SUM(F11:AF11) -> 5488.6202 | E11: 万元 | F11: =F6*参数输入表!$H$122 -> 5416.6202 | G11: =G6*参数输入表!$H$122 -> 0 | H11: =H6*参数输入表!$H$130 -> 72
B12: 2.1.1 | C12: 用于建设投资 | D12: =SUM(F12:AF12) -> 5416.6202 | E12: 万元 | F12: =F11-F13-F14 -> 5416.6202 | G12: =G11-G13-G14 -> 0 | H12: 0
B13: 2.1.2 | C13: 用于建设期利息 | D13: =SUM(F13:AF13) -> 0 | E13: 万元 | F13: 0 | G13: 0 | H13: 0
B14: 2.1.3 | C14: 用于流动资金 | D14: =SUM(F14:AF14) -> 72 | F14: 0 | G14: 0 | H14: =H9*参数输入表!H130 -> 72
B15: 2.2 | C15: 债务资金 | D15: =SUM(F15:M15) -> 21834.481 | E15: 万元 | F15: =SUM(F16:F18) -> 21666.481 | G15: =SUM(G16:G18) -> 0 | H15: =SUM(H16:H18) -> 168
B16: 2.2.1 | C16: 用于建设投资 | D16: =SUM(F16:AF16) -> 21283.38 | E16: 万元 | F16: =F7-F12 -> 21283.38 | G16: =G7-G12 -> 0 | H16: =H7-H12 -> 0
B17: 2.1.2 | C17: 用于建设期利息 | D17: =SUM(F17:AF17) -> 383.10084 | E17: 万元 | F17: =F16/2*参数输入表!$H$125 -> 383.10084 | G17: =IF(G5=0,0,(G16/2+F15)*参数输入表!$H$125) -> 0 | H17: 0
B18: 2.1.3 | C18: 用于流动资金 | D18: =SUM(F18:AF18) -> 168 | E18: 万元 | F18: 0 | G18: 0 | H18: =H9-H14 -> 168
B20: 营运资本变动
B21: 序号 | C21: 项目 | D21: 合计 | E21: 单位 | F21: 建设期 | H21: 运营期
F22: 1 | G22: 2 | H22: 1 | I22: 2 | J22: 3 | K22: 4 | L22: 5 | M22: 6 | N22: 7 | O22: 8 | P22: 9 | Q22: 10 | R22: 11 | S22: 12 | T22: 13 | U22: 14 | V22: 15 | W22: 16 | X22: 17 | Y22: 18 | Z22: 19 | AA22: 20 | AB22: 21 | AC22: 22 | AD22: 23 | AE22: 24 | AF22: 25
B23: 1 | C23: 流动资产 | D23: =SUM(F23:AF23) -> 177422.2 | E23: 万元 | F23: =SUM(F24:F27) -> 2571.0688 | G23: =SUM(G24:G27) -> 2571.0688 | H23: =SUM(H24:H27) -> 2725.4621 | I23: =SUM(I24:I27) -> 2880.1027 | J23: =SUM(J24:J27) -> 3038.851 | K23: =SUM(K24:K27) -> 3137.3603 | L23: =SUM(L24:L27) -> 3246.6568 | M23: =SUM(M24:M27) -> 3442.3133 | ... AF23: =SUM(AF24:AF27) -> 16347.897
C24: 货币资金 | D24: =SUM(F24:AF24) -> 164987.55 | E24: 万元 | F24: ='表9-现金流量表-财务计划'!F34 -> 0 | G24: ='表9-现金流量表-财务计划'!G34 -> 0 | H24: ='表9-现金流量表-财务计划'!H34 -> 543.73516 | I24: ='表9-现金流量表-财务计划'!I34 -> 1085.9656 | J24: ='表9-现金流量表-财务计划'!J34 -> 1630.5595 | K24: ='表9-现金流量表-财务计划'!K34 -> 2113.1783 | L24: ='表9-现金流量表-财务计划'!L34 -> 2604.8556 | M24: ='表9-现金流量表-财务计划'!M34 -> 3199.9482 | ... AF24: ='表9-现金流量表-财务计划'!AF34 -> 16347.897
C25: 应收账款 | D25: =SUM(F25:AF25) -> 0 | E25: 万元 | H25: ='表4-收入税金表'!H60 -> 0 | I25: ='表4-收入税金表'!I60 -> 0 | J25: ='表4-收入税金表'!J60 -> 0 | K25: ='表4-收入税金表'!K60 -> 0 | L25: ='表4-收入税金表'!L60 -> 0 | M25: ='表4-收入税金表'!M60 -> 0 | N25: ='表4-收入税金表'!N60 -> 0 | O25: ='表4-收入税金表'!O60 -> 0 | ... AF25: ='表4-收入税金表'!AF60 -> 0
C26: 存货 | D26: =SUM(F26:AF26) -> 0 | E26: 万元
C27: 其他流动资产（留抵税额） | D27: =SUM(F27:AF27) -> 12434.641 | E27: 万元 | F27: ='表4-收入税金表'!F45 -> 2571.0688 | G27: ='表4-收入税金表'!G45 -> 2571.0688 | H27: ='表4-收入税金表'!H45 -> 2181.727 | I27: ='表4-收入税金表'!I45 -> 1794.1371 | J27: ='表4-收入税金表'!J45 -> 1408.2914 | K27: ='表4-收入税金表'!K45 -> 1024.1821 | L27: ='表4-收入税金表'!L45 -> 641.80118 | M27: ='表4-收入税金表'!M45 -> 242.3651 | ... AF27: ='表4-收入税金表'!AF45 -> 0
B28: 2 | C28: 流动负债 | D28: =SUM(F28:AF28) -> 25054.411 | E28: 万元 | F28: =SUM(F29:F34) -> 0 | G28: =SUM(G29:G34) -> 0 | H28: =SUM(H29:H34) -> 345.3729 | I28: =SUM(I29:I34) -> 215.64797 | J28: =SUM(J29:J34) -> 250.12324 | K28: =SUM(K29:K34) -> 349.0055 | L28: =SUM(L29:L34) -> 376.92188 | M28: =SUM(M29:M34) -> 422.4973 | ... AF28: =SUM(AF29:AF34) -> 1860.7837
C29: 短期借款 | D29: =SUM(F29:AF29) -> 168 | E29: 万元 | F29: =F64+F74 -> 0 | G29: =G60+G70 -> 0 | H29: =H60+H70 -> 168 | I29: =I60+I70 -> 0 | J29: =J60+J70 -> 0 | K29: =K60+K70 -> 0 | L29: =L60+L70 -> 0 | M29: =M60+M70 -> 0 | N29: =N60+N70 -> 0 | ... AF29: =AF60+AF70 -> 0
C30: 预收款项 | D30: =SUM(F30:AF30) -> 0 | E30: 万元
C31: 应付职工薪酬 | D31: =SUM(F31:AF31) -> 3360 | E31: 万元 | H31: ='表3-成本费用表'!H52 -> 134.4 | I31: ='表3-成本费用表'!I52 -> 134.4 | J31: ='表3-成本费用表'!J52 -> 134.4 | K31: ='表3-成本费用表'!K52 -> 134.4 | L31: ='表3-成本费用表'!L52 -> 134.4 | M31: ='表3-成本费用表'!M52 -> 134.4 | N31: ='表3-成本费用表'!N52 -> 134.4 | O31: ='表3-成本费用表'!O52 -> 134.4 | ... AF31: ='表3-成本费用表'!AF52 -> 134.4
C32: 应交税费 | D32: =SUM(F32:AF32) -> 13678.242 | E32: 万元 | H32: ='表6-现金流量表-资本金'!H24+'表6-现金流量表-资本金'!H25+'表6-现金流量表-资本金'!H29 -> 0 | I32: ='表6-现金流量表-资本金'!I24+'表6-现金流量表-资本金'!I25+'表6-现金流量表-资本金'!I29 -> 0 | J32: ='表6-现金流量表-资本金'!J24+'表6-现金流量表-资本金'!J25+'表6-现金流量表-资本金'!J29 -> 0 | K32: ='表6-现金流量表-资本金'!K24+'表6-现金流量表-资本金'!K25+'表6-现金流量表-资本金'!K29 -> 74.153174 | L32: ='表6-现金流量表-资本金'!L24+'表6-现金流量表-资本金'!L25+'表6-现金流量表-资本金'!L29 -> 78.991107 | M32: ='表6-现金流量表-资本金'!M24+'表6-现金流量表-资本金'!M25+'表6-现金流量表-资本金'!M29 -> 95.483049 | N32: ='表6-现金流量表-资本金'!N24+'表6-现金流量表-资本金'!N25+'表6-现金流量表-资本金'!N29 -> 369.75747 | O32: ='表6-现金流量表-资本金'!O24+'表6-现金流量表-资本金'!O25+'表6-现金流量表-资本金'!O29 -> 641.54379 | ... AF32: ='表6-现金流量表-资本金'!AF24+'表6-现金流量表-资本金'!AF25+'表6-现金流量表-资本金'!AF29 -> 910.14848
C33: 应付股利 | D33: =SUM(F33:AF33) -> 7848.1691 | E33: 万元 | H33: ='表5-利润表-资本金'!H31 -> 42.972905 | I33: ='表5-利润表-资本金'!I31 -> 81.247968 | J33: ='表5-利润表-资本金'!J31 -> 115.72324 | K33: ='表5-利润表-资本金'!K31 -> 140.45232 | L33: ='表5-利润表-资本金'!L31 -> 163.53078 | M33: ='表5-利润表-资本金'!M31 -> 192.61425 | N33: ='表5-利润表-资本金'!N31 -> 208.89735 | O33: ='表5-利润表-资本金'!O31 -> 222.71886 | ... AF33: ='表5-利润表-资本金'!AF31 -> 816.23524
C34: 其他流动负债 | D34: =SUM(F34:AF34) -> 0 | E34: 万元
B36: 借款还本付息表（长期借款）
B37: 序号 | C37: 项目 | D37: 合计 | E37: 单位 | F37: 建设期 | H37: 运营期
F38: 1 | G38: 2 | H38: 1 | I38: 2 | J38: 3 | K38: 4 | L38: 5 | M38: 6 | N38: 7 | O38: 8 | P38: 9 | Q38: 10 | R38: 11 | S38: 12 | T38: 13 | U38: 14 | V38: 15 | W38: 16 | X38: 17 | Y38: 18 | Z38: 19 | AA38: 20 | AB38: 21 | AC38: 22 | AD38: 23 | AE38: 24 | AF38: 25
B39: 1 | C39: 期初借款累计 | E39: 万元 | F39: 0 | G39: =F44 -> 21666.481 | H39: =G44 -> 21666.481 | I39: =H44 -> 20551.877 | J39: =I44 -> 19397.147 | K39: =J44 -> 18200.847 | L39: =K44 -> 16961.48 | M39: =L44 -> 15677.497 | N39: =M44 -> 14347.289 | ... AF39: =AE44 -> 0
B40: 2 | C40: 当期借款 | D40: =SUM(F40:AF40) -> 21666.481 | E40: 万元 | F40: =F15 -> 21666.481 | G40: =G15 -> 0
B41: 3 | C41: 当期还本付息 | D41: =SUM(F41:AF41) -> 28418.958 | E41: 万元 | H41: =-PMT(参数输入表!$H$126,参数输入表!$H$129,'表1-资金筹措及还本付息表'!$D$40) -> 1894.5972 | I41: =-PMT(参数输入表!$H$126,参数输入表!$H$129,'表1-资金筹措及还本付息表'!$D$40) -> 1894.5972 | J41: =-PMT(参数输入表!$H$126,参数输入表!$H$129,'表1-资金筹措及还本付息表'!$D$40) -> 1894.5972 | K41: =-PMT(参数输入表!$H$126,参数输入表!$H$129,'表1-资金筹措及还本付息表'!$D$40) -> 1894.5972 | L41: =-PMT(参数输入表!$H$126,参数输入表!$H$129,'表1-资金筹措及还本付息表'!$D$40) -> 1894.5972 | M41: =-PMT(参数输入表!$H$126,参数输入表!$H$129,'表1-资金筹措及还本付息表'!$D$40) -> 1894.5972 | N41: =-PMT(参数输入表!$H$126,参数输入表!$H$129,'表1-资金筹措及还本付息表'!$D$40) -> 1894.5972 | O41: =-PMT(参数输入表!$H$126,参数输入表!$H$129,'表1-资金筹措及还本付息表'!$D$40) -> 1894.5972 | ... V41: =-PMT(参数输入表!$H$126,参数输入表!$H$129,'表1-资金筹措及还本付息表'!$D$40) -> 1894.5972
C42: 其中：还本（等额本息） | D42: =SUM(F42:AF42) -> 21666.481 | E42: 万元 | H42: =H41-H43 -> 1114.6039 | I42: =I41-I43 -> 1154.7297 | J42: =J41-J43 -> 1196.2999 | K42: =K41-K43 -> 1239.3667 | L42: =L41-L43 -> 1283.9839 | M42: =M41-M43 -> 1330.2073 | N42: =N41-N43 -> 1378.0948 | O42: =O41-O43 -> 1427.7062 | ... V42: =V41-V43 -> 1828.7618
C43: 付息 | D43: =SUM(F43:AF43) -> 6752.4776 | E43: 万元 | H43: =(H39+H40/2)*参数输入表!$H$126 -> 779.9933 | I43: =(I39+I40/2)*参数输入表!$H$126 -> 739.86756 | J43: =(J39+J40/2)*参数输入表!$H$126 -> 698.2973 | K43: =(K39+K40/2)*参数输入表!$H$126 -> 655.2305 | L43: =(L39+L40/2)*参数输入表!$H$126 -> 610.6133 | M43: =(M39+M40/2)*参数输入表!$H$126 -> 564.38987 | N43: =(N39+N40/2)*参数输入表!$H$126 -> 516.50241 | O43: =(O39+O40/2)*参数输入表!$H$126 -> 466.891 | ... V43: =(V39+V40/2)*参数输入表!$H$126 -> 65.835425
...

Sheet 表2-折旧摊销表
C1: 中间过程引用（隐藏）
C2: 动态总投资（自主投资_不含流动资金） | D2: =参数输入表!H117 -> 27083.101
C3: 可抵扣进项税 | D3: =参数输入表!H120 -> 2571.0688
C4: 固定资产原值 | D4: =D2-D15-D3 -> 24512.032 | F4: 固定资产原值=项目动态总投资（自主投资_不含流动资金）-可抵扣进项税-无形资产原值=项目静态总投资-建设补贴+建设期利息-可抵扣进项税-无形资产原值
C5: 折旧方式 | D5: 直线法/其他
C6: 折旧年限 | D6: =参数输入表!H197 -> 20
C7: 残值率 | D7: =参数输入表!H198 -> 0.05
C8: 长期待摊费用（第1年） | D8: =参数输入表!H206/(1+参数输入表!H233) -> 0 | F8: 长期待摊费用=计入长期待摊的成本项/（1+增值税税率）
C9: 长期待摊费用（第6年） | D9: =参数输入表!H211/(1+参数输入表!H233) -> 0
C10: 长期待摊费用（第11年） | D10: =参数输入表!H216/(1+参数输入表!H233) -> 0
C11: 长期待摊费用（第16年） | D11: =参数输入表!H221/(1+参数输入表!H233) -> 0
C12: 长期待摊费用（第21年） | D12: =参数输入表!H226/(1+参数输入表!H233) -> 0
C13: 摊销方式 | D13: 直线法/其他 | H13: =D4*0.95/20 -> 1164.3215
C14: 摊销年限 | D14: =参数输入表!H232 -> 5
C15: 无形资产原值 | D15: =参数输入表!H200 -> 0
C16: 摊销方式 | D16: 直线法/其他
C17: 摊销年限 | D17: =参数输入表!H202 -> 10
C18: 残值率 | D18: =参数输入表!H203 -> 0
C19: 大修及更新重置资产原值 | D19: =参数输入表!H245/(1+参数输入表!$H$264) -> 0
C20: 摊销方式 | D20: 直线法/其他
C21: 摊销年限 | D21: =参数输入表!H262 -> 10
C22: 残值率 | D22: =参数输入表!H263 -> 0.05
B24: 折旧摊销表-资本金
B25: 序号 | C25: 科目 | D25: 合计 | E25: 单位 | F25: 建设期 | H25: 运营期
F26: 1 | G26: 2 | H26: 1 | I26: 2 | J26: 3 | K26: 4 | L26: 5 | M26: 6 | N26: 7 | O26: 8 | P26: 9 | Q26: 10 | R26: 11 | S26: 12 | T26: 13 | U26: 14 | V26: 15 | W26: 16 | X26: 17 | Y26: 18 | Z26: 19 | AA26: 20 | AB26: 21 | AC26: 22 | AD26: 23 | AE26: 24 | AF26: 25
B27: 1 | C27: 固定资产净值 | E27: 万元 | F27: =D28 -> 23286.43 | G27: =IF('表1-资金筹措及还本付息表'!G5=0,0,'表1-资金筹措及还本付息表'!F6+'表1-资金筹措及还本付息表'!G6-参数输入表!H120-参数输入表!H200) -> 0 | H27: =IF('表1-资金筹措及还本付息表'!G5=0,F27-H28,G27-H28) -> 22122.109 | I27: =H27-I28 -> 20957.787 | J27: =I27-J28 -> 19793.466 | K27: =J27-K28 -> 18629.144 | L27: =K27-L28 -> 17464.823 | M27: =L27-M28 -> 16300.501 | N27: =M27-N28 -> 15136.18 | O27: =N27-O28 -> 13971.858 | P27: =O27-P28 -> 12807.537 | ... AF27: =AE27-AF28 -> -1.8189894e-12
C28: 当期固定资产折旧 | D28: =SUM(F28:AF28) -> 23286.43 | E28: 万元 | H28: =IF(H26<=$D$6,$D$4*(1-$D$7)/($D$6),0) -> 1164.3215 | I28: =IF(I26<=$D$6,$D$4*(1-$D$7)/($D$6),0) -> 1164.3215 | J28: =IF(J26<=$D$6,$D$4*(1-$D$7)/($D$6),0) -> 1164.3215 | K28: =IF(K26<=$D$6,$D$4*(1-$D$7)/($D$6),0) -> 1164.3215 | L28: =IF(L26<=$D$6,$D$4*(1-$D$7)/($D$6),0) -> 1164.3215 | M28: =IF(M26<=$D$6,$D$4*(1-$D$7)/($D$6),0) -> 1164.3215 | N28: =IF(N26<=$D$6,$D$4*(1-$D$7)/($D$6),0) -> 1164.3215 | O28: =IF(O26<=$D$6,$D$4*(1-$D$7)/($D$6),0) -> 1164.3215 | ... AF28: =IF(AF26<=$D$6,$D$4*(1-$D$7)/($D$6),0) -> 0
B29: 2 | C29: 期初长期待摊费用 | E29: 万元 | H29: 0 | I29: =H32 -> 0 | J29: =I32 -> 0 | K29: =J32 -> 0 | L29: =K32 -> 0 | M29: =L32 -> 0 | N29: =M32 -> 0 | O29: =N32 -> 0 | P29: =O32 -> 0 | ... AF29: =AE32 -> 0
C30: 当期新增长期待摊费用 | H30: =参数输入表!H206/(1+参数输入表!H233) -> 0 | I30: =参数输入表!H207/(1+参数输入表!H233) -> 0 | J30: =参数输入表!H208/(1+参数输入表!H233) -> 0 | K30: =参数输入表!H209/(1+参数输入表!H233) -> 0 | L30: =参数输入表!H210/(1+参数输入表!H233) -> 0 | M30: =参数输入表!H211/(1+参数输入表!H233) -> 0 | N30: =参数输入表!H212/(1+参数输入表!H233) -> 0 | O30: =参数输入表!H213/(1+参数输入表!H233) -> 0 | P30: =参数输入表!H214/(1+参数输入表!H233) -> 0 | Q30: =参数输入表!H215/(1+参数输入表!H233) -> 0 | R30: =参数输入表!H216/(1+参数输入表!H233) -> 0 | S30: =参数输入表!H217/(1+参数输入表!H233) -> 0 | T30: =参数输入表!H218/(1+参数输入表!H233) -> 0 | U30: =参数输入表!H219/(1+参数输入表!H233) -> 0 | V30: =参数输入表!H220/(1+参数输入表!H233) -> 0 | W30: =参数输入表!H221/(1+参数输入表!H233) -> 0 | X30: =参数输入表!H222/(1+参数输入表!H233) -> 0 | Y30: =参数输入表!H223/(1+参数输入表!H233) -> 0 | Z30: =参数输入表!H224/(1+参数输入表!H233) -> 0 | AA30: =参数输入表!H225/(1+参数输入表!H233) -> 0 | AB30: =参数输入表!H226/(1+参数输入表!H233) -> 0 | AC30: =参数输入表!H227/(1+参数输入表!H233) -> 0 | AD30: =参数输入表!H228/(1+参数输入表!H233) -> 0 | AE30: =参数输入表!H229/(1+参数输入表!H233) -> 0 | AF30: =参数输入表!H230/(1+参数输入表!H233) -> 0
C31: 当期摊销 | D31: =SUM(F31:AF31) -> 0 | E31: 万元 | H31: =H30/$D$14 -> 0 | I31: =H31 -> 0 | J31: =I31 -> 0 | K31: =J31 -> 0 | L31: =K31 -> 0 | M31: =M30/$D$14 -> 0 | N31: =M31 -> 0 | O31: =N31 -> 0 | P31: =O31 -> 0 | Q31: =P31 -> 0 | R31: =R30/$D$14 -> 0 | S31: =R31 -> 0 | T31: =S31 -> 0 | U31: =T31 -> 0 | V31: =U31 -> 0 | W31: =W30/$D$14 -> 0 | X31: =W31 -> 0 | Y31: =X31 -> 0 | Z31: =Y31 -> 0 | AA31: =Z31 -> 0 | AB31: =AB30/$D$14 -> 0 | AC31: =AB31 -> 0 | AD31: =AC31 -> 0 | AE31: =AD31 -> 0 | AF31: =AE31 -> 0
C32: 期末期初长期待摊费用 | H32: =H29+H30-H31 -> 0 | I32: =I29+I30-I31 -> 0 | J32: =J29+J30-J31 -> 0 | K32: =K29+K30-K31 -> 0 | L32: =L29+L30-L31 -> 0 | M32: =M29+M30-M31 -> 0 | N32: =N29+N30-N31 -> 0 | O32: =O29+O30-O31 -> 0 | ... AF32: =AF29+AF30-AF31 -> 0
B33: 3 | C33: 无形资产净值 | E33: 万元 | F33: =参数输入表!$H$200*参数输入表!$H$7 -> 0 | G33: =参数输入表!$H$200*参数输入表!$H$7+参数输入表!$H$200*参数输入表!$H$8 -> 0 | H33: =G33-H34 -> 0 | I33: =H33-I34 -> 0 | J33: =I33-J34 -> 0 | K33: =J33-K34 -> 0 | L33: =K33-L34 -> 0 | M33: =L33-M34 -> 0 | N33: =M33-N34 -> 0 | O33: =N33-O34 -> 0 | ... AF33: =AE33-AF34 -> 0
C34: 当期无形资产摊销 | D34: =SUM(F34:AF34) -> 0 | E34: 万元 | H34: =IF(H26<=$D$17,G33*(1-$D$18)/($D$17-H26+1),0) -> 0 | I34: =IF(I26<=$D$17,H33*(1-$D$18)/($D$17-I26+1),0) -> 0 | J34: =IF(J26<=$D$17,I33*(1-$D$18)/($D$17-J26+1),0) -> 0 | K34: =IF(K26<=$D$17,J33*(1-$D$18)/($D$17-K26+1),0) -> 0 | L34: =IF(L26<=$D$17,K33*(1-$D$18)/($D$17-L26+1),0) -> 0 | M34: =IF(M26<=$D$17,L33*(1-$D$18)/($D$17-M26+1),0) -> 0 | N34: =IF(N26<=$D$17,M33*(1-$D$18)/($D$17-N26+1),0) -> 0 | O34: =IF(O26<=$D$17,N33*(1-$D$18)/($D$17-O26+1),0) -> 0 | ... AF34: =IF(AF26<=$D$17,AE33*(1-$D$18)/($D$17-AF26+1),0) -> 0
B35: 4 | C35: 期初大修及更新重置资产净值 | E35: 万元 | H35: 0 | I35: =H38 -> 0 | J35: =I38 -> 0 | K35: =J38 -> 0 | L35: =K38 -> 0 | M35: =L38 -> 0 | N35: =M38 -> 0 | O35: =N38 -> 0 | P35: =O38 -> 0 | ... AF35: =AE38 -> 21.238938
C36: 当期新增大修及更新重置资产 | H36: =参数输入表!H236/(1+参数输入表!$H$264) -> 0 | I36: =参数输入表!H237/(1+参数输入表!$H$264) -> 0 | J36: =参数输入表!H238/(1+参数输入表!$H$264) -> 0 | K36: =参数输入表!H239/(1+参数输入表!$H$264) -> 0 | L36: =参数输入表!H240/(1+参数输入表!$H$264) -> 0 | M36: =参数输入表!H241/(1+参数输入表!$H$264) -> 0 | N36: =参数输入表!H242/(1+参数输入表!$H$264) -> 0 | O36: =参数输入表!H243/(1+参数输入表!$H$264) -> 0 | P36: =参数输入表!H244/(1+参数输入表!$H$264) -> 0 | Q36: =参数输入表!H245/(1+参数输入表!$H$264) -> 0 | R36: =参数输入表!H246/(1+参数输入表!$H$264) -> 424.77876 | S36: =参数输入表!H247/(1+参数输入表!$H$264) -> 0 | T36: =参数输入表!H248/(1+参数输入表!$H$264) -> 0 | U36: =参数输入表!H249/(1+参数输入表!$H$264) -> 0 | V36: =参数输入表!H250/(1+参数输入表!$H$264) -> 0 | W36: =参数输入表!H251/(1+参数输入表!$H$264) -> 0 | X36: =参数输入表!H252/(1+参数输入表!$H$264) -> 0 | Y36: =参数输入表!H253/(1+参数输入表!$H$264) -> 0 | Z36: =参数输入表!H254/(1+参数输入表!$H$264) -> 0 | AA36: =参数输入表!H255/(1+参数输入表!$H$264) -> 0 | AB36: =参数输入表!H256/(1+参数输入表!$H$264) -> 0 | AC36: =参数输入表!H257/(1+参数输入表!$H$264) -> 0 | AD36: =参数输入表!H258/(1+参数输入表!$H$264) -> 0 | AE36: =参数输入表!H259/(1+参数输入表!$H$264) -> 0 | AF36: =参数输入表!H260/(1+参数输入表!$H$264) -> 0
C37: 当期大修及更新重置资产折旧摊销 | D37: =SUM(F37:AF37) -> 403.53982 | E37: 万元 | H37: 0 | I37: 0 | J37: 0 | K37: 0 | L37: 0 | M37: 0 | N37: 0 | O37: 0 | P37: 0 | Q37: =Q36/D21 -> 0 | R37: =IF(参数输入表!$H$262>(R26-$R$26),$R$36*(1-参数输入表!$H$263)/参数输入表!$H$262,0) -> 40.353982 | S37: =IF(参数输入表!$H$262>(S26-$R$26),$R$36*(1-参数输入表!$H$263)/参数输入表!$H$262,0) -> 40.353982 | T37: =IF(参数输入表!$H$262>(T26-$R$26),$R$36*(1-参数输入表!$H$263)/参数输入表!$H$262,0) -> 40.353982 | U37: =IF(参数输入表!$H$262>(U26-$R$26),$R$36*(1-参数输入表!$H$263)/参数输入表!$H$262,0) -> 40.353982 | V37: =IF(参数输入表!$H$262>(V26-$R$26),$R$36*(1-参数输入表!$H$263)/参数输入表!$H$262,0) -> 40.353982 | W37: =IF(参数输入表!$H$262>(W26-$R$26),$R$36*(1-参数输入表!$H$263)/参数输入表!$H$262,0) -> 40.353982 | X37: =IF(参数输入表!$H$262>(X26-$R$26),$R$36*(1-参数输入表!$H$263)/参数输入表!$H$262,0) -> 40.353982 | Y37: =IF(参数输入表!$H$262>(Y26-$R$26),$R$36*(1-参数输入表!$H$263)/参数输入表!$H$262,0) -> 40.353982 | ... AB37: =IF(参数输入表!$H$262>(AB26-$R$26),$R$36*(1-参数输入表!$H$263)/参数输入表!$H$262,0) -> 0 | AC37: =IF(参数输入表!$H$262>=(AC26-$R$26),$R$36*(1-参数输入表!$H$263)/参数输入表!$H$262,0) -> 0 | AD37: =IF(参数输入表!$H$262>=(AD26-$R$26),$R$36*(1-参数输入表!$H$263)/参数输入表!$H$262,0) -> 0 | AE37: =IF(参数输入表!$H$262>=(AE26-$R$26),$R$36*(1-参数输入表!$H$263)/参数输入表!$H$262,0) -> 0 | AF37: =IF(参数输入表!$H$262>=(AF26-$R$26),$R$36*(1-参数输入表!$H$263)/参数输入表!$H$262,0) -> 0
C38: 期末大修及更新重置资产净值 | H38: =H35+H36-H37 -> 0 | I38: =I35+I36-I37 -> 0 | J38: =J35+J36-J37 -> 0 | K38: =K35+K36-K37 -> 0 | L38: =L35+L36-L37 -> 0 | M38: =M35+M36-M37 -> 0 | N38: =N35+N36-N37 -> 0 | O38: =O35+O36-O37 -> 0 | ... AF38: =AF35+AF36-AF37 -> 21.238938
B39: 5 | C39: 当期折旧摊销 | D39: =SUM(F39:AF39) -> 23689.97 | E39: 万元 | F39: =F28+F31+F34+F37 -> 0 | G39: =G28+G31+G34+G37 -> 0 | H39: =H28+H31+H34+H37 -> 1164.3215 | I39: =I28+I31+I34+I37 -> 1164.3215 | J39: =J28+J31+J34+J37 -> 1164.3215 | K39: =K28+K31+K34+K37 -> 1164.3215 | L39: =L28+L31+L34+L37 -> 1164.3215 | M39: =M28+M31+M34+M37 -> 1164.3215 | ... AF39: =AF28+AF31+AF34+AF37 -> 0
C42: 上述为“直线法”下折旧摊销计算，若在参数输入表中下拉菜单选择为“其他”，设置为手动输入各年份折旧额/摊销额
C44: 中间过程引用（隐藏）
...

Sheet 表3-成本费用表
B2: 成本费用表-资本金
B3: 序号 | C3: 项目 | D3: 合计 | E3: 单位 | F3: 建设期 | H3: 运营期
F4: 1 | G4: 2 | H4: 1 | I4: 2 | J4: 3 | K4: 4 | L4: 5 | M4: 6 | N4: 7 | O4: 8 | P4: 9 | Q4: 10 | R4: 11 | S4: 12 | T4: 13 | U4: 14 | V4: 15 | W4: 16 | X4: 17 | Y4: 18 | Z4: 19 | AA4: 20 | AB4: 21 | AC4: 22 | AD4: 23 | AE4: 24 | AF4: 25
B5: 一 | C5: 营业总成本 | D5: =SUM(F5:AF5) -> 46821.458 | E5: 万元 | H5: =H6+H15+H16+H19+H20 -> 2517.4608 | I5: =I6+I15+I16+I19+I20 -> 2465.4612 | J5: =J6+J15+J16+J19+J20 -> 2413.4617 | K5: =K6+K15+K16+K19+K20 -> 2361.4621 | L5: =L6+L15+L16+L19+L20 -> 2309.4626 | M5: =M6+M15+M16+M19+M20 -> 2308.7209 | N5: =N6+N15+N16+N19+N20 -> 2256.7213 | O5: =O6+O15+O16+O19+O20 -> 2204.7218 | ... AF5: =AF6+AF15+AF16+AF19+AF20 -> 778.17739
B6: 1 | C6: 生产成本 | D6: =SUM(F6:AF6) -> 38919.31 | H6: =SUM(H7:H14) -> 1670.9794 | I6: =SUM(I7:I14) -> 1670.9794 | J6: =SUM(J7:J14) -> 1670.9794 | K6: =SUM(K7:K14) -> 1670.9794 | L6: =SUM(L7:L14) -> 1670.9794 | M6: =SUM(M7:M14) -> 1722.2372 | N6: =SUM(N7:N14) -> 1722.2372 | O6: =SUM(O7:O14) -> 1722.2372 | ... AF6: =SUM(AF7:AF14) -> 711.68931
B7: 1.1 | C7: 材料费 | D7: =SUM(F7:AF7) -> 3600 | E7: 万元 | H7: =参数输入表!$H$141*参数输入表!$H$13/(1+参数输入表!$H$146) -> 144 | I7: =参数输入表!$H$141*参数输入表!$H$13/(1+参数输入表!$H$146) -> 144 | J7: =参数输入表!$H$141*参数输入表!$H$13/(1+参数输入表!$H$146) -> 144 | K7: =参数输入表!$H$141*参数输入表!$H$13/(1+参数输入表!$H$146) -> 144 | L7: =参数输入表!$H$141*参数输入表!$H$13/(1+参数输入表!$H$146) -> 144 | M7: =参数输入表!$H$142*参数输入表!$H$13/(1+参数输入表!$H$146) -> 144 | N7: =参数输入表!$H$142*参数输入表!$H$13/(1+参数输入表!$H$146) -> 144 | O7: =参数输入表!$H$142*参数输入表!$H$13/(1+参数输入表!$H$146) -> 144 | P7: =参数输入表!$H$142*参数输入表!$H$13/(1+参数输入表!$H$146) -> 144 | Q7: =参数输入表!$H$142*参数输入表!$H$13/(1+参数输入表!$H$146) -> 144 | R7: =参数输入表!$H$143*参数输入表!$H$13/(1+参数输入表!$H$146) -> 144 | S7: =参数输入表!$H$143*参数输入表!$H$13/(1+参数输入表!$H$146) -> 144 | T7: =参数输入表!$H$143*参数输入表!$H$13/(1+参数输入表!$H$146) -> 144 | U7: =参数输入表!$H$143*参数输入表!$H$13/(1+参数输入表!$H$146) -> 144 | V7: =参数输入表!$H$143*参数输入表!$H$13/(1+参数输入表!$H$146) -> 144 | W7: =参数输入表!$H$144*参数输入表!$H$13/(1+参数输入表!$H$146) -> 144 | X7: =参数输入表!$H$144*参数输入表!$H$13/(1+参数输入表!$H$146) -> 144 | Y7: =参数输入表!$H$144*参数输入表!$H$13/(1+参数输入表!$H$146) -> 144 | Z7: =参数输入表!$H$144*参数输入表!$H$13/(1+参数输入表!$H$146) -> 144 | AA7: =参数输入表!$H$144*参数输入表!$H$13/(1+参数输入表!$H$146) -> 144 | AB7: =参数输入表!$H$145*参数输入表!$H$13/(1+参数输入表!$H$146) -> 144 | AC7: =参数输入表!$H$145*参数输入表!$H$13/(1+参数输入表!$H$146) -> 144 | AD7: =参数输入表!$H$145*参数输入表!$H$13/(1+参数输入表!$H$146) -> 144 | AE7: =参数输入表!$H$145*参数输入表!$H$13/(1+参数输入表!$H$146) -> 144 | AF7: =参数输入表!$H$145*参数输入表!$H$13/(1+参数输入表!$H$146) -> 144
B8: 1.2 | C8: 维修费 | D8: =SUM(F8:AF8) -> 3619.3397 | E8: 万元 | H8: =(参数输入表!$H$113-参数输入表!$H$120)*参数输入表!$H$150/(1+参数输入表!$H$155) -> 48.257862 | I8: =(参数输入表!$H$113-参数输入表!$H$120)*参数输入表!$H$150/(1+参数输入表!$H$155) -> 48.257862 | J8: =(参数输入表!$H$113-参数输入表!$H$120)*参数输入表!$H$150/(1+参数输入表!$H$155) -> 48.257862 | K8: =(参数输入表!$H$113-参数输入表!$H$120)*参数输入表!$H$150/(1+参数输入表!$H$155) -> 48.257862 | L8: =(参数输入表!$H$113-参数输入表!$H$120)*参数输入表!$H$150/(1+参数输入表!$H$155) -> 48.257862 | M8: =(参数输入表!$H$113-参数输入表!$H$120)*参数输入表!$H$151/(1+参数输入表!$H$155) -> 96.515725 | N8: =(参数输入表!$H$113-参数输入表!$H$120)*参数输入表!$H$151/(1+参数输入表!$H$155) -> 96.515725 | O8: =(参数输入表!$H$113-参数输入表!$H$120)*参数输入表!$H$151/(1+参数输入表!$H$155) -> 96.515725 | P8: =(参数输入表!$H$113-参数输入表!$H$120)*参数输入表!$H$151/(1+参数输入表!$H$155) -> 96.515725 | Q8: =(参数输入表!$H$113-参数输入表!$H$120)*参数输入表!$H$151/(1+参数输入表!$H$155) -> 96.515725 | R8: =(参数输入表!$H$113-参数输入表!$H$120)*参数输入表!$H$152/(1+参数输入表!$H$155) -> 144.77359 | S8: =(参数输入表!$H$113-参数输入表!$H$120)*参数输入表!$H$152/(1+参数输入表!$H$155) -> 144.77359 | T8: =(参数输入表!$H$113-参数输入表!$H$120)*参数输入表!$H$152/(1+参数输入表!$H$155) -> 144.77359 | U8: =(参数输入表!$H$113-参数输入表!$H$120)*参数输入表!$H$152/(1+参数输入表!$H$155) -> 144.77359 | V8: =(参数输入表!$H$113-参数输入表!$H$120)*参数输入表!$H$152/(1+参数输入表!$H$155) -> 144.77359 | W8: =(参数输入表!$H$113-参数输入表!$H$120)*参数输入表!$H$153/(1+参数输入表!$H$155) -> 193.03145 | X8: =(参数输入表!$H$113-参数输入表!$H$120)*参数输入表!$H$153/(1+参数输入表!$H$155) -> 193.03145 | Y8: =(参数输入表!$H$113-参数输入表!$H$120)*参数输入表!$H$153/(1+参数输入表!$H$155) -> 193.03145 | Z8: =(参数输入表!$H$113-参数输入表!$H$120)*参数输入表!$H$153/(1+参数输入表!$H$155) -> 193.03145 | AA8: =(参数输入表!$H$113-参数输入表!$H$120)*参数输入表!$H$153/(1+参数输入表!$H$155) -> 193.03145 | AB8: =(参数输入表!$H$113-参数输入表!$H$120)*参数输入表!$H$154/(1+参数输入表!$H$155) -> 241.28931 | AC8: =(参数输入表!$H$113-参数输入表!$H$120)*参数输入表!$H$154/(1+参数输入表!$H$155) -> 241.28931 | AD8: =(参数输入表!$H$113-参数输入表!$H$120)*参数输入表!$H$154/(1+参数输入表!$H$155) -> 241.28931 | AE8: =(参数输入表!$H$113-参数输入表!$H$120)*参数输入表!$H$154/(1+参数输入表!$H$155) -> 241.28931 | AF8: =(参数输入表!$H$113-参数输入表!$H$120)*参数输入表!$H$154/(1+参数输入表!$H$155) -> 241.28931
B9: 1.3 | C9: 生产人员薪酬及福利 | D9: =SUM(F9:AF9) -> 3360 | E9: 万元 | H9: =(参数输入表!$H$167*参数输入表!$H$170+参数输入表!$H$168*参数输入表!$H$171)*(1+参数输入表!$H$172)*(1+参数输入表!$H$173*(H4-1))/(1+参数输入表!$H$174) -> 134.4 | I9: =(参数输入表!$H$167*参数输入表!$H$170+参数输入表!$H$168*参数输入表!$H$171)*(1+参数输入表!$H$172)*(1+参数输入表!$H$173*(I4-1))/(1+参数输入表!$H$174) -> 134.4 | J9: =(参数输入表!$H$167*参数输入表!$H$170+参数输入表!$H$168*参数输入表!$H$171)*(1+参数输入表!$H$172)*(1+参数输入表!$H$173*(J4-1))/(1+参数输入表!$H$174) -> 134.4 | K9: =(参数输入表!$H$167*参数输入表!$H$170+参数输入表!$H$168*参数输入表!$H$171)*(1+参数输入表!$H$172)*(1+参数输入表!$H$173*(K4-1))/(1+参数输入表!$H$174) -> 134.4 | L9: =(参数输入表!$H$167*参数输入表!$H$170+参数输入表!$H$168*参数输入表!$H$171)*(1+参数输入表!$H$172)*(1+参数输入表!$H$173*(L4-1))/(1+参数输入表!$H$174) -> 134.4 | M9: =(参数输入表!$H$167*参数输入表!$H$170+参数输入表!$H$168*参数输入表!$H$171)*(1+参数输入表!$H$172)*(1+参数输入表!$H$173*(M4-1))/(1+参数输入表!$H$174) -> 134.4 | N9: =(参数输入表!$H$167*参数输入表!$H$170+参数输入表!$H$168*参数输入表!$H$171)*(1+参数输入表!$H$172)*(1+参数输入表!$H$173*(N4-1))/(1+参数输入表!$H$174) -> 134.4 | O9: =(参数输入表!$H$167*参数输入表!$H$170+参数输入表!$H$168*参数输入表!$H$171)*(1+参数输入表!$H$172)*(1+参数输入表!$H$173*(O4-1))/(1+参数输入表!$H$174) -> 134.4 | ... AF9: =(参数输入表!$H$167*参数输入表!$H$170+参数输入表!$H$168*参数输入表!$H$171)*(1+参数输入表!$H$172)*(1+参数输入表!$H$173*(AF4-1))/(1+参数输入表!$H$174) -> 134.4
B10: 1.4 | C10: 长期待摊费用当期摊销 | D10: =SUM(F10:AF10) -> 0 | E10: 万元 | H10: ='表2-折旧摊销表'!H31 -> 0 | I10: ='表2-折旧摊销表'!I31 -> 0 | J10: ='表2-折旧摊销表'!J31 -> 0 | K10: ='表2-折旧摊销表'!K31 -> 0 | L10: ='表2-折旧摊销表'!L31 -> 0 | M10: ='表2-折旧摊销表'!M31 -> 0 | N10: ='表2-折旧摊销表'!N31 -> 0 | O10: ='表2-折旧摊销表'!O31 -> 0 | ... AF10: ='表2-折旧摊销表'!AF31 -> 0
B11: 1.5 | C11: 营业相关资产折旧及摊销 | D11: =SUM(F11:AF11) -> 23689.97 | E11: 万元 | H11: ='表2-折旧摊销表'!H28+'表2-折旧摊销表'!H34+'表2-折旧摊销表'!H37 -> 1164.3215 | I11: ='表2-折旧摊销表'!I28+'表2-折旧摊销表'!I34+'表2-折旧摊销表'!I37 -> 1164.3215 | J11: ='表2-折旧摊销表'!J28+'表2-折旧摊销表'!J34+'表2-折旧摊销表'!J37 -> 1164.3215 | K11: ='表2-折旧摊销表'!K28+'表2-折旧摊销表'!K34+'表2-折旧摊销表'!K37 -> 1164.3215 | L11: ='表2-折旧摊销表'!L28+'表2-折旧摊销表'!L34+'表2-折旧摊销表'!L37 -> 1164.3215 | M11: ='表2-折旧摊销表'!M28+'表2-折旧摊销表'!M34+'表2-折旧摊销表'!M37 -> 1164.3215 | N11: ='表2-折旧摊销表'!N28+'表2-折旧摊销表'!N34+'表2-折旧摊销表'!N37 -> 1164.3215 | O11: ='表2-折旧摊销表'!O28+'表2-折旧摊销表'!O34+'表2-折旧摊销表'!O37 -> 1164.3215 | ... AF11: ='表2-折旧摊销表'!AF28+'表2-折旧摊销表'!AF34+'表2-折旧摊销表'!AF37 -> 0
B12: 1.6 | C12: 其他费用 | D12: =SUM(F12:AF12) -> 3000 | E12: 万元 | H12: =参数输入表!$H$175*参数输入表!$H$13/(1+参数输入表!$H$176) -> 120 | I12: =参数输入表!$H$175*参数输入表!$H$13/(1+参数输入表!$H$176) -> 120 | J12: =参数输入表!$H$175*参数输入表!$H$13/(1+参数输入表!$H$176) -> 120 | K12: =参数输入表!$H$175*参数输入表!$H$13/(1+参数输入表!$H$176) -> 120 | L12: =参数输入表!$H$175*参数输入表!$H$13/(1+参数输入表!$H$176) -> 120 | M12: =参数输入表!$H$175*参数输入表!$H$13/(1+参数输入表!$H$176) -> 120 | N12: =参数输入表!$H$175*参数输入表!$H$13/(1+参数输入表!$H$176) -> 120 | O12: =参数输入表!$H$175*参数输入表!$H$13/(1+参数输入表!$H$176) -> 120 | ... AF12: =参数输入表!$H$175*参数输入表!$H$13/(1+参数输入表!$H$176) -> 120
B13: 1.7 | C13: 储能费用 | D13: =SUM(F13:AF13) -> 0 | E13: 万元 | H13: =参数输入表!$H$191*参数输入表!$H$13*1000/10000/(1+参数输入表!$H$192) -> 0 | I13: =参数输入表!$H$191*参数输入表!$H$13*1000/10000/(1+参数输入表!$H$192) -> 0 | J13: =参数输入表!$H$191*参数输入表!$H$13*1000/10000/(1+参数输入表!$H$192) -> 0 | K13: =参数输入表!$H$191*参数输入表!$H$13*1000/10000/(1+参数输入表!$H$192) -> 0 | L13: =参数输入表!$H$191*参数输入表!$H$13*1000/10000/(1+参数输入表!$H$192) -> 0 | M13: =参数输入表!$H$191*参数输入表!$H$13*1000/10000/(1+参数输入表!$H$192) -> 0 | N13: =参数输入表!$H$191*参数输入表!$H$13*1000/10000/(1+参数输入表!$H$192) -> 0 | O13: =参数输入表!$H$191*参数输入表!$H$13*1000/10000/(1+参数输入表!$H$192) -> 0 | ... AF13: =参数输入表!$H$191*参数输入表!$H$13*1000/10000/(1+参数输入表!$H$192) -> 0
B14: 1.8 | C14: 场地租金费用 | D14: =SUM(F14:AF14) -> 1650 | E14: 万元 | H14: =参数输入表!$H$178*参数输入表!$H$179/10000*(1+参数输入表!$H$181)/(1+参数输入表!$H$186) -> 60 | I14: =参数输入表!$H$178*参数输入表!$H$179/10000*(1+参数输入表!$H$181)/(1+参数输入表!$H$186) -> 60 | J14: =参数输入表!$H$178*参数输入表!$H$179/10000*(1+参数输入表!$H$181)/(1+参数输入表!$H$186) -> 60 | K14: =参数输入表!$H$178*参数输入表!$H$179/10000*(1+参数输入表!$H$181)/(1+参数输入表!$H$186) -> 60 | L14: =参数输入表!$H$178*参数输入表!$H$179/10000*(1+参数输入表!$H$181)/(1+参数输入表!$H$186) -> 60 | M14: =参数输入表!$H$178*参数输入表!$H$179/10000*(1+参数输入表!$H$182)/(1+参数输入表!$H$186) -> 63 | N14: =参数输入表!$H$178*参数输入表!$H$179/10000*(1+参数输入表!$H$182)/(1+参数输入表!$H$186) -> 63 | O14: =参数输入表!$H$178*参数输入表!$H$179/10000*(1+参数输入表!$H$182)/(1+参数输入表!$H$186) -> 63 | P14: =参数输入表!$H$178*参数输入表!$H$179/10000*(1+参数输入表!$H$182)/(1+参数输入表!$H$186) -> 63 | Q14: =参数输入表!$H$178*参数输入表!$H$179/10000*(1+参数输入表!$H$182)/(1+参数输入表!$H$186) -> 63 | R14: =参数输入表!$H$178*参数输入表!$H$179/10000*(1+参数输入表!$H$183)/(1+参数输入表!$H$186) -> 66 | S14: =参数输入表!$H$178*参数输入表!$H$179/10000*(1+参数输入表!$H$183)/(1+参数输入表!$H$186) -> 66 | T14: =参数输入表!$H$178*参数输入表!$H$179/10000*(1+参数输入表!$H$183)/(1+参数输入表!$H$186) -> 66 | U14: =参数输入表!$H$178*参数输入表!$H$179/10000*(1+参数输入表!$H$183)/(1+参数输入表!$H$186) -> 66 | V14: =参数输入表!$H$178*参数输入表!$H$179/10000*(1+参数输入表!$H$183)/(1+参数输入表!$H$186) -> 66 | W14: =参数输入表!$H$178*参数输入表!$H$179/10000*(1+参数输入表!$H$184)/(1+参数输入表!$H$186) -> 69 | X14: =参数输入表!$H$178*参数输入表!$H$179/10000*(1+参数输入表!$H$184)/(1+参数输入表!$H$186) -> 69 | Y14: =参数输入表!$H$178*参数输入表!$H$179/10000*(1+参数输入表!$H$184)/(1+参数输入表!$H$186) -> 69 | Z14: =参数输入表!$H$178*参数输入表!$H$179/10000*(1+参数输入表!$H$184)/(1+参数输入表!$H$186) -> 69 | AA14: =参数输入表!$H$178*参数输入表!$H$179/10000*(1+参数输入表!$H$184)/(1+参数输入表!$H$186) -> 69 | AB14: =参数输入表!$H$178*参数输入表!$H$179/10000*(1+参数输入表!$H$185)/(1+参数输入表!$H$186) -> 72 | AC14: =参数输入表!$H$178*参数输入表!$H$179/10000*(1+参数输入表!$H$185)/(1+参数输入表!$H$186) -> 72 | AD14: =参数输入表!$H$178*参数输入表!$H$179/10000*(1+参数输入表!$H$185)/(1+参数输入表!$H$186) -> 72 | AE14: =参数输入表!$H$178*参数输入表!$H$179/10000*(1+参数输入表!$H$185)/(1+参数输入表!$H$186) -> 72 | AF14: =参数输入表!$H$178*参数输入表!$H$179/10000*(1+参数输入表!$H$185)/(1+参数输入表!$H$186) -> 72
B15: 2 | C15: 销售费用 | D15: =SUM(F15:AF15) -> 0 | E15: 万元 | H15: 0 | I15: 0 | J15: 0 | K15: 0 | L15: 0 | M15: 0 | N15: 0 | O15: 0 | P15: 0 | Q15: 0 | R15: 0 | S15: 0 | T15: 0 | U15: 0 | V15: 0 | W15: 0 | X15: 0 | Y15: 0 | Z15: 0 | AA15: 0 | AB15: 0 | AC15: 0 | AD15: 0 | AE15: 0 | AF15: 0
B16: 3 | C16: 管理费用 | D16: =SUM(F16:AF16) -> 1532.002 | E16: 万元 | H16: =SUM(H17:H18) -> 61.28008 | I16: =SUM(I17:I18) -> 61.28008 | J16: =SUM(J17:J18) -> 61.28008 | K16: =SUM(K17:K18) -> 61.28008 | L16: =SUM(L17:L18) -> 61.28008 | M16: =SUM(M17:M18) -> 61.28008 | N16: =SUM(N17:N18) -> 61.28008 | O16: =SUM(O17:O18) -> 61.28008 | ... AF16: =SUM(AF17:AF18) -> 61.28008
B17: 3.1 | C17: 保险费 | D17: =SUM(F17:AF17) -> 1532.002 | E17: 万元 | H17: ='表2-折旧摊销表'!$D$4*参数输入表!$H$159/(1+参数输入表!$H$164) -> 61.28008 | I17: ='表2-折旧摊销表'!$D$4*参数输入表!$H$159/(1+参数输入表!$H$164) -> 61.28008 | J17: ='表2-折旧摊销表'!$D$4*参数输入表!$H$159/(1+参数输入表!$H$164) -> 61.28008 | K17: ='表2-折旧摊销表'!$D$4*参数输入表!$H$159/(1+参数输入表!$H$164) -> 61.28008 | L17: ='表2-折旧摊销表'!$D$4*参数输入表!$H$159/(1+参数输入表!$H$164) -> 61.28008 | M17: ='表2-折旧摊销表'!$D$4*参数输入表!$H$160/(1+参数输入表!$H$164) -> 61.28008 | N17: ='表2-折旧摊销表'!$D$4*参数输入表!$H$160/(1+参数输入表!$H$164) -> 61.28008 | O17: ='表2-折旧摊销表'!$D$4*参数输入表!$H$160/(1+参数输入表!$H$164) -> 61.28008 | P17: ='表2-折旧摊销表'!$D$4*参数输入表!$H$160/(1+参数输入表!$H$164) -> 61.28008 | Q17: ='表2-折旧摊销表'!$D$4*参数输入表!$H$160/(1+参数输入表!$H$164) -> 61.28008 | R17: ='表2-折旧摊销表'!$D$4*参数输入表!$H$161/(1+参数输入表!$H$164) -> 61.28008 | S17: ='表2-折旧摊销表'!$D$4*参数输入表!$H$161/(1+参数输入表!$H$164) -> 61.28008 | T17: ='表2-折旧摊销表'!$D$4*参数输入表!$H$161/(1+参数输入表!$H$164) -> 61.28008 | U17: ='表2-折旧摊销表'!$D$4*参数输入表!$H$161/(1+参数输入表!$H$164) -> 61.28008 | V17: ='表2-折旧摊销表'!$D$4*参数输入表!$H$161/(1+参数输入表!$H$164) -> 61.28008 | W17: ='表2-折旧摊销表'!$D$4*参数输入表!$H$162/(1+参数输入表!$H$164) -> 61.28008 | X17: ='表2-折旧摊销表'!$D$4*参数输入表!$H$162/(1+参数输入表!$H$164) -> 61.28008 | Y17: ='表2-折旧摊销表'!$D$4*参数输入表!$H$162/(1+参数输入表!$H$164) -> 61.28008 | Z17: ='表2-折旧摊销表'!$D$4*参数输入表!$H$162/(1+参数输入表!$H$164) -> 61.28008 | AA17: ='表2-折旧摊销表'!$D$4*参数输入表!$H$162/(1+参数输入表!$H$164) -> 61.28008 | AB17: ='表2-折旧摊销表'!$D$4*参数输入表!$H$163/(1+参数输入表!$H$164) -> 61.28008 | AC17: ='表2-折旧摊销表'!$D$4*参数输入表!$H$163/(1+参数输入表!$H$164) -> 61.28008 | AD17: ='表2-折旧摊销表'!$D$4*参数输入表!$H$163/(1+参数输入表!$H$164) -> 61.28008 | AE17: ='表2-折旧摊销表'!$D$4*参数输入表!$H$163/(1+参数输入表!$H$164) -> 61.28008 | AF17: ='表2-折旧摊销表'!$D$4*参数输入表!$H$163/(1+参数输入表!$H$164) -> 61.28008
B18: 3.2 | C18: 期末拆除费用 | D18: =SUM(F18:AF18) -> 0 | E18: 万元 | H18: 0 | I18: 0 | J18: 0 | K18: 0 | L18: 0 | M18: 0 | N18: 0 | O18: 0 | P18: 0 | Q18: 0 | R18: 0 | S18: 0 | T18: 0 | U18: 0 | V18: 0 | W18: 0 | X18: 0 | Y18: 0 | Z18: 0 | AA18: 0 | AB18: 0 | AC18: 0 | AD18: 0 | AE18: 0 | AF18: =参数输入表!H189*参数输入表!H188/(1+参数输入表!$H$190) -> 0
B19: 4 | C19: 研发费用 | D19: =SUM(F19:AF19) -> 0 | E19: 万元 | H19: 0 | I19: 0 | J19: 0 | K19: 0 | L19: 0 | M19: 0 | N19: 0 | O19: 0 | P19: 0 | Q19: 0 | R19: 0 | S19: 0 | T19: 0 | U19: 0 | V19: 0 | W19: 0 | X19: 0 | Y19: 0 | Z19: 0 | AA19: 0 | AB19: 0 | AC19: 0 | AD19: 0 | AE19: 0 | AF19: 0
B20: 5 | C20: 财务费用 | D20: =SUM(F20:AF20) -> 6370.1464 | E20: 万元 | H20: =SUM(H21:H23) -> 785.2013 | I20: =SUM(I21:I23) -> 733.20175 | J20: =SUM(J21:J23) -> 681.2022 | K20: =SUM(K21:K23) -> 629.20264 | L20: =SUM(L21:L23) -> 577.20309 | M20: =SUM(M21:M23) -> 525.20354 | N20: =SUM(N21:N23) -> 473.20398 | O20: =SUM(O21:O23) -> 421.20443 | ... AF20: =SUM(AF21:AF23) -> 5.208
B21: 5.1 | C21: 长期借款利息 | D21: =SUM(F21:AF21) -> 6239.9464 | E21: 万元 | H21: ='表1-资金筹措及还本付息表'!H53 -> 779.9933 | I21: ='表1-资金筹措及还本付息表'!I53 -> 727.99375 | J21: ='表1-资金筹措及还本付息表'!J53 -> 675.9942 | K21: ='表1-资金筹措及还本付息表'!K53 -> 623.99464 | L21: ='表1-资金筹措及还本付息表'!L53 -> 571.99509 | M21: ='表1-资金筹措及还本付息表'!M53 -> 519.99554 | N21: ='表1-资金筹措及还本付息表'!N53 -> 467.99598 | O21: ='表1-资金筹措及还本付息表'!O53 -> 415.99643 | ... AF21: ='表1-资金筹措及还本付息表'!AF53 -> 0
B22: 5.2 | C22: 流动资金利息 | D22: =SUM(F22:AF22) -> 130.2 | E22: 万元 | H22: ='表1-资金筹措及还本付息表'!H63 -> 5.208 | I22: =H22 -> 5.208 | J22: =I22 -> 5.208 | K22: =J22 -> 5.208 | L22: =K22 -> 5.208 | M22: =L22 -> 5.208 | N22: =M22 -> 5.208 | O22: =N22 -> 5.208 | P22: =O22 -> 5.208 | ... AF22: =AE22 -> 5.208
B23: 5.3 | C23: 短期借款利息 | D23: =SUM(F23:AF23) -> 0 | E23: 万元 | H23: ='表1-资金筹措及还本付息表'!H73 -> 0 | I23: ='表1-资金筹措及还本付息表'!I73 -> 0 | J23: ='表1-资金筹措及还本付息表'!J73 -> 0 | K23: ='表1-资金筹措及还本付息表'!K73 -> 0 | L23: ='表1-资金筹措及还本付息表'!L73 -> 0 | M23: ='表1-资金筹措及还本付息表'!M73 -> 0 | N23: ='表1-资金筹措及还本付息表'!N73 -> 0 | O23: ='表1-资金筹措及还本付息表'!O73 -> 0 | ... AF23: ='表1-资金筹措及还本付息表'!AF73 -> 0
B24: 二 | C24: 营业外支出 | D24: =SUM(F24:AF24) -> 0 | E24: 万元 | H24: =参数输入表!$H$267/(1+参数输入表!$H$271) -> 0 | I24: =参数输入表!$H$267/(1+参数输入表!$H$271) -> 0 | J24: =参数输入表!$H$267/(1+参数输入表!$H$271) -> 0 | K24: =参数输入表!$H$267/(1+参数输入表!$H$271) -> 0 | L24: =参数输入表!$H$267/(1+参数输入表!$H$271) -> 0 | M24: =参数输入表!$H$267/(1+参数输入表!$H$271) -> 0 | N24: =参数输入表!$H$267/(1+参数输入表!$H$271) -> 0 | O24: =参数输入表!$H$267/(1+参数输入表!$H$271) -> 0 | ... AF24: =参数输入表!$H$267/(1+参数输入表!$H$271) -> 0
B26: 成本费用表-全投资
B27: 序号 | C27: 项目 | D27: 合计 | E27: 单位 | F27: 建设期 | H27: 运营期
F28: 1 | G28: 2 | H28: 1 | I28: 2 | J28: 3 | K28: 4 | L28: 5 | M28: 6 | N28: 7 | O28: 8 | P28: 9 | Q28: 10 | R28: 11 | S28: 12 | T28: 13 | U28: 14 | V28: 15 | W28: 16 | X28: 17 | Y28: 18 | Z28: 19 | AA28: 20 | AB28: 21 | AC28: 22 | AD28: 23 | AE28: 24 | AF28: 25
B29: 一 | C29: 营业总成本 | D29: =SUM(F29:AF29) -> 40451.312 | E29: 万元 | H29: =H30+H39+H40+H43 -> 1732.2595 | I29: =I30+I39+I40+I43 -> 1732.2595 | J29: =J30+J39+J40+J43 -> 1732.2595 | K29: =K30+K39+K40+K43 -> 1732.2595 | L29: =L30+L39+L40+L43 -> 1732.2595 | M29: =M30+M39+M40+M43 -> 1783.5173 | N29: =N30+N39+N40+N43 -> 1783.5173 | O29: =O30+O39+O40+O43 -> 1783.5173 | ... AF29: =AF30+AF39+AF40+AF43 -> 772.96939
B30: 1 | C30: 生产成本 | D30: =SUM(F30:AF30) -> 38919.31 | H30: =SUM(H31:H38) -> 1670.9794 | I30: =SUM(I31:I38) -> 1670.9794 | J30: =SUM(J31:J38) -> 1670.9794 | K30: =SUM(K31:K38) -> 1670.9794 | L30: =SUM(L31:L38) -> 1670.9794 | M30: =SUM(M31:M38) -> 1722.2372 | N30: =SUM(N31:N38) -> 1722.2372 | O30: =SUM(O31:O38) -> 1722.2372 | ... AF30: =SUM(AF31:AF38) -> 711.68931
B31: 1.1 | C31: 材料费 | D31: =SUM(F31:AF31) -> 3600 | E31: 万元 | H31: =参数输入表!$H$141*参数输入表!$H$13/(1+参数输入表!$H$146) -> 144 | I31: =参数输入表!$H$141*参数输入表!$H$13/(1+参数输入表!$H$146) -> 144 | J31: =参数输入表!$H$141*参数输入表!$H$13/(1+参数输入表!$H$146) -> 144 | K31: =参数输入表!$H$141*参数输入表!$H$13/(1+参数输入表!$H$146) -> 144 | L31: =参数输入表!$H$141*参数输入表!$H$13/(1+参数输入表!$H$146) -> 144 | M31: =参数输入表!$H$142*参数输入表!$H$13/(1+参数输入表!$H$146) -> 144 | N31: =参数输入表!$H$142*参数输入表!$H$13/(1+参数输入表!$H$146) -> 144 | O31: =参数输入表!$H$142*参数输入表!$H$13/(1+参数输入表!$H$146) -> 144 | P31: =参数输入表!$H$142*参数输入表!$H$13/(1+参数输入表!$H$146) -> 144 | Q31: =参数输入表!$H$142*参数输入表!$H$13/(1+参数输入表!$H$146) -> 144 | R31: =参数输入表!$H$143*参数输入表!$H$13/(1+参数输入表!$H$146) -> 144 | S31: =参数输入表!$H$143*参数输入表!$H$13/(1+参数输入表!$H$146) -> 144 | T31: =参数输入表!$H$143*参数输入表!$H$13/(1+参数输入表!$H$146) -> 144 | U31: =参数输入表!$H$143*参数输入表!$H$13/(1+参数输入表!$H$146) -> 144 | V31: =参数输入表!$H$143*参数输入表!$H$13/(1+参数输入表!$H$146) -> 144 | W31: =参数输入表!$H$144*参数输入表!$H$13/(1+参数输入表!$H$146) -> 144 | X31: =参数输入表!$H$144*参数输入表!$H$13/(1+参数输入表!$H$146) -> 144 | Y31: =参数输入表!$H$144*参数输入表!$H$13/(1+参数输入表!$H$146) -> 144 | Z31: =参数输入表!$H$144*参数输入表!$H$13/(1+参数输入表!$H$146) -> 144 | AA31: =参数输入表!$H$144*参数输入表!$H$13/(1+参数输入表!$H$146) -> 144 | AB31: =参数输入表!$H$145*参数输入表!$H$13/(1+参数输入表!$H$146) -> 144 | AC31: =参数输入表!$H$145*参数输入表!$H$13/(1+参数输入表!$H$146) -> 144 | AD31: =参数输入表!$H$145*参数输入表!$H$13/(1+参数输入表!$H$146) -> 144 | AE31: =参数输入表!$H$145*参数输入表!$H$13/(1+参数输入表!$H$146) -> 144 | AF31: =参数输入表!$H$145*参数输入表!$H$13/(1+参数输入表!$H$146) -> 144
B32: 1.2 | C32: 维修费 | D32: =SUM(F32:AF32) -> 3619.3397 | E32: 万元 | H32: =(参数输入表!$H$113-参数输入表!$H$120)*参数输入表!$H$150/(1+参数输入表!$H$155) -> 48.257862 | I32: =(参数输入表!$H$113-参数输入表!$H$120)*参数输入表!$H$150/(1+参数输入表!$H$155) -> 48.257862 | J32: =(参数输入表!$H$113-参数输入表!$H$120)*参数输入表!$H$150/(1+参数输入表!$H$155) -> 48.257862 | K32: =(参数输入表!$H$113-参数输入表!$H$120)*参数输入表!$H$150/(1+参数输入表!$H$155) -> 48.257862 | L32: =(参数输入表!$H$113-参数输入表!$H$120)*参数输入表!$H$150/(1+参数输入表!$H$155) -> 48.257862 | M32: =(参数输入表!$H$113-参数输入表!$H$120)*参数输入表!$H$151/(1+参数输入表!$H$155) -> 96.515725 | N32: =(参数输入表!$H$113-参数输入表!$H$120)*参数输入表!$H$151/(1+参数输入表!$H$155) -> 96.515725 | O32: =(参数输入表!$H$113-参数输入表!$H$120)*参数输入表!$H$151/(1+参数输入表!$H$155) -> 96.515725 | P32: =(参数输入表!$H$113-参数输入表!$H$120)*参数输入表!$H$151/(1+参数输入表!$H$155) -> 96.515725 | Q32: =(参数输入表!$H$113-参数输入表!$H$120)*参数输入表!$H$151/(1+参数输入表!$H$155) -> 96.515725 | R32: =(参数输入表!$H$113-参数输入表!$H$120)*参数输入表!$H$152/(1+参数输入表!$H$155) -> 144.77359 | S32: =(参数输入表!$H$113-参数输入表!$H$120)*参数输入表!$H$152/(1+参数输入表!$H$155) -> 144.77359 | T32: =(参数输入表!$H$113-参数输入表!$H$120)*参数输入表!$H$152/(1+参数输入表!$H$155) -> 144.77359 | U32: =(参数输入表!$H$113-参数输入表!$H$120)*参数输入表!$H$152/(1+参数输入表!$H$155) -> 144.77359 | V32: =(参数输入表!$H$113-参数输入表!$H$120)*参数输入表!$H$152/(1+参数输入表!$H$155) -> 144.77359 | W32: =(参数输入表!$H$113-参数输入表!$H$120)*参数输入表!$H$153/(1+参数输入表!$H$155) -> 193.03145 | X32: =(参数输入表!$H$113-参数输入表!$H$120)*参数输入表!$H$153/(1+参数输入表!$H$155) -> 193.03145 | Y32: =(参数输入表!$H$113-参数输入表!$H$120)*参数输入表!$H$153/(1+参数输入表!$H$155) -> 193.03145 | Z32: =(参数输入表!$H$113-参数输入表!$H$120)*参数输入表!$H$153/(1+参数输入表!$H$155) -> 193.03145 | AA32: =(参数输入表!$H$113-参数输入表!$H$120)*参数输入表!$H$153/(1+参数输入表!$H$155) -> 193.03145 | AB32: =(参数输入表!$H$113-参数输入表!$H$120)*参数输入表!$H$154/(1+参数输入表!$H$155) -> 241.28931 | AC32: =(参数输入表!$H$113-参数输入表!$H$120)*参数输入表!$H$154/(1+参数输入表!$H$155) -> 241.28931 | AD32: =(参数输入表!$H$113-参数输入表!$H$120)*参数输入表!$H$154/(1+参数输入表!$H$155) -> 241.28931 | AE32: =(参数输入表!$H$113-参数输入表!$H$120)*参数输入表!$H$154/(1+参数输入表!$H$155) -> 241.28931 | AF32: =(参数输入表!$H$113-参数输入表!$H$120)*参数输入表!$H$154/(1+参数输入表!$H$155) -> 241.28931
B33: 1.3 | C33: 生产人员薪酬及福利 | D33: =SUM(F33:AF33) -> 3360 | E33: 万元 | H33: =(参数输入表!$H$167*参数输入表!$H$170+参数输入表!$H$168*参数输入表!$H$171)*(1+参数输入表!$H$172)*(1+参数输入表!$H$173*(H28-1))/(1+参数输入表!$H$174) -> 134.4 | I33: =(参数输入表!$H$167*参数输入表!$H$170+参数输入表!$H$168*参数输入表!$H$171)*(1+参数输入表!$H$172)*(1+参数输入表!$H$173*(I28-1))/(1+参数输入表!$H$174) -> 134.4 | J33: =(参数输入表!$H$167*参数输入表!$H$170+参数输入表!$H$168*参数输入表!$H$171)*(1+参数输入表!$H$172)*(1+参数输入表!$H$173*(J28-1))/(1+参数输入表!$H$174) -> 134.4 | K33: =(参数输入表!$H$167*参数输入表!$H$170+参数输入表!$H$168*参数输入表!$H$171)*(1+参数输入表!$H$172)*(1+参数输入表!$H$173*(K28-1))/(1+参数输入表!$H$174) -> 134.4 | L33: =(参数输入表!$H$167*参数输入表!$H$170+参数输入表!$H$168*参数输入表!$H$171)*(1+参数输入表!$H$172)*(1+参数输入表!$H$173*(L28-1))/(1+参数输入表!$H$174) -> 134.4 | M33: =(参数输入表!$H$167*参数输入表!$H$170+参数输入表!$H$168*参数输入表!$H$171)*(1+参数输入表!$H$172)*(1+参数输入表!$H$173*(M28-1))/(1+参数输入表!$H$174) -> 134.4 | N33: =(参数输入表!$H$167*参数输入表!$H$170+参数输入表!$H$168*参数输入表!$H$171)*(1+参数输入表!$H$172)*(1+参数输入表!$H$173*(N28-1))/(1+参数输入表!$H$174) -> 134.4 | O33: =(参数输入表!$H$167*参数输入表!$H$170+参数输入表!$H$168*参数输入表!$H$171)*(1+参数输入表!$H$172)*(1+参数输入表!$H$173*(O28-1))/(1+参数输入表!$H$174) -> 134.4 | ... AF33: =(参数输入表!$H$167*参数输入表!$H$170+参数输入表!$H$168*参数输入表!$H$171)*(1+参数输入表!$H$172)*(1+参数输入表!$H$173*(AF28-1))/(1+参数输入表!$H$174) -> 134.4
B34: 1.4 | C34: 长期待摊费用当期摊销 | D34: =SUM(F34:AF34) -> 0 | E34: 万元 | H34: ='表2-折旧摊销表'!H59 -> 0 | I34: ='表2-折旧摊销表'!I59 -> 0 | J34: ='表2-折旧摊销表'!J59 -> 0 | K34: ='表2-折旧摊销表'!K59 -> 0 | L34: ='表2-折旧摊销表'!L59 -> 0 | M34: ='表2-折旧摊销表'!M59 -> 0 | N34: ='表2-折旧摊销表'!N59 -> 0 | O34: ='表2-折旧摊销表'!O59 -> 0 | ... AF34: ='表2-折旧摊销表'!AF59 -> 0
B35: 1.5 | C35: 营业相关资产折旧及摊销 | D35: =SUM(F35:AF35) -> 23689.97 | E35: 万元 | H35: ='表2-折旧摊销表'!H56+'表2-折旧摊销表'!H62+'表2-折旧摊销表'!H65 -> 1164.3215 | I35: ='表2-折旧摊销表'!I56+'表2-折旧摊销表'!I62+'表2-折旧摊销表'!I65 -> 1164.3215 | J35: ='表2-折旧摊销表'!J56+'表2-折旧摊销表'!J62+'表2-折旧摊销表'!J65 -> 1164.3215 | K35: ='表2-折旧摊销表'!K56+'表2-折旧摊销表'!K62+'表2-折旧摊销表'!K65 -> 1164.3215 | L35: ='表2-折旧摊销表'!L56+'表2-折旧摊销表'!L62+'表2-折旧摊销表'!L65 -> 1164.3215 | M35: ='表2-折旧摊销表'!M56+'表2-折旧摊销表'!M62+'表2-折旧摊销表'!M65 -> 1164.3215 | N35: ='表2-折旧摊销表'!N56+'表2-折旧摊销表'!N62+'表2-折旧摊销表'!N65 -> 1164.3215 | O35: ='表2-折旧摊销表'!O56+'表2-折旧摊销表'!O62+'表2-折旧摊销表'!O65 -> 1164.3215 | ... AF35: ='表2-折旧摊销表'!AF56+'表2-折旧摊销表'!AF62+'表2-折旧摊销表'!AF65 -> 0
B36: 1.6 | C36: 其他费用 | D36: =SUM(F36:AF36) -> 3000 | E36: 万元 | H36: =参数输入表!$H$175*参数输入表!$H$13/(1+参数输入表!$H$176) -> 120 | I36: =参数输入表!$H$175*参数输入表!$H$13/(1+参数输入表!$H$176) -> 120 | J36: =参数输入表!$H$175*参数输入表!$H$13/(1+参数输入表!$H$176) -> 120 | K36: =参数输入表!$H$175*参数输入表!$H$13/(1+参数输入表!$H$176) -> 120 | L36: =参数输入表!$H$175*参数输入表!$H$13/(1+参数输入表!$H$176) -> 120 | M36: =参数输入表!$H$175*参数输入表!$H$13/(1+参数输入表!$H$176) -> 120 | N36: =参数输入表!$H$175*参数输入表!$H$13/(1+参数输入表!$H$176) -> 120 | O36: =参数输入表!$H$175*参数输入表!$H$13/(1+参数输入表!$H$176) -> 120 | ... AF36: =参数输入表!$H$175*参数输入表!$H$13/(1+参数输入表!$H$176) -> 120
B37: 1.7 | C37: 储能费用 | D37: =SUM(F37:AF37) -> 0 | E37: 万元 | H37: =参数输入表!$H$191*参数输入表!$H$13*1000/10000/(1+参数输入表!$H$192) -> 0 | I37: =参数输入表!$H$191*参数输入表!$H$13*1000/10000/(1+参数输入表!$H$192) -> 0 | J37: =参数输入表!$H$191*参数输入表!$H$13*1000/10000/(1+参数输入表!$H$192) -> 0 | K37: =参数输入表!$H$191*参数输入表!$H$13*1000/10000/(1+参数输入表!$H$192) -> 0 | L37: =参数输入表!$H$191*参数输入表!$H$13*1000/10000/(1+参数输入表!$H$192) -> 0 | M37: =参数输入表!$H$191*参数输入表!$H$13*1000/10000/(1+参数输入表!$H$192) -> 0 | N37: =参数输入表!$H$191*参数输入表!$H$13*1000/10000/(1+参数输入表!$H$192) -> 0 | O37: =参数输入表!$H$191*参数输入表!$H$13*1000/10000/(1+参数输入表!$H$192) -> 0 | ... AF37: =参数输入表!$H$191*参数输入表!$H$13*1000/10000/(1+参数输入表!$H$192) -> 0
B38: 1.8 | C38: 场地租金费用 | D38: =SUM(F38:AF38) -> 1650 | E38: 万元 | H38: =参数输入表!$H$178*参数输入表!$H$179/10000*(1+参数输入表!$H$181)/(1+参数输入表!$H$186) -> 60 | I38: =参数输入表!$H$178*参数输入表!$H$179/10000*(1+参数输入表!$H$181)/(1+参数输入表!$H$186) -> 60 | J38: =参数输入表!$H$178*参数输入表!$H$179/10000*(1+参数输入表!$H$181)/(1+参数输入表!$H$186) -> 60 | K38: =参数输入表!$H$178*参数输入表!$H$179/10000*(1+参数输入表!$H$181)/(1+参数输入表!$H$186) -> 60 | L38: =参数输入表!$H$178*参数输入表!$H$179/10000*(1+参数输入表!$H$181)/(1+参数输入表!$H$186) -> 60 | M38: =参数输入表!$H$178*参数输入表!$H$179/10000*(1+参数输入表!$H$182)/(1+参数输入表!$H$186) -> 63 | N38: =参数输入表!$H$178*参数输入表!$H$179/10000*(1+参数输入表!$H$182)/(1+参数输入表!$H$186) -> 63 | O38: =参数输入表!$H$178*参数输入表!$H$179/10000*(1+参数输入表!$H$182)/(1+参数输入表!$H$186) -> 63 | P38: =参数输入表!$H$178*参数输入表!$H$179/10000*(1+参数输入表!$H$182)/(1+参数输入表!$H$186) -> 63 | Q38: =参数输入表!$H$178*参数输入表!$H$179/10000*(1+参数输入表!$H$182)/(1+参数输入表!$H$186) -> 63 | R38: =参数输入表!$H$178*参数输入表!$H$179/10000*(1+参数输入表!$H$183)/(1+参数输入表!$H$186) -> 66 | S38: =参数输入表!$H$178*参数输入表!$H$179/10000*(1+参数输入表!$H$183)/(1+参数输入表!$H$186) -> 66 | T38: =参数输入表!$H$178*参数输入表!$H$179/10000*(1+参数输入表!$H$183)/(1+参数输入表!$H$186) -> 66 | U38: =参数输入表!$H$178*参数输入表!$H$179/10000*(1+参数输入表!$H$183)/(1+参数输入表!$H$186) -> 66 | V38: =参数输入表!$H$178*参数输入表!$H$179/10000*(1+参数输入表!$H$183)/(1+参数输入表!$H$186) -> 66 | W38: =参数输入表!$H$178*参数输入表!$H$179/10000*(1+参数输入表!$H$184)/(1+参数输入表!$H$186) -> 69 | X38: =参数输入表!$H$178*参数输入表!$H$179/10000*(1+参数输入表!$H$184)/(1+参数输入表!$H$186) -> 69 | Y38: =参数输入表!$H$178*参数输入表!$H$179/10000*(1+参数输入表!$H$184)/(1+参数输入表!$H$186) -> 69 | Z38: =参数输入表!$H$178*参数输入表!$H$179/10000*(1+参数输入表!$H$184)/(1+参数输入表!$H$186) -> 69 | AA38: =参数输入表!$H$178*参数输入表!$H$179/10000*(1+参数输入表!$H$184)/(1+参数输入表!$H$186) -> 69 | AB38: =参数输入表!$H$178*参数输入表!$H$179/10000*(1+参数输入表!$H$185)/(1+参数输入表!$H$186) -> 72 | AC38: =参数输入表!$H$178*参数输入表!$H$179/10000*(1+参数输入表!$H$185)/(1+参数输入表!$H$186) -> 72 | AD38: =参数输入表!$H$178*参数输入表!$H$179/10000*(1+参数输入表!$H$185)/(1+参数输入表!$H$186) -> 72 | AE38: =参数输入表!$H$178*参数输入表!$H$179/10000*(1+参数输入表!$H$185)/(1+参数输入表!$H$186) -> 72 | AF38: =参数输入表!$H$178*参数输入表!$H$179/10000*(1+参数输入表!$H$185)/(1+参数输入表!$H$186) -> 72
B39: 2 | C39: 销售费用 | D39: =SUM(F39:AF39) -> 0 | E39: 万元 | H39: 0 | I39: 0 | J39: 0 | K39: 0 | L39: 0 | M39: 0 | N39: 0 | O39: 0 | P39: 0 | Q39: 0 | R39: 0 | S39: 0 | T39: 0 | U39: 0 | V39: 0 | W39: 0 | X39: 0 | Y39: 0 | Z39: 0 | AA39: 0 | AB39: 0 | AC39: 0 | AD39: 0 | AE39: 0 | AF39: 0
B40: 3 | C40: 管理费用 | D40: =SUM(F40:AF40) -> 1532.002 | E40: 万元 | H40: =SUM(H41:H42) -> 61.28008 | I40: =SUM(I41:I42) -> 61.28008 | J40: =SUM(J41:J42) -> 61.28008 | K40: =SUM(K41:K42) -> 61.28008 | L40: =SUM(L41:L42) -> 61.28008 | M40: =SUM(M41:M42) -> 61.28008 | N40: =SUM(N41:N42) -> 61.28008 | O40: =SUM(O41:O42) -> 61.28008 | ... AF40: =SUM(AF41:AF42) -> 61.28008
B41: 3.1 | C41: 保险费 | D41: =SUM(F41:AF41) -> 1532.002 | E41: 万元 | H41: ='表2-折旧摊销表'!$D$4*参数输入表!$H$159/(1+参数输入表!$H$164) -> 61.28008 | I41: ='表2-折旧摊销表'!$D$4*参数输入表!$H$159/(1+参数输入表!$H$164) -> 61.28008 | J41: ='表2-折旧摊销表'!$D$4*参数输入表!$H$159/(1+参数输入表!$H$164) -> 61.28008 | K41: ='表2-折旧摊销表'!$D$4*参数输入表!$H$159/(1+参数输入表!$H$164) -> 61.28008 | L41: ='表2-折旧摊销表'!$D$4*参数输入表!$H$159/(1+参数输入表!$H$164) -> 61.28008 | M41: ='表2-折旧摊销表'!$D$4*参数输入表!$H$160/(1+参数输入表!$H$164) -> 61.28008 | N41: ='表2-折旧摊销表'!$D$4*参数输入表!$H$160/(1+参数输入表!$H$164) -> 61.28008 | O41: ='表2-折旧摊销表'!$D$4*参数输入表!$H$160/(1+参数输入表!$H$164) -> 61.28008 | P41: ='表2-折旧摊销表'!$D$4*参数输入表!$H$160/(1+参数输入表!$H$164) -> 61.28008 | Q41: ='表2-折旧摊销表'!$D$4*参数输入表!$H$160/(1+参数输入表!$H$164) -> 61.28008 | R41: ='表2-折旧摊销表'!$D$4*参数输入表!$H$161/(1+参数输入表!$H$164) -> 61.28008 | S41: ='表2-折旧摊销表'!$D$4*参数输入表!$H$161/(1+参数输入表!$H$164) -> 61.28008 | T41: ='表2-折旧摊销表'!$D$4*参数输入表!$H$161/(1+参数输入表!$H$164) -> 61.28008 | U41: ='表2-折旧摊销表'!$D$4*参数输入表!$H$161/(1+参数输入表!$H$164) -> 61.28008 | V41: ='表2-折旧摊销表'!$D$4*参数输入表!$H$161/(1+参数输入表!$H$164) -> 61.28008 | W41: ='表2-折旧摊销表'!$D$4*参数输入表!$H$162/(1+参数输入表!$H$164) -> 61.28008 | X41: ='表2-折旧摊销表'!$D$4*参数输入表!$H$162/(1+参数输入表!$H$164) -> 61.28008 | Y41: ='表2-折旧摊销表'!$D$4*参数输入表!$H$162/(1+参数输入表!$H$164) -> 61.28008 | Z41: ='表2-折旧摊销表'!$D$4*参数输入表!$H$162/(1+参数输入表!$H$164) -> 61.28008 | AA41: ='表2-折旧摊销表'!$D$4*参数输入表!$H$162/(1+参数输入表!$H$164) -> 61.28008 | AB41: ='表2-折旧摊销表'!$D$4*参数输入表!$H$163/(1+参数输入表!$H$164) -> 61.28008 | AC41: ='表2-折旧摊销表'!$D$4*参数输入表!$H$163/(1+参数输入表!$H$164) -> 61.28008 | AD41: ='表2-折旧摊销表'!$D$4*参数输入表!$H$163/(1+参数输入表!$H$164) -> 61.28008 | AE41: ='表2-折旧摊销表'!$D$4*参数输入表!$H$163/(1+参数输入表!$H$164) -> 61.28008 | AF41: ='表2-折旧摊销表'!$D$4*参数输入表!$H$163/(1+参数输入表!$H$164) -> 61.28008
B42: 3.2 | C42: 期末拆除费用 | D42: =SUM(F42:AF42) -> 0 | E42: 万元 | H42: 0 | I42: 0 | J42: 0 | K42: 0 | L42: 0 | M42: 0 | N42: 0 | O42: 0 | P42: 0 | Q42: 0 | R42: 0 | S42: 0 | T42: 0 | U42: 0 | V42: 0 | W42: 0 | X42: 0 | Y42: 0 | Z42: 0 | AA42: 0 | AB42: 0 | AC42: 0 | AD42: 0 | AE42: 0 | AF42: =参数输入表!H189*参数输入表!H188/(1+参数输入表!$H$190) -> 0
...

Sheet 表4-收入税金表
B2: 收入表
B3: 序号 | C3: 项目 | D3: 合计 | E3: 单位 | F3: 建设期 | H3: 运营期
F4: 1 | G4: 2 | H4: 1 | I4: 2 | J4: 3 | K4: 4 | L4: 5 | M4: 6 | N4: 7 | O4: 8 | P4: 9 | Q4: 10 | R4: 11 | S4: 12 | T4: 13 | U4: 14 | V4: 15 | W4: 16 | X4: 17 | Y4: 18 | Z4: 19 | AA4: 20 | AB4: 21 | AC4: 22 | AD4: 23 | AE4: 24 | AF4: 25
B5: 1 | C5: 营业收入 | D5: =SUM(F5:AF5) -> 73734.758 | E5: 万元 | H5: =H6 -> 2994.9375 | I5: =I6 -> 2981.4603 | J5: =J6 -> 2968.0437 | K5: =K6 -> 2954.6875 | L5: =L6 -> 2941.3914 | M5: =M6 -> 3072.5853 | N5: =N6 -> 3058.7586 | O5: =O6 -> 3044.9942 | ... AF5: =AF6 -> 2820.2523
B6: 1.1 | C6: 发电销售收入 | D6: =SUM(F6:AF6) -> 73734.758 | E6: 万元 | H6: =(H9*H10-H11-H12)/(1+参数输入表!$H$291)+(H14*H15)/(1+参数输入表!$H$296) -> 2994.9375 | I6: =(I9*I10-I11-I12)/(1+参数输入表!$H$291)+(I14*I15)/(1+参数输入表!$H$296) -> 2981.4603 | J6: =(J9*J10-J11-J12)/(1+参数输入表!$H$291)+(J14*J15)/(1+参数输入表!$H$296) -> 2968.0437 | K6: =(K9*K10-K11-K12)/(1+参数输入表!$H$291)+(K14*K15)/(1+参数输入表!$H$296) -> 2954.6875 | L6: =(L9*L10-L11-L12)/(1+参数输入表!$H$291)+(L14*L15)/(1+参数输入表!$H$296) -> 2941.3914 | M6: =(M9*M10-M11-M12)/(1+参数输入表!$H$291)+(M14*M15)/(1+参数输入表!$H$296) -> 3072.5853 | N6: =(N9*N10-N11-N12)/(1+参数输入表!$H$291)+(N14*N15)/(1+参数输入表!$H$296) -> 3058.7586 | O6: =(O9*O10-O11-O12)/(1+参数输入表!$H$291)+(O14*O15)/(1+参数输入表!$H$296) -> 3044.9942 | ... AF6: =(AF9*AF10-AF11-AF12)/(1+参数输入表!$H$291)+(AF14*AF15)/(1+参数输入表!$H$296) -> 2820.2523
C7: 发电量 | D7: =SUM(F7:AF7) -> 225201.5 | E7: 万度 | H7: =参数输入表!H13*参数输入表!H16*(1-参数输入表!H18)/10 -> 9504 | I7: =H7*(1-参数输入表!$H$19) -> 9461.232 | J7: =I7*(1-参数输入表!$H$19) -> 9418.6565 | K7: =J7*(1-参数输入表!$H$19) -> 9376.2725 | L7: =K7*(1-参数输入表!$H$19) -> 9334.0793 | M7: =L7*(1-参数输入表!$H$19) -> 9292.0759 | N7: =M7*(1-参数输入表!$H$19) -> 9250.2616 | O7: =N7*(1-参数输入表!$H$19) -> 9208.6354 | P7: =O7*(1-参数输入表!$H$19) -> 9167.1965 | ... AF7: =AE7*(1-参数输入表!$H$19) -> 8528.9736
C8: 上网售电收入 | D8: =SUM(F8:AF8) -> 21266.723 | E8: 万元 | H8: =H9*H10/1.13 -> 1312.8136 | I8: =I9*I10/1.13 -> 1306.9059 | J8: =J9*J10/1.13 -> 1301.0249 | K8: =K9*K10/1.13 -> 1295.1702 | L8: =L9*L10/1.13 -> 1289.342 | M8: =M9*M10/1.13 -> 770.12396 | N8: =N9*N10/1.13 -> 766.65841 | O8: =O9*O10/1.13 -> 763.20844 | ... AF8: =AF9*AF10/1.13 -> 706.87832
C9: 上网电量 | D9: =SUM(F9:AF9) -> 72822.415 | E9: 万度 | H9: =参数输入表!H47/10 -> 4495.392 | I9: =参数输入表!H48/10 -> 4475.1627 | J9: =参数输入表!H49/10 -> 4455.0245 | K9: =参数输入表!H50/10 -> 4434.9769 | L9: =参数输入表!H51/10 -> 4415.0195 | M9: =参数输入表!H52/10 -> 2637.0911 | N9: =参数输入表!H53/10 -> 2625.2242 | O9: =参数输入表!H54/10 -> 2613.4107 | P9: =参数输入表!H55/10 -> 2601.6504 | Q9: =参数输入表!H56/10 -> 2589.943 | R9: =参数输入表!H57/10 -> 2578.2882 | S9: =参数输入表!H58/10 -> 2566.6859 | T9: =参数输入表!H59/10 -> 2555.1358 | U9: =参数输入表!H60/10 -> 2543.6377 | V9: =参数输入表!H61/10 -> 2532.1913 | W9: =参数输入表!H62/10 -> 2520.7965 | X9: =参数输入表!H63/10 -> 2509.4529 | Y9: =参数输入表!H64/10 -> 2498.1604 | Z9: =参数输入表!H65/10 -> 2486.9186 | AA9: =参数输入表!H66/10 -> 2475.7275 | AB9: =参数输入表!H67/10 -> 2464.5867 | AC9: =参数输入表!H68/10 -> 2453.4961 | AD9: =参数输入表!H69/10 -> 2442.4554 | AE9: =参数输入表!H70/10 -> 2431.4643 | AF9: =参数输入表!H71/10 -> 2420.5227
C10: 上网电价（含税） | E10: 元/度 | H10: =参数输入表!H73 -> 0.33 | I10: =H10 -> 0.33 | J10: =I10 -> 0.33 | K10: =J10 -> 0.33 | L10: =K10 -> 0.33 | M10: =L10 -> 0.33 | N10: =M10 -> 0.33 | O10: =N10 -> 0.33 | P10: =O10 -> 0.33 | ... AF10: =AE10 -> 0.33
C11: 电网辅助服务分摊 | D11: =SUM(F11:AF11) -> 0 | E11: 万元 | H11: =H9*参数输入表!$H$284 -> 0 | I11: =I9*参数输入表!$H$284 -> 0 | J11: =J9*参数输入表!$H$284 -> 0 | K11: =K9*参数输入表!$H$284 -> 0 | L11: =L9*参数输入表!$H$284 -> 0 | M11: =M9*参数输入表!$H$284 -> 0 | N11: =N9*参数输入表!$H$284 -> 0 | O11: =O9*参数输入表!$H$284 -> 0 | ... AF11: =AF9*参数输入表!$H$284 -> 0
C12: 两个细则考核 | D12: =SUM(F12:AF12) -> 0 | E12: 万元 | H12: =H9*参数输入表!$H$288 -> 0 | I12: =I9*参数输入表!$H$288 -> 0 | J12: =J9*参数输入表!$H$288 -> 0 | K12: =K9*参数输入表!$H$288 -> 0 | L12: =L9*参数输入表!$H$288 -> 0 | M12: =M9*参数输入表!$H$288 -> 0 | N12: =N9*参数输入表!$H$288 -> 0 | O12: =O9*参数输入表!$H$288 -> 0 | ... AF12: =AF9*参数输入表!$H$288 -> 0
C13: 数能融合售电收入 | D13: =SUM(F13:AF13) -> 52468.035 | E13: 万元 | H13: =H14*H15/1.13 -> 1682.1239 | I13: =I14*I15/1.13 -> 1674.5543 | J13: =J14*J15/1.13 -> 1667.0188 | K13: =K14*K15/1.13 -> 1659.5173 | L13: =L14*L15/1.13 -> 1652.0494 | M13: =M14*M15/1.13 -> 2302.4613 | N13: =N14*N15/1.13 -> 2292.1002 | O13: =O14*O15/1.13 -> 2281.7858 | ... AF13: =AF14*AF15/1.13 -> 2113.374
C14: 数能融合消纳电量 | D14: =SUM(F14:AF14) -> 148222.2 | E14: 万度 | H14: =参数输入表!H77*参数输入表!H21/10 -> 4752 | I14: =参数输入表!H78*参数输入表!H22/10 -> 4730.616 | J14: =参数输入表!H79*参数输入表!H23/10 -> 4709.3282 | K14: =参数输入表!H80*参数输入表!H24/10 -> 4688.1363 | L14: =参数输入表!H81*参数输入表!H25/10 -> 4667.0396 | M14: =参数输入表!H82*参数输入表!H26/10 -> 6504.4531 | N14: =参数输入表!H83*参数输入表!H27/10 -> 6475.1831 | O14: =参数输入表!H84*参数输入表!H28/10 -> 6446.0448 | P14: =参数输入表!H85*参数输入表!H29/10 -> 6417.0376 | Q14: =参数输入表!H86*参数输入表!H30/10 -> 6388.1609 | R14: =参数输入表!H87*参数输入表!H31/10 -> 6359.4142 | S14: =参数输入表!H88*参数输入表!H32/10 -> 6330.7968 | T14: =参数输入表!H89*参数输入表!H33/10 -> 6302.3082 | U14: =参数输入表!H90*参数输入表!H34/10 -> 6273.9478 | V14: =参数输入表!H91*参数输入表!H35/10 -> 6245.7151 | W14: =参数输入表!H92*参数输入表!H36/10 -> 6217.6094 | X14: =参数输入表!H93*参数输入表!H37/10 -> 6189.6301 | Y14: =参数输入表!H94*参数输入表!H38/10 -> 6161.7768 | Z14: =参数输入表!H95*参数输入表!H39/10 -> 6134.0488 | AA14: =参数输入表!H96*参数输入表!H40/10 -> 6106.4456 | AB14: =参数输入表!H97/10*参数输入表!H41 -> 6078.9666 | AC14: =参数输入表!H98/10*参数输入表!H42 -> 6051.6112 | AD14: =参数输入表!H99/10*参数输入表!H43 -> 6024.379 | AE14: =参数输入表!H100/10*参数输入表!H44 -> 5997.2693 | AF14: =参数输入表!H101/10*参数输入表!H45 -> 5970.2816
C15: 数能融合机制电价（含税） | E15: 元/度 | H15: =参数输入表!H103 -> 0.4 | I15: =H15 -> 0.4 | J15: =I15 -> 0.4 | K15: =J15 -> 0.4 | L15: =K15 -> 0.4 | M15: =L15 -> 0.4 | N15: =M15 -> 0.4 | O15: =N15 -> 0.4 | P15: =O15 -> 0.4 | ... AF15: =AE15 -> 0.4
B16: 2 | C16: 其他收入 | D16: =SUM(F16:AF16) -> 0 | E16: 万元 | H16: =(参数输入表!$H$298*参数输入表!$H$299)/(1+参数输入表!$H$300) -> 0 | I16: =(参数输入表!$H$298*参数输入表!$H$299)/(1+参数输入表!$H$300) -> 0 | J16: =(参数输入表!$H$298*参数输入表!$H$299)/(1+参数输入表!$H$300) -> 0 | K16: =(参数输入表!$H$298*参数输入表!$H$299)/(1+参数输入表!$H$300) -> 0 | L16: =(参数输入表!$H$298*参数输入表!$H$299)/(1+参数输入表!$H$300) -> 0 | M16: =(参数输入表!$H$298*参数输入表!$H$299)/(1+参数输入表!$H$300) -> 0 | N16: =(参数输入表!$H$298*参数输入表!$H$299)/(1+参数输入表!$H$300) -> 0 | O16: =(参数输入表!$H$298*参数输入表!$H$299)/(1+参数输入表!$H$300) -> 0 | ... AF16: =(参数输入表!$H$298*参数输入表!$H$299)/(1+参数输入表!$H$300) -> 0
B17: 3 | C17: 营业外收入 | D17: =SUM(F17:AF17) -> 0 | E17: 万元 | H17: =SUM(H18:H19) -> 0 | I17: =SUM(I18:I19) -> 0 | J17: =SUM(J18:J19) -> 0 | K17: =SUM(K18:K19) -> 0 | L17: =SUM(L18:L19) -> 0 | M17: =SUM(M18:M19) -> 0 | N17: =SUM(N18:N19) -> 0 | O17: =SUM(O18:O19) -> 0 | ... AF17: =SUM(AF18:AF19) -> 0
B18: 3.1 | C18: 政府一次性运营补贴收入 | D18: =SUM(F18:AF18) -> 0 | E18: 万元 | H18: =参数输入表!H303 -> 0
B19: 3.2 | C19: 增值税即征即退 | D19: =SUM(F19:AF19) -> 0 | E19: 万元 | H19: =H22*参数输入表!$H$331 -> 0 | I19: =I22*参数输入表!$H$331 -> 0 | J19: =J22*参数输入表!$H$331 -> 0 | K19: =K22*参数输入表!$H$331 -> 0 | L19: =L22*参数输入表!$H$331 -> 0 | M19: =M22*参数输入表!$H$331 -> 0 | N19: =N22*参数输入表!$H$331 -> 0 | O19: =O22*参数输入表!$H$331 -> 0 | ... AF19: =AF22*参数输入表!$H$331 -> 0
B21: 税金表
B22: 1 | C22: 当期实缴增值税 | D22: =SUM(F22:AF22) -> 6959.2285 | E22: 万元 | F22: 0 | G22: =IF(G45>0,0,G44-F45) -> 0 | H22: =IF(H45>0,0,H44-G45) -> 0 | I22: =IF(I45>0,0,I44-H45) -> 0 | J22: =IF(J45>0,0,J44-I45) -> 0 | K22: =IF(K45>0,0,K44-J45) -> 0 | L22: =IF(L45>0,0,L44-K45) -> 0 | M22: =IF(M45>0,0,M44-L45) -> 0 | N22: =IF(N45>0,0,N44-M45) -> 155.27352 | ... AF22: =IF(AF45>0,0,AF44-AE45) -> 366.6328
B23: 2 | C23: 增值税销项税 | D23: =SUM(F23:AF23) -> 9585.5186 | E23: 万元 | F23: =SUM(F24:F25) -> 0 | G23: =SUM(G24:G25) -> 0 | H23: =SUM(H24:H25) -> 389.34187 | I23: =SUM(I24:I25) -> 387.58983 | J23: =SUM(J24:J25) -> 385.84568 | K23: =SUM(K24:K25) -> 384.10938 | L23: =SUM(L24:L25) -> 382.38088 | M23: =SUM(M24:M25) -> 399.43608 | ... AF23: =SUM(AF24:AF25) -> 366.6328
C24: 发电收入销项税 | D24: =SUM(F24:AF24) -> 9585.5186 | E24: 万元 | H24: =H6*参数输入表!$H$291 -> 389.34187 | I24: =I6*参数输入表!$H$291 -> 387.58983 | J24: =J6*参数输入表!$H$291 -> 385.84568 | K24: =K6*参数输入表!$H$291 -> 384.10938 | L24: =L6*参数输入表!$H$291 -> 382.38088 | M24: =M6*参数输入表!$H$291 -> 399.43608 | N24: =N6*参数输入表!$H$291 -> 397.63862 | O24: =O6*参数输入表!$H$291 -> 395.84925 | ... AF24: =AF6*参数输入表!$H$291 -> 366.6328
C25: 其他收入销项税 | D25: =SUM(F25:AF25) -> 0 | E25: 万元 | H25: =H16*参数输入表!$H$300 -> 0 | I25: =I16*参数输入表!$H$300 -> 0 | J25: =J16*参数输入表!$H$300 -> 0 | K25: =K16*参数输入表!$H$300 -> 0 | L25: =L16*参数输入表!$H$300 -> 0 | M25: =M16*参数输入表!$H$300 -> 0 | N25: =N16*参数输入表!$H$300 -> 0 | O25: =O16*参数输入表!$H$300 -> 0 | ... AF25: =AF16*参数输入表!$H$300 -> 0
B26: 3 | C26: 增值税进项税 | D26: =SUM(F26:AF26) -> 2626.2901 | E26: 万元 | F26: =F27+F28+F42+F43 -> 2571.0688 | G26: =G27+G28+G42+G43 -> 0 | H26: =H27+H28+H42+H43 -> 0 | I26: =I27+I28+I42+I43 -> 0 | J26: =J27+J28+J42+J43 -> 0 | K26: =K27+K28+K42+K43 -> 0 | L26: =L27+L28+L42+L43 -> 0 | M26: =M27+M28+M42+M43 -> 0 | ... AF26: =AF27+AF28+AF42+AF43 -> 0
B27: 3.1 | C27: 建设投资进项税 | D27: =SUM(F27:AF27) -> 2571.0688 | E27: 万元 | F27: =参数输入表!H120*参数输入表!H7 -> 2571.0688 | G27: =参数输入表!H120*参数输入表!H8 -> 0
B28: 3.2 | C28: 营业成本进项税 | D28: =SUM(F28:AF28) -> 0 | E28: 万元 | F28: =F29+F37+F38+F41 -> 0 | G28: =G29+G37+G38+G41 -> 0 | H28: =H29+H37+H38+H41 -> 0 | I28: =I29+I37+I38+I41 -> 0 | J28: =J29+J37+J38+J41 -> 0 | K28: =K29+K37+K38+K41 -> 0 | L28: =L29+L37+L38+L41 -> 0 | M28: =M29+M37+M38+M41 -> 0 | ... AF28: =AF29+AF37+AF38+AF41 -> 0
B29: 3.2.1 | C29: 生产成本进项税 | D29: =SUM(F29:AF29) -> 0 | E29: 万元 | H29: =SUM(H30:H36) -> 0 | I29: =SUM(I30:I36) -> 0 | J29: =SUM(J30:J36) -> 0 | K29: =SUM(K30:K36) -> 0 | L29: =SUM(L30:L36) -> 0 | M29: =SUM(M30:M36) -> 0 | N29: =SUM(N30:N36) -> 0 | O29: =SUM(O30:O36) -> 0 | ... AF29: =SUM(AF30:AF36) -> 0
C30: 材料费 | D30: =SUM(F30:AF30) -> 0 | E30: 万元 | H30: ='表3-成本费用表'!H50*参数输入表!$H$146 -> 0 | I30: ='表3-成本费用表'!I50*参数输入表!$H$146 -> 0 | J30: ='表3-成本费用表'!J50*参数输入表!$H$146 -> 0 | K30: ='表3-成本费用表'!K50*参数输入表!$H$146 -> 0 | L30: ='表3-成本费用表'!L50*参数输入表!$H$146 -> 0 | M30: ='表3-成本费用表'!M50*参数输入表!$H$146 -> 0 | N30: ='表3-成本费用表'!N50*参数输入表!$H$146 -> 0 | O30: ='表3-成本费用表'!O50*参数输入表!$H$146 -> 0 | ... AF30: ='表3-成本费用表'!AF50*参数输入表!$H$146 -> 0
C31: 维修费 | D31: =SUM(F31:AF31) -> 0 | E31: 万元 | H31: ='表3-成本费用表'!H51*参数输入表!$H$155 -> 0 | I31: ='表3-成本费用表'!I51*参数输入表!$H$155 -> 0 | J31: ='表3-成本费用表'!J51*参数输入表!$H$155 -> 0 | K31: ='表3-成本费用表'!K51*参数输入表!$H$155 -> 0 | L31: ='表3-成本费用表'!L51*参数输入表!$H$155 -> 0 | M31: ='表3-成本费用表'!M51*参数输入表!$H$155 -> 0 | N31: ='表3-成本费用表'!N51*参数输入表!$H$155 -> 0 | O31: ='表3-成本费用表'!O51*参数输入表!$H$155 -> 0 | ... AF31: ='表3-成本费用表'!AF51*参数输入表!$H$155 -> 0
